{
 "cells": [
  {
   "cell_type": "code",
   "execution_count": 7,
   "id": "01a57c9c",
   "metadata": {},
   "outputs": [
    {
     "name": "stderr",
     "output_type": "stream",
     "text": [
      "Exception in Tkinter callback\n",
      "Traceback (most recent call last):\n",
      "  File \"C:\\ProgramData\\Anaconda3\\lib\\tkinter\\__init__.py\", line 1892, in __call__\n",
      "    return self.func(*args)\n",
      "  File \"C:\\Users\\sanjay\\AppData\\Local\\Temp\\ipykernel_9524\\1006265385.py\", line 35, in paint\n",
      "    self.draw.line([x1, y1, x2, y2], fill=\"black\", width=5)\n",
      "AttributeError: 'DigitRecognitionApp' object has no attribute 'draw'\n",
      "Exception in Tkinter callback\n",
      "Traceback (most recent call last):\n",
      "  File \"C:\\ProgramData\\Anaconda3\\lib\\tkinter\\__init__.py\", line 1892, in __call__\n",
      "    return self.func(*args)\n",
      "  File \"C:\\Users\\sanjay\\AppData\\Local\\Temp\\ipykernel_9524\\1006265385.py\", line 35, in paint\n",
      "    self.draw.line([x1, y1, x2, y2], fill=\"black\", width=5)\n",
      "AttributeError: 'DigitRecognitionApp' object has no attribute 'draw'\n",
      "Exception in Tkinter callback\n",
      "Traceback (most recent call last):\n",
      "  File \"C:\\ProgramData\\Anaconda3\\lib\\tkinter\\__init__.py\", line 1892, in __call__\n",
      "    return self.func(*args)\n",
      "  File \"C:\\Users\\sanjay\\AppData\\Local\\Temp\\ipykernel_9524\\1006265385.py\", line 35, in paint\n",
      "    self.draw.line([x1, y1, x2, y2], fill=\"black\", width=5)\n",
      "AttributeError: 'DigitRecognitionApp' object has no attribute 'draw'\n",
      "Exception in Tkinter callback\n",
      "Traceback (most recent call last):\n",
      "  File \"C:\\ProgramData\\Anaconda3\\lib\\tkinter\\__init__.py\", line 1892, in __call__\n",
      "    return self.func(*args)\n",
      "  File \"C:\\Users\\sanjay\\AppData\\Local\\Temp\\ipykernel_9524\\1006265385.py\", line 35, in paint\n",
      "    self.draw.line([x1, y1, x2, y2], fill=\"black\", width=5)\n",
      "AttributeError: 'DigitRecognitionApp' object has no attribute 'draw'\n",
      "Exception in Tkinter callback\n",
      "Traceback (most recent call last):\n",
      "  File \"C:\\ProgramData\\Anaconda3\\lib\\tkinter\\__init__.py\", line 1892, in __call__\n",
      "    return self.func(*args)\n",
      "  File \"C:\\Users\\sanjay\\AppData\\Local\\Temp\\ipykernel_9524\\1006265385.py\", line 35, in paint\n",
      "    self.draw.line([x1, y1, x2, y2], fill=\"black\", width=5)\n",
      "AttributeError: 'DigitRecognitionApp' object has no attribute 'draw'\n",
      "Exception in Tkinter callback\n",
      "Traceback (most recent call last):\n",
      "  File \"C:\\ProgramData\\Anaconda3\\lib\\tkinter\\__init__.py\", line 1892, in __call__\n",
      "    return self.func(*args)\n",
      "  File \"C:\\Users\\sanjay\\AppData\\Local\\Temp\\ipykernel_9524\\1006265385.py\", line 35, in paint\n",
      "    self.draw.line([x1, y1, x2, y2], fill=\"black\", width=5)\n",
      "AttributeError: 'DigitRecognitionApp' object has no attribute 'draw'\n",
      "Exception in Tkinter callback\n",
      "Traceback (most recent call last):\n",
      "  File \"C:\\ProgramData\\Anaconda3\\lib\\tkinter\\__init__.py\", line 1892, in __call__\n",
      "    return self.func(*args)\n",
      "  File \"C:\\Users\\sanjay\\AppData\\Local\\Temp\\ipykernel_9524\\1006265385.py\", line 35, in paint\n",
      "    self.draw.line([x1, y1, x2, y2], fill=\"black\", width=5)\n",
      "AttributeError: 'DigitRecognitionApp' object has no attribute 'draw'\n",
      "Exception in Tkinter callback\n",
      "Traceback (most recent call last):\n",
      "  File \"C:\\ProgramData\\Anaconda3\\lib\\tkinter\\__init__.py\", line 1892, in __call__\n",
      "    return self.func(*args)\n",
      "  File \"C:\\Users\\sanjay\\AppData\\Local\\Temp\\ipykernel_9524\\1006265385.py\", line 35, in paint\n",
      "    self.draw.line([x1, y1, x2, y2], fill=\"black\", width=5)\n",
      "AttributeError: 'DigitRecognitionApp' object has no attribute 'draw'\n",
      "Exception in Tkinter callback\n",
      "Traceback (most recent call last):\n",
      "  File \"C:\\ProgramData\\Anaconda3\\lib\\tkinter\\__init__.py\", line 1892, in __call__\n",
      "    return self.func(*args)\n",
      "  File \"C:\\Users\\sanjay\\AppData\\Local\\Temp\\ipykernel_9524\\1006265385.py\", line 35, in paint\n",
      "    self.draw.line([x1, y1, x2, y2], fill=\"black\", width=5)\n",
      "AttributeError: 'DigitRecognitionApp' object has no attribute 'draw'\n",
      "Exception in Tkinter callback\n",
      "Traceback (most recent call last):\n",
      "  File \"C:\\ProgramData\\Anaconda3\\lib\\tkinter\\__init__.py\", line 1892, in __call__\n",
      "    return self.func(*args)\n",
      "  File \"C:\\Users\\sanjay\\AppData\\Local\\Temp\\ipykernel_9524\\1006265385.py\", line 35, in paint\n",
      "    self.draw.line([x1, y1, x2, y2], fill=\"black\", width=5)\n",
      "AttributeError: 'DigitRecognitionApp' object has no attribute 'draw'\n",
      "Exception in Tkinter callback\n",
      "Traceback (most recent call last):\n",
      "  File \"C:\\ProgramData\\Anaconda3\\lib\\tkinter\\__init__.py\", line 1892, in __call__\n",
      "    return self.func(*args)\n",
      "  File \"C:\\Users\\sanjay\\AppData\\Local\\Temp\\ipykernel_9524\\1006265385.py\", line 35, in paint\n",
      "    self.draw.line([x1, y1, x2, y2], fill=\"black\", width=5)\n",
      "AttributeError: 'DigitRecognitionApp' object has no attribute 'draw'\n",
      "Exception in Tkinter callback\n",
      "Traceback (most recent call last):\n",
      "  File \"C:\\ProgramData\\Anaconda3\\lib\\tkinter\\__init__.py\", line 1892, in __call__\n",
      "    return self.func(*args)\n",
      "  File \"C:\\Users\\sanjay\\AppData\\Local\\Temp\\ipykernel_9524\\1006265385.py\", line 35, in paint\n",
      "    self.draw.line([x1, y1, x2, y2], fill=\"black\", width=5)\n",
      "AttributeError: 'DigitRecognitionApp' object has no attribute 'draw'\n",
      "Exception in Tkinter callback\n",
      "Traceback (most recent call last):\n",
      "  File \"C:\\ProgramData\\Anaconda3\\lib\\tkinter\\__init__.py\", line 1892, in __call__\n",
      "    return self.func(*args)\n",
      "  File \"C:\\Users\\sanjay\\AppData\\Local\\Temp\\ipykernel_9524\\1006265385.py\", line 35, in paint\n",
      "    self.draw.line([x1, y1, x2, y2], fill=\"black\", width=5)\n",
      "AttributeError: 'DigitRecognitionApp' object has no attribute 'draw'\n",
      "Exception in Tkinter callback\n",
      "Traceback (most recent call last):\n",
      "  File \"C:\\ProgramData\\Anaconda3\\lib\\tkinter\\__init__.py\", line 1892, in __call__\n",
      "    return self.func(*args)\n",
      "  File \"C:\\Users\\sanjay\\AppData\\Local\\Temp\\ipykernel_9524\\1006265385.py\", line 35, in paint\n",
      "    self.draw.line([x1, y1, x2, y2], fill=\"black\", width=5)\n",
      "AttributeError: 'DigitRecognitionApp' object has no attribute 'draw'\n",
      "Exception in Tkinter callback\n",
      "Traceback (most recent call last):\n",
      "  File \"C:\\ProgramData\\Anaconda3\\lib\\tkinter\\__init__.py\", line 1892, in __call__\n",
      "    return self.func(*args)\n",
      "  File \"C:\\Users\\sanjay\\AppData\\Local\\Temp\\ipykernel_9524\\1006265385.py\", line 35, in paint\n",
      "    self.draw.line([x1, y1, x2, y2], fill=\"black\", width=5)\n",
      "AttributeError: 'DigitRecognitionApp' object has no attribute 'draw'\n",
      "Exception in Tkinter callback\n",
      "Traceback (most recent call last):\n",
      "  File \"C:\\ProgramData\\Anaconda3\\lib\\tkinter\\__init__.py\", line 1892, in __call__\n",
      "    return self.func(*args)\n",
      "  File \"C:\\Users\\sanjay\\AppData\\Local\\Temp\\ipykernel_9524\\1006265385.py\", line 35, in paint\n",
      "    self.draw.line([x1, y1, x2, y2], fill=\"black\", width=5)\n",
      "AttributeError: 'DigitRecognitionApp' object has no attribute 'draw'\n",
      "Exception in Tkinter callback\n",
      "Traceback (most recent call last):\n",
      "  File \"C:\\ProgramData\\Anaconda3\\lib\\tkinter\\__init__.py\", line 1892, in __call__\n",
      "    return self.func(*args)\n",
      "  File \"C:\\Users\\sanjay\\AppData\\Local\\Temp\\ipykernel_9524\\1006265385.py\", line 35, in paint\n",
      "    self.draw.line([x1, y1, x2, y2], fill=\"black\", width=5)\n",
      "AttributeError: 'DigitRecognitionApp' object has no attribute 'draw'\n",
      "Exception in Tkinter callback\n",
      "Traceback (most recent call last):\n",
      "  File \"C:\\ProgramData\\Anaconda3\\lib\\tkinter\\__init__.py\", line 1892, in __call__\n",
      "    return self.func(*args)\n",
      "  File \"C:\\Users\\sanjay\\AppData\\Local\\Temp\\ipykernel_9524\\1006265385.py\", line 35, in paint\n",
      "    self.draw.line([x1, y1, x2, y2], fill=\"black\", width=5)\n",
      "AttributeError: 'DigitRecognitionApp' object has no attribute 'draw'\n",
      "Exception in Tkinter callback\n",
      "Traceback (most recent call last):\n",
      "  File \"C:\\ProgramData\\Anaconda3\\lib\\tkinter\\__init__.py\", line 1892, in __call__\n",
      "    return self.func(*args)\n",
      "  File \"C:\\Users\\sanjay\\AppData\\Local\\Temp\\ipykernel_9524\\1006265385.py\", line 35, in paint\n",
      "    self.draw.line([x1, y1, x2, y2], fill=\"black\", width=5)\n",
      "AttributeError: 'DigitRecognitionApp' object has no attribute 'draw'\n",
      "Exception in Tkinter callback\n",
      "Traceback (most recent call last):\n",
      "  File \"C:\\ProgramData\\Anaconda3\\lib\\tkinter\\__init__.py\", line 1892, in __call__\n",
      "    return self.func(*args)\n",
      "  File \"C:\\Users\\sanjay\\AppData\\Local\\Temp\\ipykernel_9524\\1006265385.py\", line 35, in paint\n",
      "    self.draw.line([x1, y1, x2, y2], fill=\"black\", width=5)\n",
      "AttributeError: 'DigitRecognitionApp' object has no attribute 'draw'\n",
      "Exception in Tkinter callback\n",
      "Traceback (most recent call last):\n",
      "  File \"C:\\ProgramData\\Anaconda3\\lib\\tkinter\\__init__.py\", line 1892, in __call__\n",
      "    return self.func(*args)\n",
      "  File \"C:\\Users\\sanjay\\AppData\\Local\\Temp\\ipykernel_9524\\1006265385.py\", line 35, in paint\n",
      "    self.draw.line([x1, y1, x2, y2], fill=\"black\", width=5)\n",
      "AttributeError: 'DigitRecognitionApp' object has no attribute 'draw'\n",
      "Exception in Tkinter callback\n",
      "Traceback (most recent call last):\n",
      "  File \"C:\\ProgramData\\Anaconda3\\lib\\tkinter\\__init__.py\", line 1892, in __call__\n",
      "    return self.func(*args)\n",
      "  File \"C:\\Users\\sanjay\\AppData\\Local\\Temp\\ipykernel_9524\\1006265385.py\", line 35, in paint\n",
      "    self.draw.line([x1, y1, x2, y2], fill=\"black\", width=5)\n",
      "AttributeError: 'DigitRecognitionApp' object has no attribute 'draw'\n",
      "Exception in Tkinter callback\n",
      "Traceback (most recent call last):\n",
      "  File \"C:\\ProgramData\\Anaconda3\\lib\\tkinter\\__init__.py\", line 1892, in __call__\n",
      "    return self.func(*args)\n",
      "  File \"C:\\Users\\sanjay\\AppData\\Local\\Temp\\ipykernel_9524\\1006265385.py\", line 35, in paint\n",
      "    self.draw.line([x1, y1, x2, y2], fill=\"black\", width=5)\n",
      "AttributeError: 'DigitRecognitionApp' object has no attribute 'draw'\n",
      "Exception in Tkinter callback\n",
      "Traceback (most recent call last):\n",
      "  File \"C:\\ProgramData\\Anaconda3\\lib\\tkinter\\__init__.py\", line 1892, in __call__\n",
      "    return self.func(*args)\n",
      "  File \"C:\\Users\\sanjay\\AppData\\Local\\Temp\\ipykernel_9524\\1006265385.py\", line 35, in paint\n",
      "    self.draw.line([x1, y1, x2, y2], fill=\"black\", width=5)\n",
      "AttributeError: 'DigitRecognitionApp' object has no attribute 'draw'\n",
      "Exception in Tkinter callback\n",
      "Traceback (most recent call last):\n",
      "  File \"C:\\ProgramData\\Anaconda3\\lib\\tkinter\\__init__.py\", line 1892, in __call__\n",
      "    return self.func(*args)\n",
      "  File \"C:\\Users\\sanjay\\AppData\\Local\\Temp\\ipykernel_9524\\1006265385.py\", line 35, in paint\n",
      "    self.draw.line([x1, y1, x2, y2], fill=\"black\", width=5)\n",
      "AttributeError: 'DigitRecognitionApp' object has no attribute 'draw'\n",
      "Exception in Tkinter callback\n",
      "Traceback (most recent call last):\n",
      "  File \"C:\\ProgramData\\Anaconda3\\lib\\tkinter\\__init__.py\", line 1892, in __call__\n",
      "    return self.func(*args)\n",
      "  File \"C:\\Users\\sanjay\\AppData\\Local\\Temp\\ipykernel_9524\\1006265385.py\", line 35, in paint\n",
      "    self.draw.line([x1, y1, x2, y2], fill=\"black\", width=5)\n",
      "AttributeError: 'DigitRecognitionApp' object has no attribute 'draw'\n",
      "Exception in Tkinter callback\n",
      "Traceback (most recent call last):\n",
      "  File \"C:\\ProgramData\\Anaconda3\\lib\\tkinter\\__init__.py\", line 1892, in __call__\n",
      "    return self.func(*args)\n",
      "  File \"C:\\Users\\sanjay\\AppData\\Local\\Temp\\ipykernel_9524\\1006265385.py\", line 35, in paint\n",
      "    self.draw.line([x1, y1, x2, y2], fill=\"black\", width=5)\n",
      "AttributeError: 'DigitRecognitionApp' object has no attribute 'draw'\n",
      "Exception in Tkinter callback\n",
      "Traceback (most recent call last):\n",
      "  File \"C:\\ProgramData\\Anaconda3\\lib\\tkinter\\__init__.py\", line 1892, in __call__\n",
      "    return self.func(*args)\n",
      "  File \"C:\\Users\\sanjay\\AppData\\Local\\Temp\\ipykernel_9524\\1006265385.py\", line 35, in paint\n",
      "    self.draw.line([x1, y1, x2, y2], fill=\"black\", width=5)\n",
      "AttributeError: 'DigitRecognitionApp' object has no attribute 'draw'\n",
      "Exception in Tkinter callback\n",
      "Traceback (most recent call last):\n",
      "  File \"C:\\ProgramData\\Anaconda3\\lib\\tkinter\\__init__.py\", line 1892, in __call__\n",
      "    return self.func(*args)\n",
      "  File \"C:\\Users\\sanjay\\AppData\\Local\\Temp\\ipykernel_9524\\1006265385.py\", line 35, in paint\n",
      "    self.draw.line([x1, y1, x2, y2], fill=\"black\", width=5)\n",
      "AttributeError: 'DigitRecognitionApp' object has no attribute 'draw'\n",
      "Exception in Tkinter callback\n",
      "Traceback (most recent call last):\n",
      "  File \"C:\\ProgramData\\Anaconda3\\lib\\tkinter\\__init__.py\", line 1892, in __call__\n",
      "    return self.func(*args)\n",
      "  File \"C:\\Users\\sanjay\\AppData\\Local\\Temp\\ipykernel_9524\\1006265385.py\", line 35, in paint\n",
      "    self.draw.line([x1, y1, x2, y2], fill=\"black\", width=5)\n",
      "AttributeError: 'DigitRecognitionApp' object has no attribute 'draw'\n",
      "Exception in Tkinter callback\n",
      "Traceback (most recent call last):\n",
      "  File \"C:\\ProgramData\\Anaconda3\\lib\\tkinter\\__init__.py\", line 1892, in __call__\n",
      "    return self.func(*args)\n",
      "  File \"C:\\Users\\sanjay\\AppData\\Local\\Temp\\ipykernel_9524\\1006265385.py\", line 35, in paint\n",
      "    self.draw.line([x1, y1, x2, y2], fill=\"black\", width=5)\n",
      "AttributeError: 'DigitRecognitionApp' object has no attribute 'draw'\n",
      "Exception in Tkinter callback\n",
      "Traceback (most recent call last):\n",
      "  File \"C:\\ProgramData\\Anaconda3\\lib\\tkinter\\__init__.py\", line 1892, in __call__\n",
      "    return self.func(*args)\n",
      "  File \"C:\\Users\\sanjay\\AppData\\Local\\Temp\\ipykernel_9524\\1006265385.py\", line 35, in paint\n",
      "    self.draw.line([x1, y1, x2, y2], fill=\"black\", width=5)\n",
      "AttributeError: 'DigitRecognitionApp' object has no attribute 'draw'\n",
      "Exception in Tkinter callback\n",
      "Traceback (most recent call last):\n",
      "  File \"C:\\ProgramData\\Anaconda3\\lib\\tkinter\\__init__.py\", line 1892, in __call__\n",
      "    return self.func(*args)\n",
      "  File \"C:\\Users\\sanjay\\AppData\\Local\\Temp\\ipykernel_9524\\1006265385.py\", line 35, in paint\n",
      "    self.draw.line([x1, y1, x2, y2], fill=\"black\", width=5)\n",
      "AttributeError: 'DigitRecognitionApp' object has no attribute 'draw'\n",
      "Exception in Tkinter callback\n",
      "Traceback (most recent call last):\n",
      "  File \"C:\\ProgramData\\Anaconda3\\lib\\tkinter\\__init__.py\", line 1892, in __call__\n",
      "    return self.func(*args)\n",
      "  File \"C:\\Users\\sanjay\\AppData\\Local\\Temp\\ipykernel_9524\\1006265385.py\", line 35, in paint\n",
      "    self.draw.line([x1, y1, x2, y2], fill=\"black\", width=5)\n",
      "AttributeError: 'DigitRecognitionApp' object has no attribute 'draw'\n",
      "Exception in Tkinter callback\n",
      "Traceback (most recent call last):\n",
      "  File \"C:\\ProgramData\\Anaconda3\\lib\\tkinter\\__init__.py\", line 1892, in __call__\n",
      "    return self.func(*args)\n",
      "  File \"C:\\Users\\sanjay\\AppData\\Local\\Temp\\ipykernel_9524\\1006265385.py\", line 35, in paint\n",
      "    self.draw.line([x1, y1, x2, y2], fill=\"black\", width=5)\n",
      "AttributeError: 'DigitRecognitionApp' object has no attribute 'draw'\n",
      "Exception in Tkinter callback\n",
      "Traceback (most recent call last):\n",
      "  File \"C:\\ProgramData\\Anaconda3\\lib\\tkinter\\__init__.py\", line 1892, in __call__\n",
      "    return self.func(*args)\n",
      "  File \"C:\\Users\\sanjay\\AppData\\Local\\Temp\\ipykernel_9524\\1006265385.py\", line 35, in paint\n",
      "    self.draw.line([x1, y1, x2, y2], fill=\"black\", width=5)\n",
      "AttributeError: 'DigitRecognitionApp' object has no attribute 'draw'\n",
      "Exception in Tkinter callback\n",
      "Traceback (most recent call last):\n",
      "  File \"C:\\ProgramData\\Anaconda3\\lib\\tkinter\\__init__.py\", line 1892, in __call__\n",
      "    return self.func(*args)\n",
      "  File \"C:\\Users\\sanjay\\AppData\\Local\\Temp\\ipykernel_9524\\1006265385.py\", line 35, in paint\n",
      "    self.draw.line([x1, y1, x2, y2], fill=\"black\", width=5)\n",
      "AttributeError: 'DigitRecognitionApp' object has no attribute 'draw'\n",
      "Exception in Tkinter callback\n",
      "Traceback (most recent call last):\n",
      "  File \"C:\\ProgramData\\Anaconda3\\lib\\tkinter\\__init__.py\", line 1892, in __call__\n",
      "    return self.func(*args)\n",
      "  File \"C:\\Users\\sanjay\\AppData\\Local\\Temp\\ipykernel_9524\\1006265385.py\", line 35, in paint\n",
      "    self.draw.line([x1, y1, x2, y2], fill=\"black\", width=5)\n",
      "AttributeError: 'DigitRecognitionApp' object has no attribute 'draw'\n",
      "Exception in Tkinter callback\n",
      "Traceback (most recent call last):\n",
      "  File \"C:\\ProgramData\\Anaconda3\\lib\\tkinter\\__init__.py\", line 1892, in __call__\n",
      "    return self.func(*args)\n",
      "  File \"C:\\Users\\sanjay\\AppData\\Local\\Temp\\ipykernel_9524\\1006265385.py\", line 35, in paint\n",
      "    self.draw.line([x1, y1, x2, y2], fill=\"black\", width=5)\n",
      "AttributeError: 'DigitRecognitionApp' object has no attribute 'draw'\n",
      "Exception in Tkinter callback\n",
      "Traceback (most recent call last):\n",
      "  File \"C:\\ProgramData\\Anaconda3\\lib\\tkinter\\__init__.py\", line 1892, in __call__\n",
      "    return self.func(*args)\n",
      "  File \"C:\\Users\\sanjay\\AppData\\Local\\Temp\\ipykernel_9524\\1006265385.py\", line 35, in paint\n",
      "    self.draw.line([x1, y1, x2, y2], fill=\"black\", width=5)\n",
      "AttributeError: 'DigitRecognitionApp' object has no attribute 'draw'\n",
      "Exception in Tkinter callback\n",
      "Traceback (most recent call last):\n",
      "  File \"C:\\ProgramData\\Anaconda3\\lib\\tkinter\\__init__.py\", line 1892, in __call__\n",
      "    return self.func(*args)\n",
      "  File \"C:\\Users\\sanjay\\AppData\\Local\\Temp\\ipykernel_9524\\1006265385.py\", line 35, in paint\n",
      "    self.draw.line([x1, y1, x2, y2], fill=\"black\", width=5)\n",
      "AttributeError: 'DigitRecognitionApp' object has no attribute 'draw'\n",
      "Exception in Tkinter callback\n",
      "Traceback (most recent call last):\n",
      "  File \"C:\\ProgramData\\Anaconda3\\lib\\tkinter\\__init__.py\", line 1892, in __call__\n",
      "    return self.func(*args)\n",
      "  File \"C:\\Users\\sanjay\\AppData\\Local\\Temp\\ipykernel_9524\\1006265385.py\", line 35, in paint\n",
      "    self.draw.line([x1, y1, x2, y2], fill=\"black\", width=5)\n",
      "AttributeError: 'DigitRecognitionApp' object has no attribute 'draw'\n",
      "Exception in Tkinter callback\n",
      "Traceback (most recent call last):\n",
      "  File \"C:\\ProgramData\\Anaconda3\\lib\\tkinter\\__init__.py\", line 1892, in __call__\n",
      "    return self.func(*args)\n",
      "  File \"C:\\Users\\sanjay\\AppData\\Local\\Temp\\ipykernel_9524\\1006265385.py\", line 35, in paint\n",
      "    self.draw.line([x1, y1, x2, y2], fill=\"black\", width=5)\n",
      "AttributeError: 'DigitRecognitionApp' object has no attribute 'draw'\n",
      "Exception in Tkinter callback\n",
      "Traceback (most recent call last):\n",
      "  File \"C:\\ProgramData\\Anaconda3\\lib\\tkinter\\__init__.py\", line 1892, in __call__\n",
      "    return self.func(*args)\n",
      "  File \"C:\\Users\\sanjay\\AppData\\Local\\Temp\\ipykernel_9524\\1006265385.py\", line 35, in paint\n",
      "    self.draw.line([x1, y1, x2, y2], fill=\"black\", width=5)\n",
      "AttributeError: 'DigitRecognitionApp' object has no attribute 'draw'\n",
      "Exception in Tkinter callback\n",
      "Traceback (most recent call last):\n",
      "  File \"C:\\ProgramData\\Anaconda3\\lib\\tkinter\\__init__.py\", line 1892, in __call__\n",
      "    return self.func(*args)\n",
      "  File \"C:\\Users\\sanjay\\AppData\\Local\\Temp\\ipykernel_9524\\1006265385.py\", line 35, in paint\n",
      "    self.draw.line([x1, y1, x2, y2], fill=\"black\", width=5)\n",
      "AttributeError: 'DigitRecognitionApp' object has no attribute 'draw'\n",
      "Exception in Tkinter callback\n",
      "Traceback (most recent call last):\n",
      "  File \"C:\\ProgramData\\Anaconda3\\lib\\tkinter\\__init__.py\", line 1892, in __call__\n",
      "    return self.func(*args)\n",
      "  File \"C:\\Users\\sanjay\\AppData\\Local\\Temp\\ipykernel_9524\\1006265385.py\", line 35, in paint\n",
      "    self.draw.line([x1, y1, x2, y2], fill=\"black\", width=5)\n",
      "AttributeError: 'DigitRecognitionApp' object has no attribute 'draw'\n",
      "Exception in Tkinter callback\n",
      "Traceback (most recent call last):\n",
      "  File \"C:\\ProgramData\\Anaconda3\\lib\\tkinter\\__init__.py\", line 1892, in __call__\n",
      "    return self.func(*args)\n",
      "  File \"C:\\Users\\sanjay\\AppData\\Local\\Temp\\ipykernel_9524\\1006265385.py\", line 35, in paint\n",
      "    self.draw.line([x1, y1, x2, y2], fill=\"black\", width=5)\n",
      "AttributeError: 'DigitRecognitionApp' object has no attribute 'draw'\n",
      "Exception in Tkinter callback\n",
      "Traceback (most recent call last):\n",
      "  File \"C:\\ProgramData\\Anaconda3\\lib\\tkinter\\__init__.py\", line 1892, in __call__\n",
      "    return self.func(*args)\n",
      "  File \"C:\\Users\\sanjay\\AppData\\Local\\Temp\\ipykernel_9524\\1006265385.py\", line 35, in paint\n",
      "    self.draw.line([x1, y1, x2, y2], fill=\"black\", width=5)\n",
      "AttributeError: 'DigitRecognitionApp' object has no attribute 'draw'\n",
      "Exception in Tkinter callback\n",
      "Traceback (most recent call last):\n",
      "  File \"C:\\ProgramData\\Anaconda3\\lib\\tkinter\\__init__.py\", line 1892, in __call__\n",
      "    return self.func(*args)\n",
      "  File \"C:\\Users\\sanjay\\AppData\\Local\\Temp\\ipykernel_9524\\1006265385.py\", line 35, in paint\n",
      "    self.draw.line([x1, y1, x2, y2], fill=\"black\", width=5)\n",
      "AttributeError: 'DigitRecognitionApp' object has no attribute 'draw'\n",
      "Exception in Tkinter callback\n",
      "Traceback (most recent call last):\n",
      "  File \"C:\\ProgramData\\Anaconda3\\lib\\tkinter\\__init__.py\", line 1892, in __call__\n",
      "    return self.func(*args)\n",
      "  File \"C:\\Users\\sanjay\\AppData\\Local\\Temp\\ipykernel_9524\\1006265385.py\", line 35, in paint\n",
      "    self.draw.line([x1, y1, x2, y2], fill=\"black\", width=5)\n",
      "AttributeError: 'DigitRecognitionApp' object has no attribute 'draw'\n",
      "Exception in Tkinter callback\n",
      "Traceback (most recent call last):\n",
      "  File \"C:\\ProgramData\\Anaconda3\\lib\\tkinter\\__init__.py\", line 1892, in __call__\n",
      "    return self.func(*args)\n",
      "  File \"C:\\Users\\sanjay\\AppData\\Local\\Temp\\ipykernel_9524\\1006265385.py\", line 35, in paint\n",
      "    self.draw.line([x1, y1, x2, y2], fill=\"black\", width=5)\n",
      "AttributeError: 'DigitRecognitionApp' object has no attribute 'draw'\n",
      "Exception in Tkinter callback\n",
      "Traceback (most recent call last):\n",
      "  File \"C:\\ProgramData\\Anaconda3\\lib\\tkinter\\__init__.py\", line 1892, in __call__\n",
      "    return self.func(*args)\n",
      "  File \"C:\\Users\\sanjay\\AppData\\Local\\Temp\\ipykernel_9524\\1006265385.py\", line 35, in paint\n",
      "    self.draw.line([x1, y1, x2, y2], fill=\"black\", width=5)\n",
      "AttributeError: 'DigitRecognitionApp' object has no attribute 'draw'\n",
      "Exception in Tkinter callback\n",
      "Traceback (most recent call last):\n",
      "  File \"C:\\ProgramData\\Anaconda3\\lib\\tkinter\\__init__.py\", line 1892, in __call__\n",
      "    return self.func(*args)\n",
      "  File \"C:\\Users\\sanjay\\AppData\\Local\\Temp\\ipykernel_9524\\1006265385.py\", line 35, in paint\n",
      "    self.draw.line([x1, y1, x2, y2], fill=\"black\", width=5)\n",
      "AttributeError: 'DigitRecognitionApp' object has no attribute 'draw'\n",
      "Exception in Tkinter callback\n",
      "Traceback (most recent call last):\n",
      "  File \"C:\\ProgramData\\Anaconda3\\lib\\tkinter\\__init__.py\", line 1892, in __call__\n",
      "    return self.func(*args)\n",
      "  File \"C:\\Users\\sanjay\\AppData\\Local\\Temp\\ipykernel_9524\\1006265385.py\", line 35, in paint\n",
      "    self.draw.line([x1, y1, x2, y2], fill=\"black\", width=5)\n",
      "AttributeError: 'DigitRecognitionApp' object has no attribute 'draw'\n",
      "Exception in Tkinter callback\n",
      "Traceback (most recent call last):\n",
      "  File \"C:\\ProgramData\\Anaconda3\\lib\\tkinter\\__init__.py\", line 1892, in __call__\n",
      "    return self.func(*args)\n",
      "  File \"C:\\Users\\sanjay\\AppData\\Local\\Temp\\ipykernel_9524\\1006265385.py\", line 35, in paint\n",
      "    self.draw.line([x1, y1, x2, y2], fill=\"black\", width=5)\n",
      "AttributeError: 'DigitRecognitionApp' object has no attribute 'draw'\n",
      "Exception in Tkinter callback\n",
      "Traceback (most recent call last):\n",
      "  File \"C:\\ProgramData\\Anaconda3\\lib\\tkinter\\__init__.py\", line 1892, in __call__\n",
      "    return self.func(*args)\n",
      "  File \"C:\\Users\\sanjay\\AppData\\Local\\Temp\\ipykernel_9524\\1006265385.py\", line 35, in paint\n",
      "    self.draw.line([x1, y1, x2, y2], fill=\"black\", width=5)\n",
      "AttributeError: 'DigitRecognitionApp' object has no attribute 'draw'\n",
      "Exception in Tkinter callback\n",
      "Traceback (most recent call last):\n",
      "  File \"C:\\ProgramData\\Anaconda3\\lib\\tkinter\\__init__.py\", line 1892, in __call__\n",
      "    return self.func(*args)\n",
      "  File \"C:\\Users\\sanjay\\AppData\\Local\\Temp\\ipykernel_9524\\1006265385.py\", line 35, in paint\n",
      "    self.draw.line([x1, y1, x2, y2], fill=\"black\", width=5)\n",
      "AttributeError: 'DigitRecognitionApp' object has no attribute 'draw'\n",
      "Exception in Tkinter callback\n",
      "Traceback (most recent call last):\n",
      "  File \"C:\\ProgramData\\Anaconda3\\lib\\tkinter\\__init__.py\", line 1892, in __call__\n",
      "    return self.func(*args)\n",
      "  File \"C:\\Users\\sanjay\\AppData\\Local\\Temp\\ipykernel_9524\\1006265385.py\", line 35, in paint\n",
      "    self.draw.line([x1, y1, x2, y2], fill=\"black\", width=5)\n",
      "AttributeError: 'DigitRecognitionApp' object has no attribute 'draw'\n",
      "Exception in Tkinter callback\n",
      "Traceback (most recent call last):\n",
      "  File \"C:\\ProgramData\\Anaconda3\\lib\\tkinter\\__init__.py\", line 1892, in __call__\n",
      "    return self.func(*args)\n",
      "  File \"C:\\Users\\sanjay\\AppData\\Local\\Temp\\ipykernel_9524\\1006265385.py\", line 35, in paint\n",
      "    self.draw.line([x1, y1, x2, y2], fill=\"black\", width=5)\n",
      "AttributeError: 'DigitRecognitionApp' object has no attribute 'draw'\n",
      "Exception in Tkinter callback\n",
      "Traceback (most recent call last):\n",
      "  File \"C:\\ProgramData\\Anaconda3\\lib\\tkinter\\__init__.py\", line 1892, in __call__\n",
      "    return self.func(*args)\n",
      "  File \"C:\\Users\\sanjay\\AppData\\Local\\Temp\\ipykernel_9524\\1006265385.py\", line 35, in paint\n",
      "    self.draw.line([x1, y1, x2, y2], fill=\"black\", width=5)\n",
      "AttributeError: 'DigitRecognitionApp' object has no attribute 'draw'\n",
      "Exception in Tkinter callback\n",
      "Traceback (most recent call last):\n",
      "  File \"C:\\ProgramData\\Anaconda3\\lib\\tkinter\\__init__.py\", line 1892, in __call__\n",
      "    return self.func(*args)\n",
      "  File \"C:\\Users\\sanjay\\AppData\\Local\\Temp\\ipykernel_9524\\1006265385.py\", line 35, in paint\n",
      "    self.draw.line([x1, y1, x2, y2], fill=\"black\", width=5)\n",
      "AttributeError: 'DigitRecognitionApp' object has no attribute 'draw'\n",
      "Exception in Tkinter callback\n",
      "Traceback (most recent call last):\n",
      "  File \"C:\\ProgramData\\Anaconda3\\lib\\tkinter\\__init__.py\", line 1892, in __call__\n",
      "    return self.func(*args)\n",
      "  File \"C:\\Users\\sanjay\\AppData\\Local\\Temp\\ipykernel_9524\\1006265385.py\", line 35, in paint\n",
      "    self.draw.line([x1, y1, x2, y2], fill=\"black\", width=5)\n",
      "AttributeError: 'DigitRecognitionApp' object has no attribute 'draw'\n",
      "Exception in Tkinter callback\n",
      "Traceback (most recent call last):\n",
      "  File \"C:\\ProgramData\\Anaconda3\\lib\\tkinter\\__init__.py\", line 1892, in __call__\n",
      "    return self.func(*args)\n",
      "  File \"C:\\Users\\sanjay\\AppData\\Local\\Temp\\ipykernel_9524\\1006265385.py\", line 35, in paint\n",
      "    self.draw.line([x1, y1, x2, y2], fill=\"black\", width=5)\n",
      "AttributeError: 'DigitRecognitionApp' object has no attribute 'draw'\n",
      "Exception in Tkinter callback\n",
      "Traceback (most recent call last):\n",
      "  File \"C:\\ProgramData\\Anaconda3\\lib\\tkinter\\__init__.py\", line 1892, in __call__\n",
      "    return self.func(*args)\n",
      "  File \"C:\\Users\\sanjay\\AppData\\Local\\Temp\\ipykernel_9524\\1006265385.py\", line 35, in paint\n",
      "    self.draw.line([x1, y1, x2, y2], fill=\"black\", width=5)\n",
      "AttributeError: 'DigitRecognitionApp' object has no attribute 'draw'\n",
      "Exception in Tkinter callback\n",
      "Traceback (most recent call last):\n",
      "  File \"C:\\ProgramData\\Anaconda3\\lib\\tkinter\\__init__.py\", line 1892, in __call__\n",
      "    return self.func(*args)\n",
      "  File \"C:\\Users\\sanjay\\AppData\\Local\\Temp\\ipykernel_9524\\1006265385.py\", line 35, in paint\n",
      "    self.draw.line([x1, y1, x2, y2], fill=\"black\", width=5)\n",
      "AttributeError: 'DigitRecognitionApp' object has no attribute 'draw'\n",
      "Exception in Tkinter callback\n",
      "Traceback (most recent call last):\n",
      "  File \"C:\\ProgramData\\Anaconda3\\lib\\tkinter\\__init__.py\", line 1892, in __call__\n",
      "    return self.func(*args)\n",
      "  File \"C:\\Users\\sanjay\\AppData\\Local\\Temp\\ipykernel_9524\\1006265385.py\", line 35, in paint\n",
      "    self.draw.line([x1, y1, x2, y2], fill=\"black\", width=5)\n",
      "AttributeError: 'DigitRecognitionApp' object has no attribute 'draw'\n",
      "Exception in Tkinter callback\n",
      "Traceback (most recent call last):\n",
      "  File \"C:\\ProgramData\\Anaconda3\\lib\\tkinter\\__init__.py\", line 1892, in __call__\n",
      "    return self.func(*args)\n",
      "  File \"C:\\Users\\sanjay\\AppData\\Local\\Temp\\ipykernel_9524\\1006265385.py\", line 35, in paint\n",
      "    self.draw.line([x1, y1, x2, y2], fill=\"black\", width=5)\n",
      "AttributeError: 'DigitRecognitionApp' object has no attribute 'draw'\n",
      "Exception in Tkinter callback\n",
      "Traceback (most recent call last):\n",
      "  File \"C:\\ProgramData\\Anaconda3\\lib\\tkinter\\__init__.py\", line 1892, in __call__\n",
      "    return self.func(*args)\n",
      "  File \"C:\\Users\\sanjay\\AppData\\Local\\Temp\\ipykernel_9524\\1006265385.py\", line 35, in paint\n",
      "    self.draw.line([x1, y1, x2, y2], fill=\"black\", width=5)\n",
      "AttributeError: 'DigitRecognitionApp' object has no attribute 'draw'\n",
      "Exception in Tkinter callback\n",
      "Traceback (most recent call last):\n",
      "  File \"C:\\ProgramData\\Anaconda3\\lib\\tkinter\\__init__.py\", line 1892, in __call__\n",
      "    return self.func(*args)\n",
      "  File \"C:\\Users\\sanjay\\AppData\\Local\\Temp\\ipykernel_9524\\1006265385.py\", line 35, in paint\n",
      "    self.draw.line([x1, y1, x2, y2], fill=\"black\", width=5)\n",
      "AttributeError: 'DigitRecognitionApp' object has no attribute 'draw'\n",
      "Exception in Tkinter callback\n",
      "Traceback (most recent call last):\n",
      "  File \"C:\\ProgramData\\Anaconda3\\lib\\tkinter\\__init__.py\", line 1892, in __call__\n",
      "    return self.func(*args)\n",
      "  File \"C:\\Users\\sanjay\\AppData\\Local\\Temp\\ipykernel_9524\\1006265385.py\", line 35, in paint\n",
      "    self.draw.line([x1, y1, x2, y2], fill=\"black\", width=5)\n",
      "AttributeError: 'DigitRecognitionApp' object has no attribute 'draw'\n",
      "Exception in Tkinter callback\n",
      "Traceback (most recent call last):\n",
      "  File \"C:\\ProgramData\\Anaconda3\\lib\\tkinter\\__init__.py\", line 1892, in __call__\n",
      "    return self.func(*args)\n",
      "  File \"C:\\Users\\sanjay\\AppData\\Local\\Temp\\ipykernel_9524\\1006265385.py\", line 35, in paint\n",
      "    self.draw.line([x1, y1, x2, y2], fill=\"black\", width=5)\n",
      "AttributeError: 'DigitRecognitionApp' object has no attribute 'draw'\n",
      "Exception in Tkinter callback\n",
      "Traceback (most recent call last):\n",
      "  File \"C:\\ProgramData\\Anaconda3\\lib\\tkinter\\__init__.py\", line 1892, in __call__\n",
      "    return self.func(*args)\n",
      "  File \"C:\\Users\\sanjay\\AppData\\Local\\Temp\\ipykernel_9524\\1006265385.py\", line 35, in paint\n",
      "    self.draw.line([x1, y1, x2, y2], fill=\"black\", width=5)\n",
      "AttributeError: 'DigitRecognitionApp' object has no attribute 'draw'\n",
      "Exception in Tkinter callback\n",
      "Traceback (most recent call last):\n",
      "  File \"C:\\ProgramData\\Anaconda3\\lib\\tkinter\\__init__.py\", line 1892, in __call__\n",
      "    return self.func(*args)\n",
      "  File \"C:\\Users\\sanjay\\AppData\\Local\\Temp\\ipykernel_9524\\1006265385.py\", line 35, in paint\n",
      "    self.draw.line([x1, y1, x2, y2], fill=\"black\", width=5)\n",
      "AttributeError: 'DigitRecognitionApp' object has no attribute 'draw'\n",
      "Exception in Tkinter callback\n",
      "Traceback (most recent call last):\n",
      "  File \"C:\\ProgramData\\Anaconda3\\lib\\tkinter\\__init__.py\", line 1892, in __call__\n",
      "    return self.func(*args)\n",
      "  File \"C:\\Users\\sanjay\\AppData\\Local\\Temp\\ipykernel_9524\\1006265385.py\", line 35, in paint\n",
      "    self.draw.line([x1, y1, x2, y2], fill=\"black\", width=5)\n",
      "AttributeError: 'DigitRecognitionApp' object has no attribute 'draw'\n",
      "Exception in Tkinter callback\n",
      "Traceback (most recent call last):\n",
      "  File \"C:\\ProgramData\\Anaconda3\\lib\\tkinter\\__init__.py\", line 1892, in __call__\n",
      "    return self.func(*args)\n",
      "  File \"C:\\Users\\sanjay\\AppData\\Local\\Temp\\ipykernel_9524\\1006265385.py\", line 35, in paint\n",
      "    self.draw.line([x1, y1, x2, y2], fill=\"black\", width=5)\n",
      "AttributeError: 'DigitRecognitionApp' object has no attribute 'draw'\n",
      "Exception in Tkinter callback\n",
      "Traceback (most recent call last):\n",
      "  File \"C:\\ProgramData\\Anaconda3\\lib\\tkinter\\__init__.py\", line 1892, in __call__\n",
      "    return self.func(*args)\n",
      "  File \"C:\\Users\\sanjay\\AppData\\Local\\Temp\\ipykernel_9524\\1006265385.py\", line 35, in paint\n",
      "    self.draw.line([x1, y1, x2, y2], fill=\"black\", width=5)\n",
      "AttributeError: 'DigitRecognitionApp' object has no attribute 'draw'\n",
      "Exception in Tkinter callback\n",
      "Traceback (most recent call last):\n",
      "  File \"C:\\ProgramData\\Anaconda3\\lib\\tkinter\\__init__.py\", line 1892, in __call__\n",
      "    return self.func(*args)\n",
      "  File \"C:\\Users\\sanjay\\AppData\\Local\\Temp\\ipykernel_9524\\1006265385.py\", line 35, in paint\n",
      "    self.draw.line([x1, y1, x2, y2], fill=\"black\", width=5)\n",
      "AttributeError: 'DigitRecognitionApp' object has no attribute 'draw'\n",
      "Exception in Tkinter callback\n",
      "Traceback (most recent call last):\n",
      "  File \"C:\\ProgramData\\Anaconda3\\lib\\tkinter\\__init__.py\", line 1892, in __call__\n",
      "    return self.func(*args)\n",
      "  File \"C:\\Users\\sanjay\\AppData\\Local\\Temp\\ipykernel_9524\\1006265385.py\", line 35, in paint\n",
      "    self.draw.line([x1, y1, x2, y2], fill=\"black\", width=5)\n",
      "AttributeError: 'DigitRecognitionApp' object has no attribute 'draw'\n",
      "Exception in Tkinter callback\n",
      "Traceback (most recent call last):\n",
      "  File \"C:\\ProgramData\\Anaconda3\\lib\\tkinter\\__init__.py\", line 1892, in __call__\n",
      "    return self.func(*args)\n",
      "  File \"C:\\Users\\sanjay\\AppData\\Local\\Temp\\ipykernel_9524\\1006265385.py\", line 35, in paint\n",
      "    self.draw.line([x1, y1, x2, y2], fill=\"black\", width=5)\n",
      "AttributeError: 'DigitRecognitionApp' object has no attribute 'draw'\n",
      "Exception in Tkinter callback\n",
      "Traceback (most recent call last):\n",
      "  File \"C:\\ProgramData\\Anaconda3\\lib\\tkinter\\__init__.py\", line 1892, in __call__\n",
      "    return self.func(*args)\n",
      "  File \"C:\\Users\\sanjay\\AppData\\Local\\Temp\\ipykernel_9524\\1006265385.py\", line 35, in paint\n",
      "    self.draw.line([x1, y1, x2, y2], fill=\"black\", width=5)\n",
      "AttributeError: 'DigitRecognitionApp' object has no attribute 'draw'\n",
      "Exception in Tkinter callback\n",
      "Traceback (most recent call last):\n",
      "  File \"C:\\ProgramData\\Anaconda3\\lib\\tkinter\\__init__.py\", line 1892, in __call__\n",
      "    return self.func(*args)\n",
      "  File \"C:\\Users\\sanjay\\AppData\\Local\\Temp\\ipykernel_9524\\1006265385.py\", line 35, in paint\n",
      "    self.draw.line([x1, y1, x2, y2], fill=\"black\", width=5)\n",
      "AttributeError: 'DigitRecognitionApp' object has no attribute 'draw'\n",
      "Exception in Tkinter callback\n",
      "Traceback (most recent call last):\n",
      "  File \"C:\\ProgramData\\Anaconda3\\lib\\tkinter\\__init__.py\", line 1892, in __call__\n",
      "    return self.func(*args)\n",
      "  File \"C:\\Users\\sanjay\\AppData\\Local\\Temp\\ipykernel_9524\\1006265385.py\", line 35, in paint\n",
      "    self.draw.line([x1, y1, x2, y2], fill=\"black\", width=5)\n",
      "AttributeError: 'DigitRecognitionApp' object has no attribute 'draw'\n",
      "Exception in Tkinter callback\n",
      "Traceback (most recent call last):\n",
      "  File \"C:\\ProgramData\\Anaconda3\\lib\\tkinter\\__init__.py\", line 1892, in __call__\n",
      "    return self.func(*args)\n",
      "  File \"C:\\Users\\sanjay\\AppData\\Local\\Temp\\ipykernel_9524\\1006265385.py\", line 35, in paint\n",
      "    self.draw.line([x1, y1, x2, y2], fill=\"black\", width=5)\n",
      "AttributeError: 'DigitRecognitionApp' object has no attribute 'draw'\n",
      "Exception in Tkinter callback\n",
      "Traceback (most recent call last):\n",
      "  File \"C:\\ProgramData\\Anaconda3\\lib\\tkinter\\__init__.py\", line 1892, in __call__\n",
      "    return self.func(*args)\n",
      "  File \"C:\\Users\\sanjay\\AppData\\Local\\Temp\\ipykernel_9524\\1006265385.py\", line 35, in paint\n",
      "    self.draw.line([x1, y1, x2, y2], fill=\"black\", width=5)\n",
      "AttributeError: 'DigitRecognitionApp' object has no attribute 'draw'\n",
      "Exception in Tkinter callback\n",
      "Traceback (most recent call last):\n",
      "  File \"C:\\ProgramData\\Anaconda3\\lib\\tkinter\\__init__.py\", line 1892, in __call__\n",
      "    return self.func(*args)\n",
      "  File \"C:\\Users\\sanjay\\AppData\\Local\\Temp\\ipykernel_9524\\1006265385.py\", line 35, in paint\n",
      "    self.draw.line([x1, y1, x2, y2], fill=\"black\", width=5)\n",
      "AttributeError: 'DigitRecognitionApp' object has no attribute 'draw'\n",
      "Exception in Tkinter callback\n",
      "Traceback (most recent call last):\n",
      "  File \"C:\\ProgramData\\Anaconda3\\lib\\tkinter\\__init__.py\", line 1892, in __call__\n",
      "    return self.func(*args)\n",
      "  File \"C:\\Users\\sanjay\\AppData\\Local\\Temp\\ipykernel_9524\\1006265385.py\", line 35, in paint\n",
      "    self.draw.line([x1, y1, x2, y2], fill=\"black\", width=5)\n",
      "AttributeError: 'DigitRecognitionApp' object has no attribute 'draw'\n",
      "Exception in Tkinter callback\n",
      "Traceback (most recent call last):\n",
      "  File \"C:\\ProgramData\\Anaconda3\\lib\\tkinter\\__init__.py\", line 1892, in __call__\n",
      "    return self.func(*args)\n",
      "  File \"C:\\Users\\sanjay\\AppData\\Local\\Temp\\ipykernel_9524\\1006265385.py\", line 35, in paint\n",
      "    self.draw.line([x1, y1, x2, y2], fill=\"black\", width=5)\n",
      "AttributeError: 'DigitRecognitionApp' object has no attribute 'draw'\n",
      "Exception in Tkinter callback\n",
      "Traceback (most recent call last):\n",
      "  File \"C:\\ProgramData\\Anaconda3\\lib\\tkinter\\__init__.py\", line 1892, in __call__\n",
      "    return self.func(*args)\n",
      "  File \"C:\\Users\\sanjay\\AppData\\Local\\Temp\\ipykernel_9524\\1006265385.py\", line 35, in paint\n",
      "    self.draw.line([x1, y1, x2, y2], fill=\"black\", width=5)\n",
      "AttributeError: 'DigitRecognitionApp' object has no attribute 'draw'\n",
      "Exception in Tkinter callback\n",
      "Traceback (most recent call last):\n",
      "  File \"C:\\ProgramData\\Anaconda3\\lib\\tkinter\\__init__.py\", line 1892, in __call__\n",
      "    return self.func(*args)\n",
      "  File \"C:\\Users\\sanjay\\AppData\\Local\\Temp\\ipykernel_9524\\1006265385.py\", line 35, in paint\n",
      "    self.draw.line([x1, y1, x2, y2], fill=\"black\", width=5)\n",
      "AttributeError: 'DigitRecognitionApp' object has no attribute 'draw'\n",
      "Exception in Tkinter callback\n",
      "Traceback (most recent call last):\n",
      "  File \"C:\\ProgramData\\Anaconda3\\lib\\tkinter\\__init__.py\", line 1892, in __call__\n",
      "    return self.func(*args)\n",
      "  File \"C:\\Users\\sanjay\\AppData\\Local\\Temp\\ipykernel_9524\\1006265385.py\", line 35, in paint\n",
      "    self.draw.line([x1, y1, x2, y2], fill=\"black\", width=5)\n",
      "AttributeError: 'DigitRecognitionApp' object has no attribute 'draw'\n",
      "Exception in Tkinter callback\n",
      "Traceback (most recent call last):\n",
      "  File \"C:\\ProgramData\\Anaconda3\\lib\\tkinter\\__init__.py\", line 1892, in __call__\n",
      "    return self.func(*args)\n",
      "  File \"C:\\Users\\sanjay\\AppData\\Local\\Temp\\ipykernel_9524\\1006265385.py\", line 35, in paint\n",
      "    self.draw.line([x1, y1, x2, y2], fill=\"black\", width=5)\n",
      "AttributeError: 'DigitRecognitionApp' object has no attribute 'draw'\n",
      "Exception in Tkinter callback\n",
      "Traceback (most recent call last):\n",
      "  File \"C:\\ProgramData\\Anaconda3\\lib\\tkinter\\__init__.py\", line 1892, in __call__\n",
      "    return self.func(*args)\n",
      "  File \"C:\\Users\\sanjay\\AppData\\Local\\Temp\\ipykernel_9524\\1006265385.py\", line 35, in paint\n",
      "    self.draw.line([x1, y1, x2, y2], fill=\"black\", width=5)\n",
      "AttributeError: 'DigitRecognitionApp' object has no attribute 'draw'\n",
      "Exception in Tkinter callback\n",
      "Traceback (most recent call last):\n",
      "  File \"C:\\ProgramData\\Anaconda3\\lib\\tkinter\\__init__.py\", line 1892, in __call__\n",
      "    return self.func(*args)\n",
      "  File \"C:\\Users\\sanjay\\AppData\\Local\\Temp\\ipykernel_9524\\1006265385.py\", line 35, in paint\n",
      "    self.draw.line([x1, y1, x2, y2], fill=\"black\", width=5)\n",
      "AttributeError: 'DigitRecognitionApp' object has no attribute 'draw'\n",
      "Exception in Tkinter callback\n",
      "Traceback (most recent call last):\n",
      "  File \"C:\\ProgramData\\Anaconda3\\lib\\tkinter\\__init__.py\", line 1892, in __call__\n",
      "    return self.func(*args)\n",
      "  File \"C:\\Users\\sanjay\\AppData\\Local\\Temp\\ipykernel_9524\\1006265385.py\", line 35, in paint\n",
      "    self.draw.line([x1, y1, x2, y2], fill=\"black\", width=5)\n",
      "AttributeError: 'DigitRecognitionApp' object has no attribute 'draw'\n",
      "Exception in Tkinter callback\n",
      "Traceback (most recent call last):\n",
      "  File \"C:\\ProgramData\\Anaconda3\\lib\\tkinter\\__init__.py\", line 1892, in __call__\n",
      "    return self.func(*args)\n",
      "  File \"C:\\Users\\sanjay\\AppData\\Local\\Temp\\ipykernel_9524\\1006265385.py\", line 35, in paint\n",
      "    self.draw.line([x1, y1, x2, y2], fill=\"black\", width=5)\n",
      "AttributeError: 'DigitRecognitionApp' object has no attribute 'draw'\n",
      "Exception in Tkinter callback\n",
      "Traceback (most recent call last):\n",
      "  File \"C:\\ProgramData\\Anaconda3\\lib\\tkinter\\__init__.py\", line 1892, in __call__\n",
      "    return self.func(*args)\n",
      "  File \"C:\\Users\\sanjay\\AppData\\Local\\Temp\\ipykernel_9524\\1006265385.py\", line 35, in paint\n",
      "    self.draw.line([x1, y1, x2, y2], fill=\"black\", width=5)\n",
      "AttributeError: 'DigitRecognitionApp' object has no attribute 'draw'\n",
      "Exception in Tkinter callback\n",
      "Traceback (most recent call last):\n",
      "  File \"C:\\ProgramData\\Anaconda3\\lib\\tkinter\\__init__.py\", line 1892, in __call__\n",
      "    return self.func(*args)\n",
      "  File \"C:\\Users\\sanjay\\AppData\\Local\\Temp\\ipykernel_9524\\1006265385.py\", line 35, in paint\n",
      "    self.draw.line([x1, y1, x2, y2], fill=\"black\", width=5)\n",
      "AttributeError: 'DigitRecognitionApp' object has no attribute 'draw'\n",
      "Exception in Tkinter callback\n",
      "Traceback (most recent call last):\n",
      "  File \"C:\\ProgramData\\Anaconda3\\lib\\tkinter\\__init__.py\", line 1892, in __call__\n",
      "    return self.func(*args)\n",
      "  File \"C:\\Users\\sanjay\\AppData\\Local\\Temp\\ipykernel_9524\\1006265385.py\", line 35, in paint\n",
      "    self.draw.line([x1, y1, x2, y2], fill=\"black\", width=5)\n",
      "AttributeError: 'DigitRecognitionApp' object has no attribute 'draw'\n",
      "Exception in Tkinter callback\n",
      "Traceback (most recent call last):\n",
      "  File \"C:\\ProgramData\\Anaconda3\\lib\\tkinter\\__init__.py\", line 1892, in __call__\n",
      "    return self.func(*args)\n",
      "  File \"C:\\Users\\sanjay\\AppData\\Local\\Temp\\ipykernel_9524\\1006265385.py\", line 35, in paint\n",
      "    self.draw.line([x1, y1, x2, y2], fill=\"black\", width=5)\n",
      "AttributeError: 'DigitRecognitionApp' object has no attribute 'draw'\n",
      "Exception in Tkinter callback\n",
      "Traceback (most recent call last):\n",
      "  File \"C:\\ProgramData\\Anaconda3\\lib\\tkinter\\__init__.py\", line 1892, in __call__\n",
      "    return self.func(*args)\n",
      "  File \"C:\\Users\\sanjay\\AppData\\Local\\Temp\\ipykernel_9524\\1006265385.py\", line 35, in paint\n",
      "    self.draw.line([x1, y1, x2, y2], fill=\"black\", width=5)\n",
      "AttributeError: 'DigitRecognitionApp' object has no attribute 'draw'\n",
      "Exception in Tkinter callback\n",
      "Traceback (most recent call last):\n",
      "  File \"C:\\ProgramData\\Anaconda3\\lib\\tkinter\\__init__.py\", line 1892, in __call__\n",
      "    return self.func(*args)\n",
      "  File \"C:\\Users\\sanjay\\AppData\\Local\\Temp\\ipykernel_9524\\1006265385.py\", line 35, in paint\n",
      "    self.draw.line([x1, y1, x2, y2], fill=\"black\", width=5)\n",
      "AttributeError: 'DigitRecognitionApp' object has no attribute 'draw'\n",
      "Exception in Tkinter callback\n",
      "Traceback (most recent call last):\n",
      "  File \"C:\\ProgramData\\Anaconda3\\lib\\tkinter\\__init__.py\", line 1892, in __call__\n",
      "    return self.func(*args)\n",
      "  File \"C:\\Users\\sanjay\\AppData\\Local\\Temp\\ipykernel_9524\\1006265385.py\", line 35, in paint\n",
      "    self.draw.line([x1, y1, x2, y2], fill=\"black\", width=5)\n",
      "AttributeError: 'DigitRecognitionApp' object has no attribute 'draw'\n",
      "Exception in Tkinter callback\n",
      "Traceback (most recent call last):\n",
      "  File \"C:\\ProgramData\\Anaconda3\\lib\\tkinter\\__init__.py\", line 1892, in __call__\n",
      "    return self.func(*args)\n",
      "  File \"C:\\Users\\sanjay\\AppData\\Local\\Temp\\ipykernel_9524\\1006265385.py\", line 35, in paint\n",
      "    self.draw.line([x1, y1, x2, y2], fill=\"black\", width=5)\n",
      "AttributeError: 'DigitRecognitionApp' object has no attribute 'draw'\n",
      "Exception in Tkinter callback\n",
      "Traceback (most recent call last):\n",
      "  File \"C:\\ProgramData\\Anaconda3\\lib\\tkinter\\__init__.py\", line 1892, in __call__\n",
      "    return self.func(*args)\n",
      "  File \"C:\\Users\\sanjay\\AppData\\Local\\Temp\\ipykernel_9524\\1006265385.py\", line 35, in paint\n",
      "    self.draw.line([x1, y1, x2, y2], fill=\"black\", width=5)\n",
      "AttributeError: 'DigitRecognitionApp' object has no attribute 'draw'\n",
      "Exception in Tkinter callback\n",
      "Traceback (most recent call last):\n",
      "  File \"C:\\ProgramData\\Anaconda3\\lib\\tkinter\\__init__.py\", line 1892, in __call__\n",
      "    return self.func(*args)\n",
      "  File \"C:\\Users\\sanjay\\AppData\\Local\\Temp\\ipykernel_9524\\1006265385.py\", line 35, in paint\n",
      "    self.draw.line([x1, y1, x2, y2], fill=\"black\", width=5)\n",
      "AttributeError: 'DigitRecognitionApp' object has no attribute 'draw'\n",
      "Exception in Tkinter callback\n",
      "Traceback (most recent call last):\n",
      "  File \"C:\\ProgramData\\Anaconda3\\lib\\tkinter\\__init__.py\", line 1892, in __call__\n",
      "    return self.func(*args)\n",
      "  File \"C:\\Users\\sanjay\\AppData\\Local\\Temp\\ipykernel_9524\\1006265385.py\", line 35, in paint\n",
      "    self.draw.line([x1, y1, x2, y2], fill=\"black\", width=5)\n",
      "AttributeError: 'DigitRecognitionApp' object has no attribute 'draw'\n",
      "Exception in Tkinter callback\n",
      "Traceback (most recent call last):\n",
      "  File \"C:\\ProgramData\\Anaconda3\\lib\\tkinter\\__init__.py\", line 1892, in __call__\n",
      "    return self.func(*args)\n",
      "  File \"C:\\Users\\sanjay\\AppData\\Local\\Temp\\ipykernel_9524\\1006265385.py\", line 35, in paint\n",
      "    self.draw.line([x1, y1, x2, y2], fill=\"black\", width=5)\n",
      "AttributeError: 'DigitRecognitionApp' object has no attribute 'draw'\n",
      "Exception in Tkinter callback\n",
      "Traceback (most recent call last):\n",
      "  File \"C:\\ProgramData\\Anaconda3\\lib\\tkinter\\__init__.py\", line 1892, in __call__\n",
      "    return self.func(*args)\n",
      "  File \"C:\\Users\\sanjay\\AppData\\Local\\Temp\\ipykernel_9524\\1006265385.py\", line 35, in paint\n",
      "    self.draw.line([x1, y1, x2, y2], fill=\"black\", width=5)\n",
      "AttributeError: 'DigitRecognitionApp' object has no attribute 'draw'\n",
      "Exception in Tkinter callback\n",
      "Traceback (most recent call last):\n",
      "  File \"C:\\ProgramData\\Anaconda3\\lib\\tkinter\\__init__.py\", line 1892, in __call__\n",
      "    return self.func(*args)\n",
      "  File \"C:\\Users\\sanjay\\AppData\\Local\\Temp\\ipykernel_9524\\1006265385.py\", line 35, in paint\n",
      "    self.draw.line([x1, y1, x2, y2], fill=\"black\", width=5)\n",
      "AttributeError: 'DigitRecognitionApp' object has no attribute 'draw'\n",
      "Exception in Tkinter callback\n",
      "Traceback (most recent call last):\n",
      "  File \"C:\\ProgramData\\Anaconda3\\lib\\tkinter\\__init__.py\", line 1892, in __call__\n",
      "    return self.func(*args)\n",
      "  File \"C:\\Users\\sanjay\\AppData\\Local\\Temp\\ipykernel_9524\\1006265385.py\", line 35, in paint\n",
      "    self.draw.line([x1, y1, x2, y2], fill=\"black\", width=5)\n",
      "AttributeError: 'DigitRecognitionApp' object has no attribute 'draw'\n",
      "Exception in Tkinter callback\n",
      "Traceback (most recent call last):\n",
      "  File \"C:\\ProgramData\\Anaconda3\\lib\\tkinter\\__init__.py\", line 1892, in __call__\n",
      "    return self.func(*args)\n",
      "  File \"C:\\Users\\sanjay\\AppData\\Local\\Temp\\ipykernel_9524\\1006265385.py\", line 35, in paint\n",
      "    self.draw.line([x1, y1, x2, y2], fill=\"black\", width=5)\n",
      "AttributeError: 'DigitRecognitionApp' object has no attribute 'draw'\n",
      "Exception in Tkinter callback\n",
      "Traceback (most recent call last):\n",
      "  File \"C:\\ProgramData\\Anaconda3\\lib\\tkinter\\__init__.py\", line 1892, in __call__\n",
      "    return self.func(*args)\n",
      "  File \"C:\\Users\\sanjay\\AppData\\Local\\Temp\\ipykernel_9524\\1006265385.py\", line 35, in paint\n",
      "    self.draw.line([x1, y1, x2, y2], fill=\"black\", width=5)\n",
      "AttributeError: 'DigitRecognitionApp' object has no attribute 'draw'\n",
      "Exception in Tkinter callback\n",
      "Traceback (most recent call last):\n",
      "  File \"C:\\ProgramData\\Anaconda3\\lib\\tkinter\\__init__.py\", line 1892, in __call__\n",
      "    return self.func(*args)\n",
      "  File \"C:\\Users\\sanjay\\AppData\\Local\\Temp\\ipykernel_9524\\1006265385.py\", line 35, in paint\n",
      "    self.draw.line([x1, y1, x2, y2], fill=\"black\", width=5)\n",
      "AttributeError: 'DigitRecognitionApp' object has no attribute 'draw'\n",
      "Exception in Tkinter callback\n",
      "Traceback (most recent call last):\n",
      "  File \"C:\\ProgramData\\Anaconda3\\lib\\tkinter\\__init__.py\", line 1892, in __call__\n",
      "    return self.func(*args)\n",
      "  File \"C:\\Users\\sanjay\\AppData\\Local\\Temp\\ipykernel_9524\\1006265385.py\", line 35, in paint\n",
      "    self.draw.line([x1, y1, x2, y2], fill=\"black\", width=5)\n",
      "AttributeError: 'DigitRecognitionApp' object has no attribute 'draw'\n",
      "Exception in Tkinter callback\n",
      "Traceback (most recent call last):\n",
      "  File \"C:\\ProgramData\\Anaconda3\\lib\\tkinter\\__init__.py\", line 1892, in __call__\n",
      "    return self.func(*args)\n",
      "  File \"C:\\Users\\sanjay\\AppData\\Local\\Temp\\ipykernel_9524\\1006265385.py\", line 35, in paint\n",
      "    self.draw.line([x1, y1, x2, y2], fill=\"black\", width=5)\n",
      "AttributeError: 'DigitRecognitionApp' object has no attribute 'draw'\n",
      "Exception in Tkinter callback\n",
      "Traceback (most recent call last):\n",
      "  File \"C:\\ProgramData\\Anaconda3\\lib\\tkinter\\__init__.py\", line 1892, in __call__\n",
      "    return self.func(*args)\n",
      "  File \"C:\\Users\\sanjay\\AppData\\Local\\Temp\\ipykernel_9524\\1006265385.py\", line 35, in paint\n",
      "    self.draw.line([x1, y1, x2, y2], fill=\"black\", width=5)\n",
      "AttributeError: 'DigitRecognitionApp' object has no attribute 'draw'\n",
      "Exception in Tkinter callback\n",
      "Traceback (most recent call last):\n",
      "  File \"C:\\ProgramData\\Anaconda3\\lib\\tkinter\\__init__.py\", line 1892, in __call__\n",
      "    return self.func(*args)\n",
      "  File \"C:\\Users\\sanjay\\AppData\\Local\\Temp\\ipykernel_9524\\1006265385.py\", line 35, in paint\n",
      "    self.draw.line([x1, y1, x2, y2], fill=\"black\", width=5)\n",
      "AttributeError: 'DigitRecognitionApp' object has no attribute 'draw'\n",
      "Exception in Tkinter callback\n",
      "Traceback (most recent call last):\n",
      "  File \"C:\\ProgramData\\Anaconda3\\lib\\tkinter\\__init__.py\", line 1892, in __call__\n",
      "    return self.func(*args)\n",
      "  File \"C:\\Users\\sanjay\\AppData\\Local\\Temp\\ipykernel_9524\\1006265385.py\", line 35, in paint\n",
      "    self.draw.line([x1, y1, x2, y2], fill=\"black\", width=5)\n",
      "AttributeError: 'DigitRecognitionApp' object has no attribute 'draw'\n",
      "Exception in Tkinter callback\n",
      "Traceback (most recent call last):\n",
      "  File \"C:\\ProgramData\\Anaconda3\\lib\\tkinter\\__init__.py\", line 1892, in __call__\n",
      "    return self.func(*args)\n",
      "  File \"C:\\Users\\sanjay\\AppData\\Local\\Temp\\ipykernel_9524\\1006265385.py\", line 35, in paint\n",
      "    self.draw.line([x1, y1, x2, y2], fill=\"black\", width=5)\n",
      "AttributeError: 'DigitRecognitionApp' object has no attribute 'draw'\n",
      "Exception in Tkinter callback\n",
      "Traceback (most recent call last):\n",
      "  File \"C:\\ProgramData\\Anaconda3\\lib\\tkinter\\__init__.py\", line 1892, in __call__\n",
      "    return self.func(*args)\n",
      "  File \"C:\\Users\\sanjay\\AppData\\Local\\Temp\\ipykernel_9524\\1006265385.py\", line 35, in paint\n",
      "    self.draw.line([x1, y1, x2, y2], fill=\"black\", width=5)\n",
      "AttributeError: 'DigitRecognitionApp' object has no attribute 'draw'\n",
      "Exception in Tkinter callback\n",
      "Traceback (most recent call last):\n",
      "  File \"C:\\ProgramData\\Anaconda3\\lib\\tkinter\\__init__.py\", line 1892, in __call__\n",
      "    return self.func(*args)\n",
      "  File \"C:\\Users\\sanjay\\AppData\\Local\\Temp\\ipykernel_9524\\1006265385.py\", line 35, in paint\n",
      "    self.draw.line([x1, y1, x2, y2], fill=\"black\", width=5)\n",
      "AttributeError: 'DigitRecognitionApp' object has no attribute 'draw'\n",
      "Exception in Tkinter callback\n",
      "Traceback (most recent call last):\n",
      "  File \"C:\\ProgramData\\Anaconda3\\lib\\tkinter\\__init__.py\", line 1892, in __call__\n",
      "    return self.func(*args)\n",
      "  File \"C:\\Users\\sanjay\\AppData\\Local\\Temp\\ipykernel_9524\\1006265385.py\", line 35, in paint\n",
      "    self.draw.line([x1, y1, x2, y2], fill=\"black\", width=5)\n",
      "AttributeError: 'DigitRecognitionApp' object has no attribute 'draw'\n",
      "Exception in Tkinter callback\n",
      "Traceback (most recent call last):\n",
      "  File \"C:\\ProgramData\\Anaconda3\\lib\\tkinter\\__init__.py\", line 1892, in __call__\n",
      "    return self.func(*args)\n",
      "  File \"C:\\Users\\sanjay\\AppData\\Local\\Temp\\ipykernel_9524\\1006265385.py\", line 35, in paint\n",
      "    self.draw.line([x1, y1, x2, y2], fill=\"black\", width=5)\n",
      "AttributeError: 'DigitRecognitionApp' object has no attribute 'draw'\n",
      "Exception in Tkinter callback\n",
      "Traceback (most recent call last):\n",
      "  File \"C:\\ProgramData\\Anaconda3\\lib\\tkinter\\__init__.py\", line 1892, in __call__\n",
      "    return self.func(*args)\n",
      "  File \"C:\\Users\\sanjay\\AppData\\Local\\Temp\\ipykernel_9524\\1006265385.py\", line 35, in paint\n",
      "    self.draw.line([x1, y1, x2, y2], fill=\"black\", width=5)\n",
      "AttributeError: 'DigitRecognitionApp' object has no attribute 'draw'\n",
      "Exception in Tkinter callback\n",
      "Traceback (most recent call last):\n",
      "  File \"C:\\ProgramData\\Anaconda3\\lib\\tkinter\\__init__.py\", line 1892, in __call__\n",
      "    return self.func(*args)\n",
      "  File \"C:\\Users\\sanjay\\AppData\\Local\\Temp\\ipykernel_9524\\1006265385.py\", line 35, in paint\n",
      "    self.draw.line([x1, y1, x2, y2], fill=\"black\", width=5)\n",
      "AttributeError: 'DigitRecognitionApp' object has no attribute 'draw'\n",
      "Exception in Tkinter callback\n",
      "Traceback (most recent call last):\n",
      "  File \"C:\\ProgramData\\Anaconda3\\lib\\tkinter\\__init__.py\", line 1892, in __call__\n",
      "    return self.func(*args)\n",
      "  File \"C:\\Users\\sanjay\\AppData\\Local\\Temp\\ipykernel_9524\\1006265385.py\", line 35, in paint\n",
      "    self.draw.line([x1, y1, x2, y2], fill=\"black\", width=5)\n",
      "AttributeError: 'DigitRecognitionApp' object has no attribute 'draw'\n",
      "Exception in Tkinter callback\n",
      "Traceback (most recent call last):\n",
      "  File \"C:\\ProgramData\\Anaconda3\\lib\\tkinter\\__init__.py\", line 1892, in __call__\n",
      "    return self.func(*args)\n",
      "  File \"C:\\Users\\sanjay\\AppData\\Local\\Temp\\ipykernel_9524\\1006265385.py\", line 35, in paint\n",
      "    self.draw.line([x1, y1, x2, y2], fill=\"black\", width=5)\n",
      "AttributeError: 'DigitRecognitionApp' object has no attribute 'draw'\n",
      "Exception in Tkinter callback\n",
      "Traceback (most recent call last):\n",
      "  File \"C:\\ProgramData\\Anaconda3\\lib\\tkinter\\__init__.py\", line 1892, in __call__\n",
      "    return self.func(*args)\n",
      "  File \"C:\\Users\\sanjay\\AppData\\Local\\Temp\\ipykernel_9524\\1006265385.py\", line 35, in paint\n",
      "    self.draw.line([x1, y1, x2, y2], fill=\"black\", width=5)\n",
      "AttributeError: 'DigitRecognitionApp' object has no attribute 'draw'\n",
      "Exception in Tkinter callback\n",
      "Traceback (most recent call last):\n",
      "  File \"C:\\ProgramData\\Anaconda3\\lib\\tkinter\\__init__.py\", line 1892, in __call__\n",
      "    return self.func(*args)\n",
      "  File \"C:\\Users\\sanjay\\AppData\\Local\\Temp\\ipykernel_9524\\1006265385.py\", line 35, in paint\n",
      "    self.draw.line([x1, y1, x2, y2], fill=\"black\", width=5)\n",
      "AttributeError: 'DigitRecognitionApp' object has no attribute 'draw'\n",
      "Exception in Tkinter callback\n",
      "Traceback (most recent call last):\n",
      "  File \"C:\\ProgramData\\Anaconda3\\lib\\tkinter\\__init__.py\", line 1892, in __call__\n",
      "    return self.func(*args)\n",
      "  File \"C:\\Users\\sanjay\\AppData\\Local\\Temp\\ipykernel_9524\\1006265385.py\", line 35, in paint\n",
      "    self.draw.line([x1, y1, x2, y2], fill=\"black\", width=5)\n",
      "AttributeError: 'DigitRecognitionApp' object has no attribute 'draw'\n",
      "Exception in Tkinter callback\n",
      "Traceback (most recent call last):\n",
      "  File \"C:\\ProgramData\\Anaconda3\\lib\\tkinter\\__init__.py\", line 1892, in __call__\n",
      "    return self.func(*args)\n",
      "  File \"C:\\Users\\sanjay\\AppData\\Local\\Temp\\ipykernel_9524\\1006265385.py\", line 35, in paint\n",
      "    self.draw.line([x1, y1, x2, y2], fill=\"black\", width=5)\n",
      "AttributeError: 'DigitRecognitionApp' object has no attribute 'draw'\n",
      "Exception in Tkinter callback\n",
      "Traceback (most recent call last):\n",
      "  File \"C:\\ProgramData\\Anaconda3\\lib\\tkinter\\__init__.py\", line 1892, in __call__\n",
      "    return self.func(*args)\n",
      "  File \"C:\\Users\\sanjay\\AppData\\Local\\Temp\\ipykernel_9524\\1006265385.py\", line 35, in paint\n",
      "    self.draw.line([x1, y1, x2, y2], fill=\"black\", width=5)\n",
      "AttributeError: 'DigitRecognitionApp' object has no attribute 'draw'\n",
      "Exception in Tkinter callback\n",
      "Traceback (most recent call last):\n",
      "  File \"C:\\ProgramData\\Anaconda3\\lib\\tkinter\\__init__.py\", line 1892, in __call__\n",
      "    return self.func(*args)\n",
      "  File \"C:\\Users\\sanjay\\AppData\\Local\\Temp\\ipykernel_9524\\1006265385.py\", line 35, in paint\n",
      "    self.draw.line([x1, y1, x2, y2], fill=\"black\", width=5)\n",
      "AttributeError: 'DigitRecognitionApp' object has no attribute 'draw'\n",
      "Exception in Tkinter callback\n",
      "Traceback (most recent call last):\n",
      "  File \"C:\\ProgramData\\Anaconda3\\lib\\tkinter\\__init__.py\", line 1892, in __call__\n",
      "    return self.func(*args)\n",
      "  File \"C:\\Users\\sanjay\\AppData\\Local\\Temp\\ipykernel_9524\\1006265385.py\", line 35, in paint\n",
      "    self.draw.line([x1, y1, x2, y2], fill=\"black\", width=5)\n",
      "AttributeError: 'DigitRecognitionApp' object has no attribute 'draw'\n",
      "Exception in Tkinter callback\n",
      "Traceback (most recent call last):\n",
      "  File \"C:\\ProgramData\\Anaconda3\\lib\\tkinter\\__init__.py\", line 1892, in __call__\n",
      "    return self.func(*args)\n",
      "  File \"C:\\Users\\sanjay\\AppData\\Local\\Temp\\ipykernel_9524\\1006265385.py\", line 35, in paint\n",
      "    self.draw.line([x1, y1, x2, y2], fill=\"black\", width=5)\n",
      "AttributeError: 'DigitRecognitionApp' object has no attribute 'draw'\n",
      "Exception in Tkinter callback\n",
      "Traceback (most recent call last):\n",
      "  File \"C:\\ProgramData\\Anaconda3\\lib\\tkinter\\__init__.py\", line 1892, in __call__\n",
      "    return self.func(*args)\n",
      "  File \"C:\\Users\\sanjay\\AppData\\Local\\Temp\\ipykernel_9524\\1006265385.py\", line 35, in paint\n",
      "    self.draw.line([x1, y1, x2, y2], fill=\"black\", width=5)\n",
      "AttributeError: 'DigitRecognitionApp' object has no attribute 'draw'\n",
      "Exception in Tkinter callback\n",
      "Traceback (most recent call last):\n",
      "  File \"C:\\ProgramData\\Anaconda3\\lib\\tkinter\\__init__.py\", line 1892, in __call__\n",
      "    return self.func(*args)\n",
      "  File \"C:\\Users\\sanjay\\AppData\\Local\\Temp\\ipykernel_9524\\1006265385.py\", line 35, in paint\n",
      "    self.draw.line([x1, y1, x2, y2], fill=\"black\", width=5)\n",
      "AttributeError: 'DigitRecognitionApp' object has no attribute 'draw'\n",
      "Exception in Tkinter callback\n",
      "Traceback (most recent call last):\n",
      "  File \"C:\\ProgramData\\Anaconda3\\lib\\tkinter\\__init__.py\", line 1892, in __call__\n",
      "    return self.func(*args)\n",
      "  File \"C:\\Users\\sanjay\\AppData\\Local\\Temp\\ipykernel_9524\\1006265385.py\", line 35, in paint\n",
      "    self.draw.line([x1, y1, x2, y2], fill=\"black\", width=5)\n",
      "AttributeError: 'DigitRecognitionApp' object has no attribute 'draw'\n",
      "Exception in Tkinter callback\n",
      "Traceback (most recent call last):\n",
      "  File \"C:\\ProgramData\\Anaconda3\\lib\\tkinter\\__init__.py\", line 1892, in __call__\n",
      "    return self.func(*args)\n",
      "  File \"C:\\Users\\sanjay\\AppData\\Local\\Temp\\ipykernel_9524\\1006265385.py\", line 35, in paint\n",
      "    self.draw.line([x1, y1, x2, y2], fill=\"black\", width=5)\n",
      "AttributeError: 'DigitRecognitionApp' object has no attribute 'draw'\n",
      "Exception in Tkinter callback\n",
      "Traceback (most recent call last):\n",
      "  File \"C:\\ProgramData\\Anaconda3\\lib\\tkinter\\__init__.py\", line 1892, in __call__\n",
      "    return self.func(*args)\n",
      "  File \"C:\\Users\\sanjay\\AppData\\Local\\Temp\\ipykernel_9524\\1006265385.py\", line 35, in paint\n",
      "    self.draw.line([x1, y1, x2, y2], fill=\"black\", width=5)\n",
      "AttributeError: 'DigitRecognitionApp' object has no attribute 'draw'\n",
      "Exception in Tkinter callback\n",
      "Traceback (most recent call last):\n",
      "  File \"C:\\ProgramData\\Anaconda3\\lib\\tkinter\\__init__.py\", line 1892, in __call__\n",
      "    return self.func(*args)\n",
      "  File \"C:\\Users\\sanjay\\AppData\\Local\\Temp\\ipykernel_9524\\1006265385.py\", line 35, in paint\n",
      "    self.draw.line([x1, y1, x2, y2], fill=\"black\", width=5)\n",
      "AttributeError: 'DigitRecognitionApp' object has no attribute 'draw'\n",
      "Exception in Tkinter callback\n",
      "Traceback (most recent call last):\n",
      "  File \"C:\\ProgramData\\Anaconda3\\lib\\tkinter\\__init__.py\", line 1892, in __call__\n",
      "    return self.func(*args)\n",
      "  File \"C:\\Users\\sanjay\\AppData\\Local\\Temp\\ipykernel_9524\\1006265385.py\", line 35, in paint\n",
      "    self.draw.line([x1, y1, x2, y2], fill=\"black\", width=5)\n",
      "AttributeError: 'DigitRecognitionApp' object has no attribute 'draw'\n",
      "Exception in Tkinter callback\n",
      "Traceback (most recent call last):\n",
      "  File \"C:\\ProgramData\\Anaconda3\\lib\\tkinter\\__init__.py\", line 1892, in __call__\n",
      "    return self.func(*args)\n",
      "  File \"C:\\Users\\sanjay\\AppData\\Local\\Temp\\ipykernel_9524\\1006265385.py\", line 35, in paint\n",
      "    self.draw.line([x1, y1, x2, y2], fill=\"black\", width=5)\n",
      "AttributeError: 'DigitRecognitionApp' object has no attribute 'draw'\n",
      "Exception in Tkinter callback\n",
      "Traceback (most recent call last):\n",
      "  File \"C:\\ProgramData\\Anaconda3\\lib\\tkinter\\__init__.py\", line 1892, in __call__\n",
      "    return self.func(*args)\n",
      "  File \"C:\\Users\\sanjay\\AppData\\Local\\Temp\\ipykernel_9524\\1006265385.py\", line 35, in paint\n",
      "    self.draw.line([x1, y1, x2, y2], fill=\"black\", width=5)\n",
      "AttributeError: 'DigitRecognitionApp' object has no attribute 'draw'\n",
      "Exception in Tkinter callback\n",
      "Traceback (most recent call last):\n",
      "  File \"C:\\ProgramData\\Anaconda3\\lib\\tkinter\\__init__.py\", line 1892, in __call__\n",
      "    return self.func(*args)\n",
      "  File \"C:\\Users\\sanjay\\AppData\\Local\\Temp\\ipykernel_9524\\1006265385.py\", line 35, in paint\n",
      "    self.draw.line([x1, y1, x2, y2], fill=\"black\", width=5)\n",
      "AttributeError: 'DigitRecognitionApp' object has no attribute 'draw'\n",
      "Exception in Tkinter callback\n",
      "Traceback (most recent call last):\n",
      "  File \"C:\\ProgramData\\Anaconda3\\lib\\tkinter\\__init__.py\", line 1892, in __call__\n",
      "    return self.func(*args)\n",
      "  File \"C:\\Users\\sanjay\\AppData\\Local\\Temp\\ipykernel_9524\\1006265385.py\", line 35, in paint\n",
      "    self.draw.line([x1, y1, x2, y2], fill=\"black\", width=5)\n",
      "AttributeError: 'DigitRecognitionApp' object has no attribute 'draw'\n",
      "Exception in Tkinter callback\n",
      "Traceback (most recent call last):\n",
      "  File \"C:\\ProgramData\\Anaconda3\\lib\\tkinter\\__init__.py\", line 1892, in __call__\n",
      "    return self.func(*args)\n",
      "  File \"C:\\Users\\sanjay\\AppData\\Local\\Temp\\ipykernel_9524\\1006265385.py\", line 35, in paint\n",
      "    self.draw.line([x1, y1, x2, y2], fill=\"black\", width=5)\n",
      "AttributeError: 'DigitRecognitionApp' object has no attribute 'draw'\n",
      "Exception in Tkinter callback\n",
      "Traceback (most recent call last):\n",
      "  File \"C:\\ProgramData\\Anaconda3\\lib\\tkinter\\__init__.py\", line 1892, in __call__\n",
      "    return self.func(*args)\n",
      "  File \"C:\\Users\\sanjay\\AppData\\Local\\Temp\\ipykernel_9524\\1006265385.py\", line 35, in paint\n",
      "    self.draw.line([x1, y1, x2, y2], fill=\"black\", width=5)\n",
      "AttributeError: 'DigitRecognitionApp' object has no attribute 'draw'\n",
      "Exception in Tkinter callback\n",
      "Traceback (most recent call last):\n",
      "  File \"C:\\ProgramData\\Anaconda3\\lib\\tkinter\\__init__.py\", line 1892, in __call__\n",
      "    return self.func(*args)\n",
      "  File \"C:\\Users\\sanjay\\AppData\\Local\\Temp\\ipykernel_9524\\1006265385.py\", line 35, in paint\n",
      "    self.draw.line([x1, y1, x2, y2], fill=\"black\", width=5)\n",
      "AttributeError: 'DigitRecognitionApp' object has no attribute 'draw'\n",
      "Exception in Tkinter callback\n",
      "Traceback (most recent call last):\n",
      "  File \"C:\\ProgramData\\Anaconda3\\lib\\tkinter\\__init__.py\", line 1892, in __call__\n",
      "    return self.func(*args)\n",
      "  File \"C:\\Users\\sanjay\\AppData\\Local\\Temp\\ipykernel_9524\\1006265385.py\", line 35, in paint\n",
      "    self.draw.line([x1, y1, x2, y2], fill=\"black\", width=5)\n",
      "AttributeError: 'DigitRecognitionApp' object has no attribute 'draw'\n",
      "Exception in Tkinter callback\n",
      "Traceback (most recent call last):\n",
      "  File \"C:\\ProgramData\\Anaconda3\\lib\\tkinter\\__init__.py\", line 1892, in __call__\n",
      "    return self.func(*args)\n",
      "  File \"C:\\Users\\sanjay\\AppData\\Local\\Temp\\ipykernel_9524\\1006265385.py\", line 35, in paint\n",
      "    self.draw.line([x1, y1, x2, y2], fill=\"black\", width=5)\n",
      "AttributeError: 'DigitRecognitionApp' object has no attribute 'draw'\n",
      "Exception in Tkinter callback\n",
      "Traceback (most recent call last):\n",
      "  File \"C:\\ProgramData\\Anaconda3\\lib\\tkinter\\__init__.py\", line 1892, in __call__\n",
      "    return self.func(*args)\n",
      "  File \"C:\\Users\\sanjay\\AppData\\Local\\Temp\\ipykernel_9524\\1006265385.py\", line 35, in paint\n",
      "    self.draw.line([x1, y1, x2, y2], fill=\"black\", width=5)\n",
      "AttributeError: 'DigitRecognitionApp' object has no attribute 'draw'\n",
      "Exception in Tkinter callback\n",
      "Traceback (most recent call last):\n",
      "  File \"C:\\ProgramData\\Anaconda3\\lib\\tkinter\\__init__.py\", line 1892, in __call__\n",
      "    return self.func(*args)\n",
      "  File \"C:\\Users\\sanjay\\AppData\\Local\\Temp\\ipykernel_9524\\1006265385.py\", line 35, in paint\n",
      "    self.draw.line([x1, y1, x2, y2], fill=\"black\", width=5)\n",
      "AttributeError: 'DigitRecognitionApp' object has no attribute 'draw'\n",
      "Exception in Tkinter callback\n",
      "Traceback (most recent call last):\n",
      "  File \"C:\\ProgramData\\Anaconda3\\lib\\tkinter\\__init__.py\", line 1892, in __call__\n",
      "    return self.func(*args)\n",
      "  File \"C:\\Users\\sanjay\\AppData\\Local\\Temp\\ipykernel_9524\\1006265385.py\", line 35, in paint\n",
      "    self.draw.line([x1, y1, x2, y2], fill=\"black\", width=5)\n",
      "AttributeError: 'DigitRecognitionApp' object has no attribute 'draw'\n",
      "Exception in Tkinter callback\n",
      "Traceback (most recent call last):\n",
      "  File \"C:\\ProgramData\\Anaconda3\\lib\\tkinter\\__init__.py\", line 1892, in __call__\n",
      "    return self.func(*args)\n",
      "  File \"C:\\Users\\sanjay\\AppData\\Local\\Temp\\ipykernel_9524\\1006265385.py\", line 35, in paint\n",
      "    self.draw.line([x1, y1, x2, y2], fill=\"black\", width=5)\n",
      "AttributeError: 'DigitRecognitionApp' object has no attribute 'draw'\n",
      "Exception in Tkinter callback\n",
      "Traceback (most recent call last):\n",
      "  File \"C:\\ProgramData\\Anaconda3\\lib\\tkinter\\__init__.py\", line 1892, in __call__\n",
      "    return self.func(*args)\n",
      "  File \"C:\\Users\\sanjay\\AppData\\Local\\Temp\\ipykernel_9524\\1006265385.py\", line 35, in paint\n",
      "    self.draw.line([x1, y1, x2, y2], fill=\"black\", width=5)\n",
      "AttributeError: 'DigitRecognitionApp' object has no attribute 'draw'\n",
      "Exception in Tkinter callback\n",
      "Traceback (most recent call last):\n",
      "  File \"C:\\ProgramData\\Anaconda3\\lib\\tkinter\\__init__.py\", line 1892, in __call__\n",
      "    return self.func(*args)\n",
      "  File \"C:\\Users\\sanjay\\AppData\\Local\\Temp\\ipykernel_9524\\1006265385.py\", line 35, in paint\n",
      "    self.draw.line([x1, y1, x2, y2], fill=\"black\", width=5)\n",
      "AttributeError: 'DigitRecognitionApp' object has no attribute 'draw'\n",
      "Exception in Tkinter callback\n",
      "Traceback (most recent call last):\n",
      "  File \"C:\\ProgramData\\Anaconda3\\lib\\tkinter\\__init__.py\", line 1892, in __call__\n",
      "    return self.func(*args)\n",
      "  File \"C:\\Users\\sanjay\\AppData\\Local\\Temp\\ipykernel_9524\\1006265385.py\", line 35, in paint\n",
      "    self.draw.line([x1, y1, x2, y2], fill=\"black\", width=5)\n",
      "AttributeError: 'DigitRecognitionApp' object has no attribute 'draw'\n",
      "Exception in Tkinter callback\n",
      "Traceback (most recent call last):\n",
      "  File \"C:\\ProgramData\\Anaconda3\\lib\\tkinter\\__init__.py\", line 1892, in __call__\n",
      "    return self.func(*args)\n",
      "  File \"C:\\Users\\sanjay\\AppData\\Local\\Temp\\ipykernel_9524\\1006265385.py\", line 35, in paint\n",
      "    self.draw.line([x1, y1, x2, y2], fill=\"black\", width=5)\n",
      "AttributeError: 'DigitRecognitionApp' object has no attribute 'draw'\n",
      "Exception in Tkinter callback\n",
      "Traceback (most recent call last):\n",
      "  File \"C:\\ProgramData\\Anaconda3\\lib\\tkinter\\__init__.py\", line 1892, in __call__\n",
      "    return self.func(*args)\n",
      "  File \"C:\\Users\\sanjay\\AppData\\Local\\Temp\\ipykernel_9524\\1006265385.py\", line 35, in paint\n",
      "    self.draw.line([x1, y1, x2, y2], fill=\"black\", width=5)\n",
      "AttributeError: 'DigitRecognitionApp' object has no attribute 'draw'\n",
      "Exception in Tkinter callback\n",
      "Traceback (most recent call last):\n",
      "  File \"C:\\ProgramData\\Anaconda3\\lib\\tkinter\\__init__.py\", line 1892, in __call__\n",
      "    return self.func(*args)\n",
      "  File \"C:\\Users\\sanjay\\AppData\\Local\\Temp\\ipykernel_9524\\1006265385.py\", line 35, in paint\n",
      "    self.draw.line([x1, y1, x2, y2], fill=\"black\", width=5)\n",
      "AttributeError: 'DigitRecognitionApp' object has no attribute 'draw'\n",
      "Exception in Tkinter callback\n",
      "Traceback (most recent call last):\n",
      "  File \"C:\\ProgramData\\Anaconda3\\lib\\tkinter\\__init__.py\", line 1892, in __call__\n",
      "    return self.func(*args)\n",
      "  File \"C:\\Users\\sanjay\\AppData\\Local\\Temp\\ipykernel_9524\\1006265385.py\", line 35, in paint\n",
      "    self.draw.line([x1, y1, x2, y2], fill=\"black\", width=5)\n",
      "AttributeError: 'DigitRecognitionApp' object has no attribute 'draw'\n",
      "Exception in Tkinter callback\n",
      "Traceback (most recent call last):\n",
      "  File \"C:\\ProgramData\\Anaconda3\\lib\\tkinter\\__init__.py\", line 1892, in __call__\n",
      "    return self.func(*args)\n",
      "  File \"C:\\Users\\sanjay\\AppData\\Local\\Temp\\ipykernel_9524\\1006265385.py\", line 35, in paint\n",
      "    self.draw.line([x1, y1, x2, y2], fill=\"black\", width=5)\n",
      "AttributeError: 'DigitRecognitionApp' object has no attribute 'draw'\n",
      "Exception in Tkinter callback\n",
      "Traceback (most recent call last):\n",
      "  File \"C:\\ProgramData\\Anaconda3\\lib\\tkinter\\__init__.py\", line 1892, in __call__\n",
      "    return self.func(*args)\n",
      "  File \"C:\\Users\\sanjay\\AppData\\Local\\Temp\\ipykernel_9524\\1006265385.py\", line 35, in paint\n",
      "    self.draw.line([x1, y1, x2, y2], fill=\"black\", width=5)\n",
      "AttributeError: 'DigitRecognitionApp' object has no attribute 'draw'\n",
      "Exception in Tkinter callback\n",
      "Traceback (most recent call last):\n",
      "  File \"C:\\ProgramData\\Anaconda3\\lib\\tkinter\\__init__.py\", line 1892, in __call__\n",
      "    return self.func(*args)\n",
      "  File \"C:\\Users\\sanjay\\AppData\\Local\\Temp\\ipykernel_9524\\1006265385.py\", line 35, in paint\n",
      "    self.draw.line([x1, y1, x2, y2], fill=\"black\", width=5)\n",
      "AttributeError: 'DigitRecognitionApp' object has no attribute 'draw'\n",
      "Exception in Tkinter callback\n",
      "Traceback (most recent call last):\n",
      "  File \"C:\\ProgramData\\Anaconda3\\lib\\tkinter\\__init__.py\", line 1892, in __call__\n",
      "    return self.func(*args)\n",
      "  File \"C:\\Users\\sanjay\\AppData\\Local\\Temp\\ipykernel_9524\\1006265385.py\", line 35, in paint\n",
      "    self.draw.line([x1, y1, x2, y2], fill=\"black\", width=5)\n",
      "AttributeError: 'DigitRecognitionApp' object has no attribute 'draw'\n",
      "Exception in Tkinter callback\n",
      "Traceback (most recent call last):\n",
      "  File \"C:\\ProgramData\\Anaconda3\\lib\\tkinter\\__init__.py\", line 1892, in __call__\n",
      "    return self.func(*args)\n",
      "  File \"C:\\Users\\sanjay\\AppData\\Local\\Temp\\ipykernel_9524\\1006265385.py\", line 35, in paint\n",
      "    self.draw.line([x1, y1, x2, y2], fill=\"black\", width=5)\n",
      "AttributeError: 'DigitRecognitionApp' object has no attribute 'draw'\n",
      "Exception in Tkinter callback\n",
      "Traceback (most recent call last):\n",
      "  File \"C:\\ProgramData\\Anaconda3\\lib\\tkinter\\__init__.py\", line 1892, in __call__\n",
      "    return self.func(*args)\n",
      "  File \"C:\\Users\\sanjay\\AppData\\Local\\Temp\\ipykernel_9524\\1006265385.py\", line 35, in paint\n",
      "    self.draw.line([x1, y1, x2, y2], fill=\"black\", width=5)\n",
      "AttributeError: 'DigitRecognitionApp' object has no attribute 'draw'\n",
      "Exception in Tkinter callback\n",
      "Traceback (most recent call last):\n",
      "  File \"C:\\ProgramData\\Anaconda3\\lib\\tkinter\\__init__.py\", line 1892, in __call__\n",
      "    return self.func(*args)\n",
      "  File \"C:\\Users\\sanjay\\AppData\\Local\\Temp\\ipykernel_9524\\1006265385.py\", line 35, in paint\n",
      "    self.draw.line([x1, y1, x2, y2], fill=\"black\", width=5)\n",
      "AttributeError: 'DigitRecognitionApp' object has no attribute 'draw'\n",
      "Exception in Tkinter callback\n",
      "Traceback (most recent call last):\n",
      "  File \"C:\\ProgramData\\Anaconda3\\lib\\tkinter\\__init__.py\", line 1892, in __call__\n",
      "    return self.func(*args)\n",
      "  File \"C:\\Users\\sanjay\\AppData\\Local\\Temp\\ipykernel_9524\\1006265385.py\", line 35, in paint\n",
      "    self.draw.line([x1, y1, x2, y2], fill=\"black\", width=5)\n",
      "AttributeError: 'DigitRecognitionApp' object has no attribute 'draw'\n",
      "Exception in Tkinter callback\n",
      "Traceback (most recent call last):\n",
      "  File \"C:\\ProgramData\\Anaconda3\\lib\\tkinter\\__init__.py\", line 1892, in __call__\n",
      "    return self.func(*args)\n",
      "  File \"C:\\Users\\sanjay\\AppData\\Local\\Temp\\ipykernel_9524\\1006265385.py\", line 35, in paint\n",
      "    self.draw.line([x1, y1, x2, y2], fill=\"black\", width=5)\n",
      "AttributeError: 'DigitRecognitionApp' object has no attribute 'draw'\n",
      "Exception in Tkinter callback\n",
      "Traceback (most recent call last):\n",
      "  File \"C:\\ProgramData\\Anaconda3\\lib\\tkinter\\__init__.py\", line 1892, in __call__\n",
      "    return self.func(*args)\n",
      "  File \"C:\\Users\\sanjay\\AppData\\Local\\Temp\\ipykernel_9524\\1006265385.py\", line 35, in paint\n",
      "    self.draw.line([x1, y1, x2, y2], fill=\"black\", width=5)\n",
      "AttributeError: 'DigitRecognitionApp' object has no attribute 'draw'\n",
      "Exception in Tkinter callback\n",
      "Traceback (most recent call last):\n",
      "  File \"C:\\ProgramData\\Anaconda3\\lib\\tkinter\\__init__.py\", line 1892, in __call__\n",
      "    return self.func(*args)\n",
      "  File \"C:\\Users\\sanjay\\AppData\\Local\\Temp\\ipykernel_9524\\1006265385.py\", line 35, in paint\n",
      "    self.draw.line([x1, y1, x2, y2], fill=\"black\", width=5)\n",
      "AttributeError: 'DigitRecognitionApp' object has no attribute 'draw'\n",
      "Exception in Tkinter callback\n",
      "Traceback (most recent call last):\n",
      "  File \"C:\\ProgramData\\Anaconda3\\lib\\tkinter\\__init__.py\", line 1892, in __call__\n",
      "    return self.func(*args)\n",
      "  File \"C:\\Users\\sanjay\\AppData\\Local\\Temp\\ipykernel_9524\\1006265385.py\", line 35, in paint\n",
      "    self.draw.line([x1, y1, x2, y2], fill=\"black\", width=5)\n",
      "AttributeError: 'DigitRecognitionApp' object has no attribute 'draw'\n",
      "Exception in Tkinter callback\n",
      "Traceback (most recent call last):\n",
      "  File \"C:\\ProgramData\\Anaconda3\\lib\\tkinter\\__init__.py\", line 1892, in __call__\n",
      "    return self.func(*args)\n",
      "  File \"C:\\Users\\sanjay\\AppData\\Local\\Temp\\ipykernel_9524\\1006265385.py\", line 35, in paint\n",
      "    self.draw.line([x1, y1, x2, y2], fill=\"black\", width=5)\n",
      "AttributeError: 'DigitRecognitionApp' object has no attribute 'draw'\n",
      "Exception in Tkinter callback\n",
      "Traceback (most recent call last):\n",
      "  File \"C:\\ProgramData\\Anaconda3\\lib\\tkinter\\__init__.py\", line 1892, in __call__\n",
      "    return self.func(*args)\n",
      "  File \"C:\\Users\\sanjay\\AppData\\Local\\Temp\\ipykernel_9524\\1006265385.py\", line 35, in paint\n",
      "    self.draw.line([x1, y1, x2, y2], fill=\"black\", width=5)\n",
      "AttributeError: 'DigitRecognitionApp' object has no attribute 'draw'\n",
      "Exception in Tkinter callback\n",
      "Traceback (most recent call last):\n",
      "  File \"C:\\ProgramData\\Anaconda3\\lib\\tkinter\\__init__.py\", line 1892, in __call__\n",
      "    return self.func(*args)\n",
      "  File \"C:\\Users\\sanjay\\AppData\\Local\\Temp\\ipykernel_9524\\1006265385.py\", line 35, in paint\n",
      "    self.draw.line([x1, y1, x2, y2], fill=\"black\", width=5)\n",
      "AttributeError: 'DigitRecognitionApp' object has no attribute 'draw'\n",
      "Exception in Tkinter callback\n",
      "Traceback (most recent call last):\n",
      "  File \"C:\\ProgramData\\Anaconda3\\lib\\tkinter\\__init__.py\", line 1892, in __call__\n",
      "    return self.func(*args)\n",
      "  File \"C:\\Users\\sanjay\\AppData\\Local\\Temp\\ipykernel_9524\\1006265385.py\", line 35, in paint\n",
      "    self.draw.line([x1, y1, x2, y2], fill=\"black\", width=5)\n",
      "AttributeError: 'DigitRecognitionApp' object has no attribute 'draw'\n",
      "Exception in Tkinter callback\n",
      "Traceback (most recent call last):\n",
      "  File \"C:\\ProgramData\\Anaconda3\\lib\\tkinter\\__init__.py\", line 1892, in __call__\n",
      "    return self.func(*args)\n",
      "  File \"C:\\Users\\sanjay\\AppData\\Local\\Temp\\ipykernel_9524\\1006265385.py\", line 35, in paint\n",
      "    self.draw.line([x1, y1, x2, y2], fill=\"black\", width=5)\n",
      "AttributeError: 'DigitRecognitionApp' object has no attribute 'draw'\n",
      "Exception in Tkinter callback\n",
      "Traceback (most recent call last):\n",
      "  File \"C:\\ProgramData\\Anaconda3\\lib\\tkinter\\__init__.py\", line 1892, in __call__\n",
      "    return self.func(*args)\n",
      "  File \"C:\\Users\\sanjay\\AppData\\Local\\Temp\\ipykernel_9524\\1006265385.py\", line 35, in paint\n",
      "    self.draw.line([x1, y1, x2, y2], fill=\"black\", width=5)\n",
      "AttributeError: 'DigitRecognitionApp' object has no attribute 'draw'\n",
      "Exception in Tkinter callback\n",
      "Traceback (most recent call last):\n",
      "  File \"C:\\ProgramData\\Anaconda3\\lib\\tkinter\\__init__.py\", line 1892, in __call__\n",
      "    return self.func(*args)\n",
      "  File \"C:\\Users\\sanjay\\AppData\\Local\\Temp\\ipykernel_9524\\1006265385.py\", line 35, in paint\n",
      "    self.draw.line([x1, y1, x2, y2], fill=\"black\", width=5)\n",
      "AttributeError: 'DigitRecognitionApp' object has no attribute 'draw'\n",
      "Exception in Tkinter callback\n",
      "Traceback (most recent call last):\n",
      "  File \"C:\\ProgramData\\Anaconda3\\lib\\tkinter\\__init__.py\", line 1892, in __call__\n",
      "    return self.func(*args)\n",
      "  File \"C:\\Users\\sanjay\\AppData\\Local\\Temp\\ipykernel_9524\\1006265385.py\", line 35, in paint\n",
      "    self.draw.line([x1, y1, x2, y2], fill=\"black\", width=5)\n",
      "AttributeError: 'DigitRecognitionApp' object has no attribute 'draw'\n",
      "Exception in Tkinter callback\n",
      "Traceback (most recent call last):\n",
      "  File \"C:\\ProgramData\\Anaconda3\\lib\\tkinter\\__init__.py\", line 1892, in __call__\n",
      "    return self.func(*args)\n",
      "  File \"C:\\Users\\sanjay\\AppData\\Local\\Temp\\ipykernel_9524\\1006265385.py\", line 35, in paint\n",
      "    self.draw.line([x1, y1, x2, y2], fill=\"black\", width=5)\n",
      "AttributeError: 'DigitRecognitionApp' object has no attribute 'draw'\n",
      "Exception in Tkinter callback\n",
      "Traceback (most recent call last):\n",
      "  File \"C:\\ProgramData\\Anaconda3\\lib\\tkinter\\__init__.py\", line 1892, in __call__\n",
      "    return self.func(*args)\n",
      "  File \"C:\\Users\\sanjay\\AppData\\Local\\Temp\\ipykernel_9524\\1006265385.py\", line 35, in paint\n",
      "    self.draw.line([x1, y1, x2, y2], fill=\"black\", width=5)\n",
      "AttributeError: 'DigitRecognitionApp' object has no attribute 'draw'\n",
      "Exception in Tkinter callback\n",
      "Traceback (most recent call last):\n",
      "  File \"C:\\ProgramData\\Anaconda3\\lib\\tkinter\\__init__.py\", line 1892, in __call__\n",
      "    return self.func(*args)\n",
      "  File \"C:\\Users\\sanjay\\AppData\\Local\\Temp\\ipykernel_9524\\1006265385.py\", line 35, in paint\n",
      "    self.draw.line([x1, y1, x2, y2], fill=\"black\", width=5)\n",
      "AttributeError: 'DigitRecognitionApp' object has no attribute 'draw'\n",
      "Exception in Tkinter callback\n",
      "Traceback (most recent call last):\n",
      "  File \"C:\\ProgramData\\Anaconda3\\lib\\tkinter\\__init__.py\", line 1892, in __call__\n",
      "    return self.func(*args)\n",
      "  File \"C:\\Users\\sanjay\\AppData\\Local\\Temp\\ipykernel_9524\\1006265385.py\", line 35, in paint\n",
      "    self.draw.line([x1, y1, x2, y2], fill=\"black\", width=5)\n",
      "AttributeError: 'DigitRecognitionApp' object has no attribute 'draw'\n",
      "Exception in Tkinter callback\n",
      "Traceback (most recent call last):\n",
      "  File \"C:\\ProgramData\\Anaconda3\\lib\\tkinter\\__init__.py\", line 1892, in __call__\n",
      "    return self.func(*args)\n",
      "  File \"C:\\Users\\sanjay\\AppData\\Local\\Temp\\ipykernel_9524\\1006265385.py\", line 35, in paint\n",
      "    self.draw.line([x1, y1, x2, y2], fill=\"black\", width=5)\n",
      "AttributeError: 'DigitRecognitionApp' object has no attribute 'draw'\n",
      "Exception in Tkinter callback\n",
      "Traceback (most recent call last):\n",
      "  File \"C:\\ProgramData\\Anaconda3\\lib\\tkinter\\__init__.py\", line 1892, in __call__\n",
      "    return self.func(*args)\n",
      "  File \"C:\\Users\\sanjay\\AppData\\Local\\Temp\\ipykernel_9524\\1006265385.py\", line 35, in paint\n",
      "    self.draw.line([x1, y1, x2, y2], fill=\"black\", width=5)\n",
      "AttributeError: 'DigitRecognitionApp' object has no attribute 'draw'\n",
      "Exception in Tkinter callback\n",
      "Traceback (most recent call last):\n",
      "  File \"C:\\ProgramData\\Anaconda3\\lib\\tkinter\\__init__.py\", line 1892, in __call__\n",
      "    return self.func(*args)\n",
      "  File \"C:\\Users\\sanjay\\AppData\\Local\\Temp\\ipykernel_9524\\1006265385.py\", line 35, in paint\n",
      "    self.draw.line([x1, y1, x2, y2], fill=\"black\", width=5)\n",
      "AttributeError: 'DigitRecognitionApp' object has no attribute 'draw'\n",
      "Exception in Tkinter callback\n",
      "Traceback (most recent call last):\n",
      "  File \"C:\\ProgramData\\Anaconda3\\lib\\tkinter\\__init__.py\", line 1892, in __call__\n",
      "    return self.func(*args)\n",
      "  File \"C:\\Users\\sanjay\\AppData\\Local\\Temp\\ipykernel_9524\\1006265385.py\", line 35, in paint\n",
      "    self.draw.line([x1, y1, x2, y2], fill=\"black\", width=5)\n",
      "AttributeError: 'DigitRecognitionApp' object has no attribute 'draw'\n",
      "Exception in Tkinter callback\n",
      "Traceback (most recent call last):\n",
      "  File \"C:\\ProgramData\\Anaconda3\\lib\\tkinter\\__init__.py\", line 1892, in __call__\n",
      "    return self.func(*args)\n",
      "  File \"C:\\Users\\sanjay\\AppData\\Local\\Temp\\ipykernel_9524\\1006265385.py\", line 35, in paint\n",
      "    self.draw.line([x1, y1, x2, y2], fill=\"black\", width=5)\n",
      "AttributeError: 'DigitRecognitionApp' object has no attribute 'draw'\n",
      "Exception in Tkinter callback\n",
      "Traceback (most recent call last):\n",
      "  File \"C:\\ProgramData\\Anaconda3\\lib\\tkinter\\__init__.py\", line 1892, in __call__\n",
      "    return self.func(*args)\n",
      "  File \"C:\\Users\\sanjay\\AppData\\Local\\Temp\\ipykernel_9524\\1006265385.py\", line 35, in paint\n",
      "    self.draw.line([x1, y1, x2, y2], fill=\"black\", width=5)\n",
      "AttributeError: 'DigitRecognitionApp' object has no attribute 'draw'\n",
      "Exception in Tkinter callback\n",
      "Traceback (most recent call last):\n",
      "  File \"C:\\ProgramData\\Anaconda3\\lib\\tkinter\\__init__.py\", line 1892, in __call__\n",
      "    return self.func(*args)\n",
      "  File \"C:\\Users\\sanjay\\AppData\\Local\\Temp\\ipykernel_9524\\1006265385.py\", line 35, in paint\n",
      "    self.draw.line([x1, y1, x2, y2], fill=\"black\", width=5)\n",
      "AttributeError: 'DigitRecognitionApp' object has no attribute 'draw'\n",
      "Exception in Tkinter callback\n",
      "Traceback (most recent call last):\n",
      "  File \"C:\\ProgramData\\Anaconda3\\lib\\tkinter\\__init__.py\", line 1892, in __call__\n",
      "    return self.func(*args)\n",
      "  File \"C:\\Users\\sanjay\\AppData\\Local\\Temp\\ipykernel_9524\\1006265385.py\", line 35, in paint\n",
      "    self.draw.line([x1, y1, x2, y2], fill=\"black\", width=5)\n",
      "AttributeError: 'DigitRecognitionApp' object has no attribute 'draw'\n",
      "Exception in Tkinter callback\n",
      "Traceback (most recent call last):\n",
      "  File \"C:\\ProgramData\\Anaconda3\\lib\\tkinter\\__init__.py\", line 1892, in __call__\n",
      "    return self.func(*args)\n",
      "  File \"C:\\Users\\sanjay\\AppData\\Local\\Temp\\ipykernel_9524\\1006265385.py\", line 35, in paint\n",
      "    self.draw.line([x1, y1, x2, y2], fill=\"black\", width=5)\n",
      "AttributeError: 'DigitRecognitionApp' object has no attribute 'draw'\n",
      "Exception in Tkinter callback\n",
      "Traceback (most recent call last):\n",
      "  File \"C:\\ProgramData\\Anaconda3\\lib\\tkinter\\__init__.py\", line 1892, in __call__\n",
      "    return self.func(*args)\n",
      "  File \"C:\\Users\\sanjay\\AppData\\Local\\Temp\\ipykernel_9524\\1006265385.py\", line 35, in paint\n",
      "    self.draw.line([x1, y1, x2, y2], fill=\"black\", width=5)\n",
      "AttributeError: 'DigitRecognitionApp' object has no attribute 'draw'\n",
      "Exception in Tkinter callback\n",
      "Traceback (most recent call last):\n",
      "  File \"C:\\ProgramData\\Anaconda3\\lib\\tkinter\\__init__.py\", line 1892, in __call__\n",
      "    return self.func(*args)\n",
      "  File \"C:\\Users\\sanjay\\AppData\\Local\\Temp\\ipykernel_9524\\1006265385.py\", line 35, in paint\n",
      "    self.draw.line([x1, y1, x2, y2], fill=\"black\", width=5)\n",
      "AttributeError: 'DigitRecognitionApp' object has no attribute 'draw'\n",
      "Exception in Tkinter callback\n",
      "Traceback (most recent call last):\n",
      "  File \"C:\\ProgramData\\Anaconda3\\lib\\tkinter\\__init__.py\", line 1892, in __call__\n",
      "    return self.func(*args)\n",
      "  File \"C:\\Users\\sanjay\\AppData\\Local\\Temp\\ipykernel_9524\\1006265385.py\", line 35, in paint\n",
      "    self.draw.line([x1, y1, x2, y2], fill=\"black\", width=5)\n",
      "AttributeError: 'DigitRecognitionApp' object has no attribute 'draw'\n",
      "Exception in Tkinter callback\n",
      "Traceback (most recent call last):\n",
      "  File \"C:\\ProgramData\\Anaconda3\\lib\\tkinter\\__init__.py\", line 1892, in __call__\n",
      "    return self.func(*args)\n",
      "  File \"C:\\Users\\sanjay\\AppData\\Local\\Temp\\ipykernel_9524\\1006265385.py\", line 35, in paint\n",
      "    self.draw.line([x1, y1, x2, y2], fill=\"black\", width=5)\n",
      "AttributeError: 'DigitRecognitionApp' object has no attribute 'draw'\n",
      "Exception in Tkinter callback\n",
      "Traceback (most recent call last):\n",
      "  File \"C:\\ProgramData\\Anaconda3\\lib\\tkinter\\__init__.py\", line 1892, in __call__\n",
      "    return self.func(*args)\n",
      "  File \"C:\\Users\\sanjay\\AppData\\Local\\Temp\\ipykernel_9524\\1006265385.py\", line 35, in paint\n",
      "    self.draw.line([x1, y1, x2, y2], fill=\"black\", width=5)\n",
      "AttributeError: 'DigitRecognitionApp' object has no attribute 'draw'\n",
      "Exception in Tkinter callback\n",
      "Traceback (most recent call last):\n",
      "  File \"C:\\ProgramData\\Anaconda3\\lib\\tkinter\\__init__.py\", line 1892, in __call__\n",
      "    return self.func(*args)\n",
      "  File \"C:\\Users\\sanjay\\AppData\\Local\\Temp\\ipykernel_9524\\1006265385.py\", line 35, in paint\n",
      "    self.draw.line([x1, y1, x2, y2], fill=\"black\", width=5)\n",
      "AttributeError: 'DigitRecognitionApp' object has no attribute 'draw'\n",
      "Exception in Tkinter callback\n",
      "Traceback (most recent call last):\n",
      "  File \"C:\\ProgramData\\Anaconda3\\lib\\tkinter\\__init__.py\", line 1892, in __call__\n",
      "    return self.func(*args)\n",
      "  File \"C:\\Users\\sanjay\\AppData\\Local\\Temp\\ipykernel_9524\\1006265385.py\", line 35, in paint\n",
      "    self.draw.line([x1, y1, x2, y2], fill=\"black\", width=5)\n",
      "AttributeError: 'DigitRecognitionApp' object has no attribute 'draw'\n",
      "Exception in Tkinter callback\n",
      "Traceback (most recent call last):\n",
      "  File \"C:\\ProgramData\\Anaconda3\\lib\\tkinter\\__init__.py\", line 1892, in __call__\n",
      "    return self.func(*args)\n",
      "  File \"C:\\Users\\sanjay\\AppData\\Local\\Temp\\ipykernel_9524\\1006265385.py\", line 35, in paint\n",
      "    self.draw.line([x1, y1, x2, y2], fill=\"black\", width=5)\n",
      "AttributeError: 'DigitRecognitionApp' object has no attribute 'draw'\n",
      "Exception in Tkinter callback\n",
      "Traceback (most recent call last):\n",
      "  File \"C:\\ProgramData\\Anaconda3\\lib\\tkinter\\__init__.py\", line 1892, in __call__\n",
      "    return self.func(*args)\n",
      "  File \"C:\\Users\\sanjay\\AppData\\Local\\Temp\\ipykernel_9524\\1006265385.py\", line 35, in paint\n",
      "    self.draw.line([x1, y1, x2, y2], fill=\"black\", width=5)\n",
      "AttributeError: 'DigitRecognitionApp' object has no attribute 'draw'\n",
      "Exception in Tkinter callback\n",
      "Traceback (most recent call last):\n",
      "  File \"C:\\ProgramData\\Anaconda3\\lib\\tkinter\\__init__.py\", line 1892, in __call__\n",
      "    return self.func(*args)\n",
      "  File \"C:\\Users\\sanjay\\AppData\\Local\\Temp\\ipykernel_9524\\1006265385.py\", line 35, in paint\n",
      "    self.draw.line([x1, y1, x2, y2], fill=\"black\", width=5)\n",
      "AttributeError: 'DigitRecognitionApp' object has no attribute 'draw'\n",
      "Exception in Tkinter callback\n",
      "Traceback (most recent call last):\n",
      "  File \"C:\\ProgramData\\Anaconda3\\lib\\tkinter\\__init__.py\", line 1892, in __call__\n",
      "    return self.func(*args)\n",
      "  File \"C:\\Users\\sanjay\\AppData\\Local\\Temp\\ipykernel_9524\\1006265385.py\", line 35, in paint\n",
      "    self.draw.line([x1, y1, x2, y2], fill=\"black\", width=5)\n",
      "AttributeError: 'DigitRecognitionApp' object has no attribute 'draw'\n",
      "Exception in Tkinter callback\n",
      "Traceback (most recent call last):\n",
      "  File \"C:\\ProgramData\\Anaconda3\\lib\\tkinter\\__init__.py\", line 1892, in __call__\n",
      "    return self.func(*args)\n",
      "  File \"C:\\Users\\sanjay\\AppData\\Local\\Temp\\ipykernel_9524\\1006265385.py\", line 35, in paint\n",
      "    self.draw.line([x1, y1, x2, y2], fill=\"black\", width=5)\n",
      "AttributeError: 'DigitRecognitionApp' object has no attribute 'draw'\n",
      "Exception in Tkinter callback\n",
      "Traceback (most recent call last):\n",
      "  File \"C:\\ProgramData\\Anaconda3\\lib\\tkinter\\__init__.py\", line 1892, in __call__\n",
      "    return self.func(*args)\n",
      "  File \"C:\\Users\\sanjay\\AppData\\Local\\Temp\\ipykernel_9524\\1006265385.py\", line 35, in paint\n",
      "    self.draw.line([x1, y1, x2, y2], fill=\"black\", width=5)\n",
      "AttributeError: 'DigitRecognitionApp' object has no attribute 'draw'\n",
      "Exception in Tkinter callback\n",
      "Traceback (most recent call last):\n",
      "  File \"C:\\ProgramData\\Anaconda3\\lib\\tkinter\\__init__.py\", line 1892, in __call__\n",
      "    return self.func(*args)\n",
      "  File \"C:\\Users\\sanjay\\AppData\\Local\\Temp\\ipykernel_9524\\1006265385.py\", line 35, in paint\n",
      "    self.draw.line([x1, y1, x2, y2], fill=\"black\", width=5)\n",
      "AttributeError: 'DigitRecognitionApp' object has no attribute 'draw'\n",
      "Exception in Tkinter callback\n",
      "Traceback (most recent call last):\n",
      "  File \"C:\\ProgramData\\Anaconda3\\lib\\tkinter\\__init__.py\", line 1892, in __call__\n",
      "    return self.func(*args)\n",
      "  File \"C:\\Users\\sanjay\\AppData\\Local\\Temp\\ipykernel_9524\\1006265385.py\", line 35, in paint\n",
      "    self.draw.line([x1, y1, x2, y2], fill=\"black\", width=5)\n",
      "AttributeError: 'DigitRecognitionApp' object has no attribute 'draw'\n",
      "Exception in Tkinter callback\n",
      "Traceback (most recent call last):\n",
      "  File \"C:\\ProgramData\\Anaconda3\\lib\\tkinter\\__init__.py\", line 1892, in __call__\n",
      "    return self.func(*args)\n",
      "  File \"C:\\Users\\sanjay\\AppData\\Local\\Temp\\ipykernel_9524\\1006265385.py\", line 35, in paint\n",
      "    self.draw.line([x1, y1, x2, y2], fill=\"black\", width=5)\n",
      "AttributeError: 'DigitRecognitionApp' object has no attribute 'draw'\n",
      "Exception in Tkinter callback\n",
      "Traceback (most recent call last):\n",
      "  File \"C:\\ProgramData\\Anaconda3\\lib\\tkinter\\__init__.py\", line 1892, in __call__\n",
      "    return self.func(*args)\n",
      "  File \"C:\\Users\\sanjay\\AppData\\Local\\Temp\\ipykernel_9524\\1006265385.py\", line 35, in paint\n",
      "    self.draw.line([x1, y1, x2, y2], fill=\"black\", width=5)\n",
      "AttributeError: 'DigitRecognitionApp' object has no attribute 'draw'\n",
      "Exception in Tkinter callback\n",
      "Traceback (most recent call last):\n",
      "  File \"C:\\ProgramData\\Anaconda3\\lib\\tkinter\\__init__.py\", line 1892, in __call__\n",
      "    return self.func(*args)\n",
      "  File \"C:\\Users\\sanjay\\AppData\\Local\\Temp\\ipykernel_9524\\1006265385.py\", line 35, in paint\n",
      "    self.draw.line([x1, y1, x2, y2], fill=\"black\", width=5)\n",
      "AttributeError: 'DigitRecognitionApp' object has no attribute 'draw'\n",
      "Exception in Tkinter callback\n",
      "Traceback (most recent call last):\n",
      "  File \"C:\\ProgramData\\Anaconda3\\lib\\tkinter\\__init__.py\", line 1892, in __call__\n",
      "    return self.func(*args)\n",
      "  File \"C:\\Users\\sanjay\\AppData\\Local\\Temp\\ipykernel_9524\\1006265385.py\", line 35, in paint\n",
      "    self.draw.line([x1, y1, x2, y2], fill=\"black\", width=5)\n",
      "AttributeError: 'DigitRecognitionApp' object has no attribute 'draw'\n",
      "Exception in Tkinter callback\n",
      "Traceback (most recent call last):\n",
      "  File \"C:\\ProgramData\\Anaconda3\\lib\\tkinter\\__init__.py\", line 1892, in __call__\n",
      "    return self.func(*args)\n",
      "  File \"C:\\Users\\sanjay\\AppData\\Local\\Temp\\ipykernel_9524\\1006265385.py\", line 35, in paint\n",
      "    self.draw.line([x1, y1, x2, y2], fill=\"black\", width=5)\n",
      "AttributeError: 'DigitRecognitionApp' object has no attribute 'draw'\n",
      "Exception in Tkinter callback\n",
      "Traceback (most recent call last):\n",
      "  File \"C:\\ProgramData\\Anaconda3\\lib\\tkinter\\__init__.py\", line 1892, in __call__\n",
      "    return self.func(*args)\n",
      "  File \"C:\\Users\\sanjay\\AppData\\Local\\Temp\\ipykernel_9524\\1006265385.py\", line 35, in paint\n",
      "    self.draw.line([x1, y1, x2, y2], fill=\"black\", width=5)\n",
      "AttributeError: 'DigitRecognitionApp' object has no attribute 'draw'\n",
      "Exception in Tkinter callback\n",
      "Traceback (most recent call last):\n",
      "  File \"C:\\ProgramData\\Anaconda3\\lib\\tkinter\\__init__.py\", line 1892, in __call__\n",
      "    return self.func(*args)\n",
      "  File \"C:\\Users\\sanjay\\AppData\\Local\\Temp\\ipykernel_9524\\1006265385.py\", line 35, in paint\n",
      "    self.draw.line([x1, y1, x2, y2], fill=\"black\", width=5)\n",
      "AttributeError: 'DigitRecognitionApp' object has no attribute 'draw'\n",
      "Exception in Tkinter callback\n",
      "Traceback (most recent call last):\n",
      "  File \"C:\\ProgramData\\Anaconda3\\lib\\tkinter\\__init__.py\", line 1892, in __call__\n",
      "    return self.func(*args)\n",
      "  File \"C:\\Users\\sanjay\\AppData\\Local\\Temp\\ipykernel_9524\\1006265385.py\", line 35, in paint\n",
      "    self.draw.line([x1, y1, x2, y2], fill=\"black\", width=5)\n",
      "AttributeError: 'DigitRecognitionApp' object has no attribute 'draw'\n",
      "Exception in Tkinter callback\n",
      "Traceback (most recent call last):\n",
      "  File \"C:\\ProgramData\\Anaconda3\\lib\\tkinter\\__init__.py\", line 1892, in __call__\n",
      "    return self.func(*args)\n",
      "  File \"C:\\Users\\sanjay\\AppData\\Local\\Temp\\ipykernel_9524\\1006265385.py\", line 35, in paint\n",
      "    self.draw.line([x1, y1, x2, y2], fill=\"black\", width=5)\n",
      "AttributeError: 'DigitRecognitionApp' object has no attribute 'draw'\n",
      "Exception in Tkinter callback\n",
      "Traceback (most recent call last):\n",
      "  File \"C:\\ProgramData\\Anaconda3\\lib\\tkinter\\__init__.py\", line 1892, in __call__\n",
      "    return self.func(*args)\n",
      "  File \"C:\\Users\\sanjay\\AppData\\Local\\Temp\\ipykernel_9524\\1006265385.py\", line 35, in paint\n",
      "    self.draw.line([x1, y1, x2, y2], fill=\"black\", width=5)\n",
      "AttributeError: 'DigitRecognitionApp' object has no attribute 'draw'\n",
      "Exception in Tkinter callback\n",
      "Traceback (most recent call last):\n",
      "  File \"C:\\ProgramData\\Anaconda3\\lib\\tkinter\\__init__.py\", line 1892, in __call__\n",
      "    return self.func(*args)\n",
      "  File \"C:\\Users\\sanjay\\AppData\\Local\\Temp\\ipykernel_9524\\1006265385.py\", line 35, in paint\n",
      "    self.draw.line([x1, y1, x2, y2], fill=\"black\", width=5)\n",
      "AttributeError: 'DigitRecognitionApp' object has no attribute 'draw'\n",
      "Exception in Tkinter callback\n",
      "Traceback (most recent call last):\n",
      "  File \"C:\\ProgramData\\Anaconda3\\lib\\tkinter\\__init__.py\", line 1892, in __call__\n",
      "    return self.func(*args)\n",
      "  File \"C:\\Users\\sanjay\\AppData\\Local\\Temp\\ipykernel_9524\\1006265385.py\", line 35, in paint\n",
      "    self.draw.line([x1, y1, x2, y2], fill=\"black\", width=5)\n",
      "AttributeError: 'DigitRecognitionApp' object has no attribute 'draw'\n",
      "Exception in Tkinter callback\n",
      "Traceback (most recent call last):\n",
      "  File \"C:\\ProgramData\\Anaconda3\\lib\\tkinter\\__init__.py\", line 1892, in __call__\n",
      "    return self.func(*args)\n",
      "  File \"C:\\Users\\sanjay\\AppData\\Local\\Temp\\ipykernel_9524\\1006265385.py\", line 35, in paint\n",
      "    self.draw.line([x1, y1, x2, y2], fill=\"black\", width=5)\n",
      "AttributeError: 'DigitRecognitionApp' object has no attribute 'draw'\n",
      "Exception in Tkinter callback\n",
      "Traceback (most recent call last):\n",
      "  File \"C:\\ProgramData\\Anaconda3\\lib\\tkinter\\__init__.py\", line 1892, in __call__\n",
      "    return self.func(*args)\n",
      "  File \"C:\\Users\\sanjay\\AppData\\Local\\Temp\\ipykernel_9524\\1006265385.py\", line 35, in paint\n",
      "    self.draw.line([x1, y1, x2, y2], fill=\"black\", width=5)\n",
      "AttributeError: 'DigitRecognitionApp' object has no attribute 'draw'\n",
      "Exception in Tkinter callback\n",
      "Traceback (most recent call last):\n",
      "  File \"C:\\ProgramData\\Anaconda3\\lib\\tkinter\\__init__.py\", line 1892, in __call__\n",
      "    return self.func(*args)\n",
      "  File \"C:\\Users\\sanjay\\AppData\\Local\\Temp\\ipykernel_9524\\1006265385.py\", line 35, in paint\n",
      "    self.draw.line([x1, y1, x2, y2], fill=\"black\", width=5)\n",
      "AttributeError: 'DigitRecognitionApp' object has no attribute 'draw'\n",
      "Exception in Tkinter callback\n",
      "Traceback (most recent call last):\n",
      "  File \"C:\\ProgramData\\Anaconda3\\lib\\tkinter\\__init__.py\", line 1892, in __call__\n",
      "    return self.func(*args)\n",
      "  File \"C:\\Users\\sanjay\\AppData\\Local\\Temp\\ipykernel_9524\\1006265385.py\", line 35, in paint\n",
      "    self.draw.line([x1, y1, x2, y2], fill=\"black\", width=5)\n",
      "AttributeError: 'DigitRecognitionApp' object has no attribute 'draw'\n",
      "Exception in Tkinter callback\n",
      "Traceback (most recent call last):\n",
      "  File \"C:\\ProgramData\\Anaconda3\\lib\\tkinter\\__init__.py\", line 1892, in __call__\n",
      "    return self.func(*args)\n",
      "  File \"C:\\Users\\sanjay\\AppData\\Local\\Temp\\ipykernel_9524\\1006265385.py\", line 35, in paint\n",
      "    self.draw.line([x1, y1, x2, y2], fill=\"black\", width=5)\n",
      "AttributeError: 'DigitRecognitionApp' object has no attribute 'draw'\n",
      "Exception in Tkinter callback\n",
      "Traceback (most recent call last):\n",
      "  File \"C:\\ProgramData\\Anaconda3\\lib\\tkinter\\__init__.py\", line 1892, in __call__\n",
      "    return self.func(*args)\n",
      "  File \"C:\\Users\\sanjay\\AppData\\Local\\Temp\\ipykernel_9524\\1006265385.py\", line 35, in paint\n",
      "    self.draw.line([x1, y1, x2, y2], fill=\"black\", width=5)\n",
      "AttributeError: 'DigitRecognitionApp' object has no attribute 'draw'\n",
      "Exception in Tkinter callback\n",
      "Traceback (most recent call last):\n",
      "  File \"C:\\ProgramData\\Anaconda3\\lib\\tkinter\\__init__.py\", line 1892, in __call__\n",
      "    return self.func(*args)\n",
      "  File \"C:\\Users\\sanjay\\AppData\\Local\\Temp\\ipykernel_9524\\1006265385.py\", line 35, in paint\n",
      "    self.draw.line([x1, y1, x2, y2], fill=\"black\", width=5)\n",
      "AttributeError: 'DigitRecognitionApp' object has no attribute 'draw'\n",
      "Exception in Tkinter callback\n",
      "Traceback (most recent call last):\n",
      "  File \"C:\\ProgramData\\Anaconda3\\lib\\tkinter\\__init__.py\", line 1892, in __call__\n",
      "    return self.func(*args)\n",
      "  File \"C:\\Users\\sanjay\\AppData\\Local\\Temp\\ipykernel_9524\\1006265385.py\", line 35, in paint\n",
      "    self.draw.line([x1, y1, x2, y2], fill=\"black\", width=5)\n",
      "AttributeError: 'DigitRecognitionApp' object has no attribute 'draw'\n",
      "Exception in Tkinter callback\n",
      "Traceback (most recent call last):\n",
      "  File \"C:\\ProgramData\\Anaconda3\\lib\\tkinter\\__init__.py\", line 1892, in __call__\n",
      "    return self.func(*args)\n",
      "  File \"C:\\Users\\sanjay\\AppData\\Local\\Temp\\ipykernel_9524\\1006265385.py\", line 35, in paint\n",
      "    self.draw.line([x1, y1, x2, y2], fill=\"black\", width=5)\n",
      "AttributeError: 'DigitRecognitionApp' object has no attribute 'draw'\n",
      "Exception in Tkinter callback\n",
      "Traceback (most recent call last):\n",
      "  File \"C:\\ProgramData\\Anaconda3\\lib\\tkinter\\__init__.py\", line 1892, in __call__\n",
      "    return self.func(*args)\n",
      "  File \"C:\\Users\\sanjay\\AppData\\Local\\Temp\\ipykernel_9524\\1006265385.py\", line 35, in paint\n",
      "    self.draw.line([x1, y1, x2, y2], fill=\"black\", width=5)\n",
      "AttributeError: 'DigitRecognitionApp' object has no attribute 'draw'\n",
      "Exception in Tkinter callback\n",
      "Traceback (most recent call last):\n",
      "  File \"C:\\ProgramData\\Anaconda3\\lib\\tkinter\\__init__.py\", line 1892, in __call__\n",
      "    return self.func(*args)\n",
      "  File \"C:\\Users\\sanjay\\AppData\\Local\\Temp\\ipykernel_9524\\1006265385.py\", line 35, in paint\n",
      "    self.draw.line([x1, y1, x2, y2], fill=\"black\", width=5)\n",
      "AttributeError: 'DigitRecognitionApp' object has no attribute 'draw'\n",
      "Exception in Tkinter callback\n",
      "Traceback (most recent call last):\n",
      "  File \"C:\\ProgramData\\Anaconda3\\lib\\tkinter\\__init__.py\", line 1892, in __call__\n",
      "    return self.func(*args)\n",
      "  File \"C:\\Users\\sanjay\\AppData\\Local\\Temp\\ipykernel_9524\\1006265385.py\", line 35, in paint\n",
      "    self.draw.line([x1, y1, x2, y2], fill=\"black\", width=5)\n",
      "AttributeError: 'DigitRecognitionApp' object has no attribute 'draw'\n",
      "Exception in Tkinter callback\n",
      "Traceback (most recent call last):\n",
      "  File \"C:\\ProgramData\\Anaconda3\\lib\\tkinter\\__init__.py\", line 1892, in __call__\n",
      "    return self.func(*args)\n",
      "  File \"C:\\Users\\sanjay\\AppData\\Local\\Temp\\ipykernel_9524\\1006265385.py\", line 35, in paint\n",
      "    self.draw.line([x1, y1, x2, y2], fill=\"black\", width=5)\n",
      "AttributeError: 'DigitRecognitionApp' object has no attribute 'draw'\n",
      "Exception in Tkinter callback\n",
      "Traceback (most recent call last):\n",
      "  File \"C:\\ProgramData\\Anaconda3\\lib\\tkinter\\__init__.py\", line 1892, in __call__\n",
      "    return self.func(*args)\n",
      "  File \"C:\\Users\\sanjay\\AppData\\Local\\Temp\\ipykernel_9524\\1006265385.py\", line 35, in paint\n",
      "    self.draw.line([x1, y1, x2, y2], fill=\"black\", width=5)\n",
      "AttributeError: 'DigitRecognitionApp' object has no attribute 'draw'\n",
      "Exception in Tkinter callback\n",
      "Traceback (most recent call last):\n",
      "  File \"C:\\ProgramData\\Anaconda3\\lib\\tkinter\\__init__.py\", line 1892, in __call__\n",
      "    return self.func(*args)\n",
      "  File \"C:\\Users\\sanjay\\AppData\\Local\\Temp\\ipykernel_9524\\1006265385.py\", line 35, in paint\n",
      "    self.draw.line([x1, y1, x2, y2], fill=\"black\", width=5)\n",
      "AttributeError: 'DigitRecognitionApp' object has no attribute 'draw'\n",
      "Exception in Tkinter callback\n",
      "Traceback (most recent call last):\n",
      "  File \"C:\\ProgramData\\Anaconda3\\lib\\tkinter\\__init__.py\", line 1892, in __call__\n",
      "    return self.func(*args)\n",
      "  File \"C:\\Users\\sanjay\\AppData\\Local\\Temp\\ipykernel_9524\\1006265385.py\", line 35, in paint\n",
      "    self.draw.line([x1, y1, x2, y2], fill=\"black\", width=5)\n",
      "AttributeError: 'DigitRecognitionApp' object has no attribute 'draw'\n",
      "Exception in Tkinter callback\n",
      "Traceback (most recent call last):\n",
      "  File \"C:\\ProgramData\\Anaconda3\\lib\\tkinter\\__init__.py\", line 1892, in __call__\n",
      "    return self.func(*args)\n",
      "  File \"C:\\Users\\sanjay\\AppData\\Local\\Temp\\ipykernel_9524\\1006265385.py\", line 35, in paint\n",
      "    self.draw.line([x1, y1, x2, y2], fill=\"black\", width=5)\n",
      "AttributeError: 'DigitRecognitionApp' object has no attribute 'draw'\n",
      "Exception in Tkinter callback\n",
      "Traceback (most recent call last):\n",
      "  File \"C:\\ProgramData\\Anaconda3\\lib\\tkinter\\__init__.py\", line 1892, in __call__\n",
      "    return self.func(*args)\n",
      "  File \"C:\\Users\\sanjay\\AppData\\Local\\Temp\\ipykernel_9524\\1006265385.py\", line 35, in paint\n",
      "    self.draw.line([x1, y1, x2, y2], fill=\"black\", width=5)\n",
      "AttributeError: 'DigitRecognitionApp' object has no attribute 'draw'\n",
      "Exception in Tkinter callback\n",
      "Traceback (most recent call last):\n",
      "  File \"C:\\ProgramData\\Anaconda3\\lib\\tkinter\\__init__.py\", line 1892, in __call__\n",
      "    return self.func(*args)\n",
      "  File \"C:\\Users\\sanjay\\AppData\\Local\\Temp\\ipykernel_9524\\1006265385.py\", line 35, in paint\n",
      "    self.draw.line([x1, y1, x2, y2], fill=\"black\", width=5)\n",
      "AttributeError: 'DigitRecognitionApp' object has no attribute 'draw'\n",
      "Exception in Tkinter callback\n",
      "Traceback (most recent call last):\n",
      "  File \"C:\\ProgramData\\Anaconda3\\lib\\tkinter\\__init__.py\", line 1892, in __call__\n",
      "    return self.func(*args)\n",
      "  File \"C:\\Users\\sanjay\\AppData\\Local\\Temp\\ipykernel_9524\\1006265385.py\", line 35, in paint\n",
      "    self.draw.line([x1, y1, x2, y2], fill=\"black\", width=5)\n",
      "AttributeError: 'DigitRecognitionApp' object has no attribute 'draw'\n",
      "Exception in Tkinter callback\n",
      "Traceback (most recent call last):\n",
      "  File \"C:\\ProgramData\\Anaconda3\\lib\\tkinter\\__init__.py\", line 1892, in __call__\n",
      "    return self.func(*args)\n",
      "  File \"C:\\Users\\sanjay\\AppData\\Local\\Temp\\ipykernel_9524\\1006265385.py\", line 35, in paint\n",
      "    self.draw.line([x1, y1, x2, y2], fill=\"black\", width=5)\n",
      "AttributeError: 'DigitRecognitionApp' object has no attribute 'draw'\n",
      "Exception in Tkinter callback\n",
      "Traceback (most recent call last):\n",
      "  File \"C:\\ProgramData\\Anaconda3\\lib\\tkinter\\__init__.py\", line 1892, in __call__\n",
      "    return self.func(*args)\n",
      "  File \"C:\\Users\\sanjay\\AppData\\Local\\Temp\\ipykernel_9524\\1006265385.py\", line 35, in paint\n",
      "    self.draw.line([x1, y1, x2, y2], fill=\"black\", width=5)\n",
      "AttributeError: 'DigitRecognitionApp' object has no attribute 'draw'\n",
      "Exception in Tkinter callback\n",
      "Traceback (most recent call last):\n",
      "  File \"C:\\ProgramData\\Anaconda3\\lib\\tkinter\\__init__.py\", line 1892, in __call__\n",
      "    return self.func(*args)\n",
      "  File \"C:\\Users\\sanjay\\AppData\\Local\\Temp\\ipykernel_9524\\1006265385.py\", line 35, in paint\n",
      "    self.draw.line([x1, y1, x2, y2], fill=\"black\", width=5)\n",
      "AttributeError: 'DigitRecognitionApp' object has no attribute 'draw'\n",
      "Exception in Tkinter callback\n",
      "Traceback (most recent call last):\n",
      "  File \"C:\\ProgramData\\Anaconda3\\lib\\tkinter\\__init__.py\", line 1892, in __call__\n",
      "    return self.func(*args)\n",
      "  File \"C:\\Users\\sanjay\\AppData\\Local\\Temp\\ipykernel_9524\\1006265385.py\", line 35, in paint\n",
      "    self.draw.line([x1, y1, x2, y2], fill=\"black\", width=5)\n",
      "AttributeError: 'DigitRecognitionApp' object has no attribute 'draw'\n",
      "Exception in Tkinter callback\n",
      "Traceback (most recent call last):\n",
      "  File \"C:\\ProgramData\\Anaconda3\\lib\\tkinter\\__init__.py\", line 1892, in __call__\n",
      "    return self.func(*args)\n",
      "  File \"C:\\Users\\sanjay\\AppData\\Local\\Temp\\ipykernel_9524\\1006265385.py\", line 35, in paint\n",
      "    self.draw.line([x1, y1, x2, y2], fill=\"black\", width=5)\n",
      "AttributeError: 'DigitRecognitionApp' object has no attribute 'draw'\n",
      "Exception in Tkinter callback\n",
      "Traceback (most recent call last):\n",
      "  File \"C:\\ProgramData\\Anaconda3\\lib\\tkinter\\__init__.py\", line 1892, in __call__\n",
      "    return self.func(*args)\n",
      "  File \"C:\\Users\\sanjay\\AppData\\Local\\Temp\\ipykernel_9524\\1006265385.py\", line 35, in paint\n",
      "    self.draw.line([x1, y1, x2, y2], fill=\"black\", width=5)\n",
      "AttributeError: 'DigitRecognitionApp' object has no attribute 'draw'\n",
      "Exception in Tkinter callback\n",
      "Traceback (most recent call last):\n",
      "  File \"C:\\ProgramData\\Anaconda3\\lib\\tkinter\\__init__.py\", line 1892, in __call__\n",
      "    return self.func(*args)\n",
      "  File \"C:\\Users\\sanjay\\AppData\\Local\\Temp\\ipykernel_9524\\1006265385.py\", line 35, in paint\n",
      "    self.draw.line([x1, y1, x2, y2], fill=\"black\", width=5)\n",
      "AttributeError: 'DigitRecognitionApp' object has no attribute 'draw'\n",
      "Exception in Tkinter callback\n",
      "Traceback (most recent call last):\n",
      "  File \"C:\\ProgramData\\Anaconda3\\lib\\tkinter\\__init__.py\", line 1892, in __call__\n",
      "    return self.func(*args)\n",
      "  File \"C:\\Users\\sanjay\\AppData\\Local\\Temp\\ipykernel_9524\\1006265385.py\", line 35, in paint\n",
      "    self.draw.line([x1, y1, x2, y2], fill=\"black\", width=5)\n",
      "AttributeError: 'DigitRecognitionApp' object has no attribute 'draw'\n",
      "Exception in Tkinter callback\n",
      "Traceback (most recent call last):\n",
      "  File \"C:\\ProgramData\\Anaconda3\\lib\\tkinter\\__init__.py\", line 1892, in __call__\n",
      "    return self.func(*args)\n",
      "  File \"C:\\Users\\sanjay\\AppData\\Local\\Temp\\ipykernel_9524\\1006265385.py\", line 35, in paint\n",
      "    self.draw.line([x1, y1, x2, y2], fill=\"black\", width=5)\n",
      "AttributeError: 'DigitRecognitionApp' object has no attribute 'draw'\n",
      "Exception in Tkinter callback\n",
      "Traceback (most recent call last):\n",
      "  File \"C:\\ProgramData\\Anaconda3\\lib\\tkinter\\__init__.py\", line 1892, in __call__\n",
      "    return self.func(*args)\n",
      "  File \"C:\\Users\\sanjay\\AppData\\Local\\Temp\\ipykernel_9524\\1006265385.py\", line 35, in paint\n",
      "    self.draw.line([x1, y1, x2, y2], fill=\"black\", width=5)\n",
      "AttributeError: 'DigitRecognitionApp' object has no attribute 'draw'\n",
      "Exception in Tkinter callback\n",
      "Traceback (most recent call last):\n",
      "  File \"C:\\ProgramData\\Anaconda3\\lib\\tkinter\\__init__.py\", line 1892, in __call__\n",
      "    return self.func(*args)\n",
      "  File \"C:\\Users\\sanjay\\AppData\\Local\\Temp\\ipykernel_9524\\1006265385.py\", line 35, in paint\n",
      "    self.draw.line([x1, y1, x2, y2], fill=\"black\", width=5)\n",
      "AttributeError: 'DigitRecognitionApp' object has no attribute 'draw'\n",
      "Exception in Tkinter callback\n",
      "Traceback (most recent call last):\n",
      "  File \"C:\\ProgramData\\Anaconda3\\lib\\tkinter\\__init__.py\", line 1892, in __call__\n",
      "    return self.func(*args)\n",
      "  File \"C:\\Users\\sanjay\\AppData\\Local\\Temp\\ipykernel_9524\\1006265385.py\", line 35, in paint\n",
      "    self.draw.line([x1, y1, x2, y2], fill=\"black\", width=5)\n",
      "AttributeError: 'DigitRecognitionApp' object has no attribute 'draw'\n",
      "Exception in Tkinter callback\n",
      "Traceback (most recent call last):\n",
      "  File \"C:\\ProgramData\\Anaconda3\\lib\\tkinter\\__init__.py\", line 1892, in __call__\n",
      "    return self.func(*args)\n",
      "  File \"C:\\Users\\sanjay\\AppData\\Local\\Temp\\ipykernel_9524\\1006265385.py\", line 35, in paint\n",
      "    self.draw.line([x1, y1, x2, y2], fill=\"black\", width=5)\n",
      "AttributeError: 'DigitRecognitionApp' object has no attribute 'draw'\n",
      "Exception in Tkinter callback\n",
      "Traceback (most recent call last):\n",
      "  File \"C:\\ProgramData\\Anaconda3\\lib\\tkinter\\__init__.py\", line 1892, in __call__\n",
      "    return self.func(*args)\n",
      "  File \"C:\\Users\\sanjay\\AppData\\Local\\Temp\\ipykernel_9524\\1006265385.py\", line 35, in paint\n",
      "    self.draw.line([x1, y1, x2, y2], fill=\"black\", width=5)\n",
      "AttributeError: 'DigitRecognitionApp' object has no attribute 'draw'\n",
      "Exception in Tkinter callback\n",
      "Traceback (most recent call last):\n",
      "  File \"C:\\ProgramData\\Anaconda3\\lib\\tkinter\\__init__.py\", line 1892, in __call__\n",
      "    return self.func(*args)\n",
      "  File \"C:\\Users\\sanjay\\AppData\\Local\\Temp\\ipykernel_9524\\1006265385.py\", line 35, in paint\n",
      "    self.draw.line([x1, y1, x2, y2], fill=\"black\", width=5)\n",
      "AttributeError: 'DigitRecognitionApp' object has no attribute 'draw'\n",
      "Exception in Tkinter callback\n",
      "Traceback (most recent call last):\n",
      "  File \"C:\\ProgramData\\Anaconda3\\lib\\tkinter\\__init__.py\", line 1892, in __call__\n",
      "    return self.func(*args)\n",
      "  File \"C:\\Users\\sanjay\\AppData\\Local\\Temp\\ipykernel_9524\\1006265385.py\", line 35, in paint\n",
      "    self.draw.line([x1, y1, x2, y2], fill=\"black\", width=5)\n",
      "AttributeError: 'DigitRecognitionApp' object has no attribute 'draw'\n",
      "Exception in Tkinter callback\n",
      "Traceback (most recent call last):\n",
      "  File \"C:\\ProgramData\\Anaconda3\\lib\\tkinter\\__init__.py\", line 1892, in __call__\n",
      "    return self.func(*args)\n",
      "  File \"C:\\Users\\sanjay\\AppData\\Local\\Temp\\ipykernel_9524\\1006265385.py\", line 35, in paint\n",
      "    self.draw.line([x1, y1, x2, y2], fill=\"black\", width=5)\n",
      "AttributeError: 'DigitRecognitionApp' object has no attribute 'draw'\n",
      "Exception in Tkinter callback\n",
      "Traceback (most recent call last):\n",
      "  File \"C:\\ProgramData\\Anaconda3\\lib\\tkinter\\__init__.py\", line 1892, in __call__\n",
      "    return self.func(*args)\n",
      "  File \"C:\\Users\\sanjay\\AppData\\Local\\Temp\\ipykernel_9524\\1006265385.py\", line 35, in paint\n",
      "    self.draw.line([x1, y1, x2, y2], fill=\"black\", width=5)\n",
      "AttributeError: 'DigitRecognitionApp' object has no attribute 'draw'\n",
      "Exception in Tkinter callback\n",
      "Traceback (most recent call last):\n",
      "  File \"C:\\ProgramData\\Anaconda3\\lib\\tkinter\\__init__.py\", line 1892, in __call__\n",
      "    return self.func(*args)\n",
      "  File \"C:\\Users\\sanjay\\AppData\\Local\\Temp\\ipykernel_9524\\1006265385.py\", line 35, in paint\n",
      "    self.draw.line([x1, y1, x2, y2], fill=\"black\", width=5)\n",
      "AttributeError: 'DigitRecognitionApp' object has no attribute 'draw'\n",
      "Exception in Tkinter callback\n",
      "Traceback (most recent call last):\n",
      "  File \"C:\\ProgramData\\Anaconda3\\lib\\tkinter\\__init__.py\", line 1892, in __call__\n",
      "    return self.func(*args)\n",
      "  File \"C:\\Users\\sanjay\\AppData\\Local\\Temp\\ipykernel_9524\\1006265385.py\", line 35, in paint\n",
      "    self.draw.line([x1, y1, x2, y2], fill=\"black\", width=5)\n",
      "AttributeError: 'DigitRecognitionApp' object has no attribute 'draw'\n",
      "Exception in Tkinter callback\n",
      "Traceback (most recent call last):\n",
      "  File \"C:\\ProgramData\\Anaconda3\\lib\\tkinter\\__init__.py\", line 1892, in __call__\n",
      "    return self.func(*args)\n",
      "  File \"C:\\Users\\sanjay\\AppData\\Local\\Temp\\ipykernel_9524\\1006265385.py\", line 35, in paint\n",
      "    self.draw.line([x1, y1, x2, y2], fill=\"black\", width=5)\n",
      "AttributeError: 'DigitRecognitionApp' object has no attribute 'draw'\n",
      "Exception in Tkinter callback\n",
      "Traceback (most recent call last):\n",
      "  File \"C:\\ProgramData\\Anaconda3\\lib\\tkinter\\__init__.py\", line 1892, in __call__\n",
      "    return self.func(*args)\n",
      "  File \"C:\\Users\\sanjay\\AppData\\Local\\Temp\\ipykernel_9524\\1006265385.py\", line 35, in paint\n",
      "    self.draw.line([x1, y1, x2, y2], fill=\"black\", width=5)\n",
      "AttributeError: 'DigitRecognitionApp' object has no attribute 'draw'\n",
      "Exception in Tkinter callback\n",
      "Traceback (most recent call last):\n",
      "  File \"C:\\ProgramData\\Anaconda3\\lib\\tkinter\\__init__.py\", line 1892, in __call__\n",
      "    return self.func(*args)\n",
      "  File \"C:\\Users\\sanjay\\AppData\\Local\\Temp\\ipykernel_9524\\1006265385.py\", line 35, in paint\n",
      "    self.draw.line([x1, y1, x2, y2], fill=\"black\", width=5)\n",
      "AttributeError: 'DigitRecognitionApp' object has no attribute 'draw'\n",
      "Exception in Tkinter callback\n",
      "Traceback (most recent call last):\n",
      "  File \"C:\\ProgramData\\Anaconda3\\lib\\tkinter\\__init__.py\", line 1892, in __call__\n",
      "    return self.func(*args)\n",
      "  File \"C:\\Users\\sanjay\\AppData\\Local\\Temp\\ipykernel_9524\\1006265385.py\", line 35, in paint\n",
      "    self.draw.line([x1, y1, x2, y2], fill=\"black\", width=5)\n",
      "AttributeError: 'DigitRecognitionApp' object has no attribute 'draw'\n",
      "Exception in Tkinter callback\n",
      "Traceback (most recent call last):\n",
      "  File \"C:\\ProgramData\\Anaconda3\\lib\\tkinter\\__init__.py\", line 1892, in __call__\n",
      "    return self.func(*args)\n",
      "  File \"C:\\Users\\sanjay\\AppData\\Local\\Temp\\ipykernel_9524\\1006265385.py\", line 35, in paint\n",
      "    self.draw.line([x1, y1, x2, y2], fill=\"black\", width=5)\n",
      "AttributeError: 'DigitRecognitionApp' object has no attribute 'draw'\n",
      "Exception in Tkinter callback\n",
      "Traceback (most recent call last):\n",
      "  File \"C:\\ProgramData\\Anaconda3\\lib\\tkinter\\__init__.py\", line 1892, in __call__\n",
      "    return self.func(*args)\n",
      "  File \"C:\\Users\\sanjay\\AppData\\Local\\Temp\\ipykernel_9524\\1006265385.py\", line 35, in paint\n",
      "    self.draw.line([x1, y1, x2, y2], fill=\"black\", width=5)\n",
      "AttributeError: 'DigitRecognitionApp' object has no attribute 'draw'\n",
      "Exception in Tkinter callback\n",
      "Traceback (most recent call last):\n",
      "  File \"C:\\ProgramData\\Anaconda3\\lib\\tkinter\\__init__.py\", line 1892, in __call__\n",
      "    return self.func(*args)\n",
      "  File \"C:\\Users\\sanjay\\AppData\\Local\\Temp\\ipykernel_9524\\1006265385.py\", line 35, in paint\n",
      "    self.draw.line([x1, y1, x2, y2], fill=\"black\", width=5)\n",
      "AttributeError: 'DigitRecognitionApp' object has no attribute 'draw'\n",
      "Exception in Tkinter callback\n",
      "Traceback (most recent call last):\n",
      "  File \"C:\\ProgramData\\Anaconda3\\lib\\tkinter\\__init__.py\", line 1892, in __call__\n",
      "    return self.func(*args)\n",
      "  File \"C:\\Users\\sanjay\\AppData\\Local\\Temp\\ipykernel_9524\\1006265385.py\", line 35, in paint\n",
      "    self.draw.line([x1, y1, x2, y2], fill=\"black\", width=5)\n",
      "AttributeError: 'DigitRecognitionApp' object has no attribute 'draw'\n",
      "Exception in Tkinter callback\n",
      "Traceback (most recent call last):\n",
      "  File \"C:\\ProgramData\\Anaconda3\\lib\\tkinter\\__init__.py\", line 1892, in __call__\n",
      "    return self.func(*args)\n",
      "  File \"C:\\Users\\sanjay\\AppData\\Local\\Temp\\ipykernel_9524\\1006265385.py\", line 35, in paint\n",
      "    self.draw.line([x1, y1, x2, y2], fill=\"black\", width=5)\n",
      "AttributeError: 'DigitRecognitionApp' object has no attribute 'draw'\n",
      "Exception in Tkinter callback\n",
      "Traceback (most recent call last):\n",
      "  File \"C:\\ProgramData\\Anaconda3\\lib\\tkinter\\__init__.py\", line 1892, in __call__\n",
      "    return self.func(*args)\n",
      "  File \"C:\\Users\\sanjay\\AppData\\Local\\Temp\\ipykernel_9524\\1006265385.py\", line 35, in paint\n",
      "    self.draw.line([x1, y1, x2, y2], fill=\"black\", width=5)\n",
      "AttributeError: 'DigitRecognitionApp' object has no attribute 'draw'\n",
      "Exception in Tkinter callback\n",
      "Traceback (most recent call last):\n",
      "  File \"C:\\ProgramData\\Anaconda3\\lib\\tkinter\\__init__.py\", line 1892, in __call__\n",
      "    return self.func(*args)\n",
      "  File \"C:\\Users\\sanjay\\AppData\\Local\\Temp\\ipykernel_9524\\1006265385.py\", line 35, in paint\n",
      "    self.draw.line([x1, y1, x2, y2], fill=\"black\", width=5)\n",
      "AttributeError: 'DigitRecognitionApp' object has no attribute 'draw'\n",
      "Exception in Tkinter callback\n",
      "Traceback (most recent call last):\n",
      "  File \"C:\\ProgramData\\Anaconda3\\lib\\tkinter\\__init__.py\", line 1892, in __call__\n",
      "    return self.func(*args)\n",
      "  File \"C:\\Users\\sanjay\\AppData\\Local\\Temp\\ipykernel_9524\\1006265385.py\", line 35, in paint\n",
      "    self.draw.line([x1, y1, x2, y2], fill=\"black\", width=5)\n",
      "AttributeError: 'DigitRecognitionApp' object has no attribute 'draw'\n",
      "Exception in Tkinter callback\n",
      "Traceback (most recent call last):\n",
      "  File \"C:\\ProgramData\\Anaconda3\\lib\\tkinter\\__init__.py\", line 1892, in __call__\n",
      "    return self.func(*args)\n",
      "  File \"C:\\Users\\sanjay\\AppData\\Local\\Temp\\ipykernel_9524\\1006265385.py\", line 35, in paint\n",
      "    self.draw.line([x1, y1, x2, y2], fill=\"black\", width=5)\n",
      "AttributeError: 'DigitRecognitionApp' object has no attribute 'draw'\n",
      "Exception in Tkinter callback\n",
      "Traceback (most recent call last):\n",
      "  File \"C:\\ProgramData\\Anaconda3\\lib\\tkinter\\__init__.py\", line 1892, in __call__\n",
      "    return self.func(*args)\n",
      "  File \"C:\\Users\\sanjay\\AppData\\Local\\Temp\\ipykernel_9524\\1006265385.py\", line 35, in paint\n",
      "    self.draw.line([x1, y1, x2, y2], fill=\"black\", width=5)\n",
      "AttributeError: 'DigitRecognitionApp' object has no attribute 'draw'\n",
      "Exception in Tkinter callback\n",
      "Traceback (most recent call last):\n",
      "  File \"C:\\ProgramData\\Anaconda3\\lib\\tkinter\\__init__.py\", line 1892, in __call__\n",
      "    return self.func(*args)\n",
      "  File \"C:\\Users\\sanjay\\AppData\\Local\\Temp\\ipykernel_9524\\1006265385.py\", line 35, in paint\n",
      "    self.draw.line([x1, y1, x2, y2], fill=\"black\", width=5)\n",
      "AttributeError: 'DigitRecognitionApp' object has no attribute 'draw'\n",
      "Exception in Tkinter callback\n",
      "Traceback (most recent call last):\n",
      "  File \"C:\\ProgramData\\Anaconda3\\lib\\tkinter\\__init__.py\", line 1892, in __call__\n",
      "    return self.func(*args)\n",
      "  File \"C:\\Users\\sanjay\\AppData\\Local\\Temp\\ipykernel_9524\\1006265385.py\", line 35, in paint\n",
      "    self.draw.line([x1, y1, x2, y2], fill=\"black\", width=5)\n",
      "AttributeError: 'DigitRecognitionApp' object has no attribute 'draw'\n",
      "Exception in Tkinter callback\n",
      "Traceback (most recent call last):\n",
      "  File \"C:\\ProgramData\\Anaconda3\\lib\\tkinter\\__init__.py\", line 1892, in __call__\n",
      "    return self.func(*args)\n",
      "  File \"C:\\Users\\sanjay\\AppData\\Local\\Temp\\ipykernel_9524\\1006265385.py\", line 35, in paint\n",
      "    self.draw.line([x1, y1, x2, y2], fill=\"black\", width=5)\n",
      "AttributeError: 'DigitRecognitionApp' object has no attribute 'draw'\n",
      "Exception in Tkinter callback\n",
      "Traceback (most recent call last):\n",
      "  File \"C:\\ProgramData\\Anaconda3\\lib\\tkinter\\__init__.py\", line 1892, in __call__\n",
      "    return self.func(*args)\n",
      "  File \"C:\\Users\\sanjay\\AppData\\Local\\Temp\\ipykernel_9524\\1006265385.py\", line 35, in paint\n",
      "    self.draw.line([x1, y1, x2, y2], fill=\"black\", width=5)\n",
      "AttributeError: 'DigitRecognitionApp' object has no attribute 'draw'\n",
      "Exception in Tkinter callback\n",
      "Traceback (most recent call last):\n",
      "  File \"C:\\ProgramData\\Anaconda3\\lib\\tkinter\\__init__.py\", line 1892, in __call__\n",
      "    return self.func(*args)\n",
      "  File \"C:\\Users\\sanjay\\AppData\\Local\\Temp\\ipykernel_9524\\1006265385.py\", line 35, in paint\n",
      "    self.draw.line([x1, y1, x2, y2], fill=\"black\", width=5)\n",
      "AttributeError: 'DigitRecognitionApp' object has no attribute 'draw'\n",
      "Exception in Tkinter callback\n",
      "Traceback (most recent call last):\n",
      "  File \"C:\\ProgramData\\Anaconda3\\lib\\tkinter\\__init__.py\", line 1892, in __call__\n",
      "    return self.func(*args)\n",
      "  File \"C:\\Users\\sanjay\\AppData\\Local\\Temp\\ipykernel_9524\\1006265385.py\", line 35, in paint\n",
      "    self.draw.line([x1, y1, x2, y2], fill=\"black\", width=5)\n",
      "AttributeError: 'DigitRecognitionApp' object has no attribute 'draw'\n",
      "Exception in Tkinter callback\n",
      "Traceback (most recent call last):\n",
      "  File \"C:\\ProgramData\\Anaconda3\\lib\\tkinter\\__init__.py\", line 1892, in __call__\n",
      "    return self.func(*args)\n",
      "  File \"C:\\Users\\sanjay\\AppData\\Local\\Temp\\ipykernel_9524\\1006265385.py\", line 35, in paint\n",
      "    self.draw.line([x1, y1, x2, y2], fill=\"black\", width=5)\n",
      "AttributeError: 'DigitRecognitionApp' object has no attribute 'draw'\n",
      "Exception in Tkinter callback\n",
      "Traceback (most recent call last):\n",
      "  File \"C:\\ProgramData\\Anaconda3\\lib\\tkinter\\__init__.py\", line 1892, in __call__\n",
      "    return self.func(*args)\n",
      "  File \"C:\\Users\\sanjay\\AppData\\Local\\Temp\\ipykernel_9524\\1006265385.py\", line 35, in paint\n",
      "    self.draw.line([x1, y1, x2, y2], fill=\"black\", width=5)\n",
      "AttributeError: 'DigitRecognitionApp' object has no attribute 'draw'\n",
      "Exception in Tkinter callback\n",
      "Traceback (most recent call last):\n",
      "  File \"C:\\ProgramData\\Anaconda3\\lib\\tkinter\\__init__.py\", line 1892, in __call__\n",
      "    return self.func(*args)\n",
      "  File \"C:\\Users\\sanjay\\AppData\\Local\\Temp\\ipykernel_9524\\1006265385.py\", line 35, in paint\n",
      "    self.draw.line([x1, y1, x2, y2], fill=\"black\", width=5)\n",
      "AttributeError: 'DigitRecognitionApp' object has no attribute 'draw'\n",
      "Exception in Tkinter callback\n",
      "Traceback (most recent call last):\n",
      "  File \"C:\\ProgramData\\Anaconda3\\lib\\tkinter\\__init__.py\", line 1892, in __call__\n",
      "    return self.func(*args)\n",
      "  File \"C:\\Users\\sanjay\\AppData\\Local\\Temp\\ipykernel_9524\\1006265385.py\", line 35, in paint\n",
      "    self.draw.line([x1, y1, x2, y2], fill=\"black\", width=5)\n",
      "AttributeError: 'DigitRecognitionApp' object has no attribute 'draw'\n",
      "Exception in Tkinter callback\n",
      "Traceback (most recent call last):\n",
      "  File \"C:\\ProgramData\\Anaconda3\\lib\\tkinter\\__init__.py\", line 1892, in __call__\n",
      "    return self.func(*args)\n",
      "  File \"C:\\Users\\sanjay\\AppData\\Local\\Temp\\ipykernel_9524\\1006265385.py\", line 35, in paint\n",
      "    self.draw.line([x1, y1, x2, y2], fill=\"black\", width=5)\n",
      "AttributeError: 'DigitRecognitionApp' object has no attribute 'draw'\n",
      "Exception in Tkinter callback\n",
      "Traceback (most recent call last):\n",
      "  File \"C:\\ProgramData\\Anaconda3\\lib\\tkinter\\__init__.py\", line 1892, in __call__\n",
      "    return self.func(*args)\n",
      "  File \"C:\\Users\\sanjay\\AppData\\Local\\Temp\\ipykernel_9524\\1006265385.py\", line 35, in paint\n",
      "    self.draw.line([x1, y1, x2, y2], fill=\"black\", width=5)\n",
      "AttributeError: 'DigitRecognitionApp' object has no attribute 'draw'\n",
      "Exception in Tkinter callback\n",
      "Traceback (most recent call last):\n",
      "  File \"C:\\ProgramData\\Anaconda3\\lib\\tkinter\\__init__.py\", line 1892, in __call__\n",
      "    return self.func(*args)\n",
      "  File \"C:\\Users\\sanjay\\AppData\\Local\\Temp\\ipykernel_9524\\1006265385.py\", line 35, in paint\n",
      "    self.draw.line([x1, y1, x2, y2], fill=\"black\", width=5)\n",
      "AttributeError: 'DigitRecognitionApp' object has no attribute 'draw'\n",
      "Exception in Tkinter callback\n",
      "Traceback (most recent call last):\n",
      "  File \"C:\\ProgramData\\Anaconda3\\lib\\tkinter\\__init__.py\", line 1892, in __call__\n",
      "    return self.func(*args)\n",
      "  File \"C:\\Users\\sanjay\\AppData\\Local\\Temp\\ipykernel_9524\\1006265385.py\", line 35, in paint\n",
      "    self.draw.line([x1, y1, x2, y2], fill=\"black\", width=5)\n",
      "AttributeError: 'DigitRecognitionApp' object has no attribute 'draw'\n",
      "Exception in Tkinter callback\n",
      "Traceback (most recent call last):\n",
      "  File \"C:\\ProgramData\\Anaconda3\\lib\\tkinter\\__init__.py\", line 1892, in __call__\n",
      "    return self.func(*args)\n",
      "  File \"C:\\Users\\sanjay\\AppData\\Local\\Temp\\ipykernel_9524\\1006265385.py\", line 35, in paint\n",
      "    self.draw.line([x1, y1, x2, y2], fill=\"black\", width=5)\n",
      "AttributeError: 'DigitRecognitionApp' object has no attribute 'draw'\n",
      "Exception in Tkinter callback\n",
      "Traceback (most recent call last):\n",
      "  File \"C:\\ProgramData\\Anaconda3\\lib\\tkinter\\__init__.py\", line 1892, in __call__\n",
      "    return self.func(*args)\n",
      "  File \"C:\\Users\\sanjay\\AppData\\Local\\Temp\\ipykernel_9524\\1006265385.py\", line 35, in paint\n",
      "    self.draw.line([x1, y1, x2, y2], fill=\"black\", width=5)\n",
      "AttributeError: 'DigitRecognitionApp' object has no attribute 'draw'\n",
      "Exception in Tkinter callback\n",
      "Traceback (most recent call last):\n",
      "  File \"C:\\ProgramData\\Anaconda3\\lib\\tkinter\\__init__.py\", line 1892, in __call__\n",
      "    return self.func(*args)\n",
      "  File \"C:\\Users\\sanjay\\AppData\\Local\\Temp\\ipykernel_9524\\1006265385.py\", line 35, in paint\n",
      "    self.draw.line([x1, y1, x2, y2], fill=\"black\", width=5)\n",
      "AttributeError: 'DigitRecognitionApp' object has no attribute 'draw'\n",
      "Exception in Tkinter callback\n",
      "Traceback (most recent call last):\n",
      "  File \"C:\\ProgramData\\Anaconda3\\lib\\tkinter\\__init__.py\", line 1892, in __call__\n",
      "    return self.func(*args)\n",
      "  File \"C:\\Users\\sanjay\\AppData\\Local\\Temp\\ipykernel_9524\\1006265385.py\", line 35, in paint\n",
      "    self.draw.line([x1, y1, x2, y2], fill=\"black\", width=5)\n",
      "AttributeError: 'DigitRecognitionApp' object has no attribute 'draw'\n",
      "Exception in Tkinter callback\n",
      "Traceback (most recent call last):\n",
      "  File \"C:\\ProgramData\\Anaconda3\\lib\\tkinter\\__init__.py\", line 1892, in __call__\n",
      "    return self.func(*args)\n",
      "  File \"C:\\Users\\sanjay\\AppData\\Local\\Temp\\ipykernel_9524\\1006265385.py\", line 35, in paint\n",
      "    self.draw.line([x1, y1, x2, y2], fill=\"black\", width=5)\n",
      "AttributeError: 'DigitRecognitionApp' object has no attribute 'draw'\n",
      "Exception in Tkinter callback\n",
      "Traceback (most recent call last):\n",
      "  File \"C:\\ProgramData\\Anaconda3\\lib\\tkinter\\__init__.py\", line 1892, in __call__\n",
      "    return self.func(*args)\n",
      "  File \"C:\\Users\\sanjay\\AppData\\Local\\Temp\\ipykernel_9524\\1006265385.py\", line 35, in paint\n",
      "    self.draw.line([x1, y1, x2, y2], fill=\"black\", width=5)\n",
      "AttributeError: 'DigitRecognitionApp' object has no attribute 'draw'\n",
      "Exception in Tkinter callback\n",
      "Traceback (most recent call last):\n",
      "  File \"C:\\ProgramData\\Anaconda3\\lib\\tkinter\\__init__.py\", line 1892, in __call__\n",
      "    return self.func(*args)\n",
      "  File \"C:\\Users\\sanjay\\AppData\\Local\\Temp\\ipykernel_9524\\1006265385.py\", line 35, in paint\n",
      "    self.draw.line([x1, y1, x2, y2], fill=\"black\", width=5)\n",
      "AttributeError: 'DigitRecognitionApp' object has no attribute 'draw'\n",
      "Exception in Tkinter callback\n",
      "Traceback (most recent call last):\n",
      "  File \"C:\\ProgramData\\Anaconda3\\lib\\tkinter\\__init__.py\", line 1892, in __call__\n",
      "    return self.func(*args)\n",
      "  File \"C:\\Users\\sanjay\\AppData\\Local\\Temp\\ipykernel_9524\\1006265385.py\", line 35, in paint\n",
      "    self.draw.line([x1, y1, x2, y2], fill=\"black\", width=5)\n",
      "AttributeError: 'DigitRecognitionApp' object has no attribute 'draw'\n",
      "Exception in Tkinter callback\n",
      "Traceback (most recent call last):\n",
      "  File \"C:\\ProgramData\\Anaconda3\\lib\\tkinter\\__init__.py\", line 1892, in __call__\n",
      "    return self.func(*args)\n",
      "  File \"C:\\Users\\sanjay\\AppData\\Local\\Temp\\ipykernel_9524\\1006265385.py\", line 35, in paint\n",
      "    self.draw.line([x1, y1, x2, y2], fill=\"black\", width=5)\n",
      "AttributeError: 'DigitRecognitionApp' object has no attribute 'draw'\n",
      "Exception in Tkinter callback\n",
      "Traceback (most recent call last):\n",
      "  File \"C:\\ProgramData\\Anaconda3\\lib\\tkinter\\__init__.py\", line 1892, in __call__\n",
      "    return self.func(*args)\n",
      "  File \"C:\\Users\\sanjay\\AppData\\Local\\Temp\\ipykernel_9524\\1006265385.py\", line 35, in paint\n",
      "    self.draw.line([x1, y1, x2, y2], fill=\"black\", width=5)\n",
      "AttributeError: 'DigitRecognitionApp' object has no attribute 'draw'\n",
      "Exception in Tkinter callback\n",
      "Traceback (most recent call last):\n",
      "  File \"C:\\ProgramData\\Anaconda3\\lib\\tkinter\\__init__.py\", line 1892, in __call__\n",
      "    return self.func(*args)\n",
      "  File \"C:\\Users\\sanjay\\AppData\\Local\\Temp\\ipykernel_9524\\1006265385.py\", line 35, in paint\n",
      "    self.draw.line([x1, y1, x2, y2], fill=\"black\", width=5)\n",
      "AttributeError: 'DigitRecognitionApp' object has no attribute 'draw'\n",
      "Exception in Tkinter callback\n",
      "Traceback (most recent call last):\n",
      "  File \"C:\\ProgramData\\Anaconda3\\lib\\tkinter\\__init__.py\", line 1892, in __call__\n",
      "    return self.func(*args)\n",
      "  File \"C:\\Users\\sanjay\\AppData\\Local\\Temp\\ipykernel_9524\\1006265385.py\", line 35, in paint\n",
      "    self.draw.line([x1, y1, x2, y2], fill=\"black\", width=5)\n",
      "AttributeError: 'DigitRecognitionApp' object has no attribute 'draw'\n",
      "Exception in Tkinter callback\n",
      "Traceback (most recent call last):\n",
      "  File \"C:\\ProgramData\\Anaconda3\\lib\\tkinter\\__init__.py\", line 1892, in __call__\n",
      "    return self.func(*args)\n",
      "  File \"C:\\Users\\sanjay\\AppData\\Local\\Temp\\ipykernel_9524\\1006265385.py\", line 35, in paint\n",
      "    self.draw.line([x1, y1, x2, y2], fill=\"black\", width=5)\n",
      "AttributeError: 'DigitRecognitionApp' object has no attribute 'draw'\n",
      "Exception in Tkinter callback\n",
      "Traceback (most recent call last):\n",
      "  File \"C:\\ProgramData\\Anaconda3\\lib\\tkinter\\__init__.py\", line 1892, in __call__\n",
      "    return self.func(*args)\n",
      "  File \"C:\\Users\\sanjay\\AppData\\Local\\Temp\\ipykernel_9524\\1006265385.py\", line 35, in paint\n",
      "    self.draw.line([x1, y1, x2, y2], fill=\"black\", width=5)\n",
      "AttributeError: 'DigitRecognitionApp' object has no attribute 'draw'\n",
      "Exception in Tkinter callback\n",
      "Traceback (most recent call last):\n",
      "  File \"C:\\ProgramData\\Anaconda3\\lib\\tkinter\\__init__.py\", line 1892, in __call__\n",
      "    return self.func(*args)\n",
      "  File \"C:\\Users\\sanjay\\AppData\\Local\\Temp\\ipykernel_9524\\1006265385.py\", line 35, in paint\n",
      "    self.draw.line([x1, y1, x2, y2], fill=\"black\", width=5)\n",
      "AttributeError: 'DigitRecognitionApp' object has no attribute 'draw'\n",
      "Exception in Tkinter callback\n",
      "Traceback (most recent call last):\n",
      "  File \"C:\\ProgramData\\Anaconda3\\lib\\tkinter\\__init__.py\", line 1892, in __call__\n",
      "    return self.func(*args)\n",
      "  File \"C:\\Users\\sanjay\\AppData\\Local\\Temp\\ipykernel_9524\\1006265385.py\", line 35, in paint\n",
      "    self.draw.line([x1, y1, x2, y2], fill=\"black\", width=5)\n",
      "AttributeError: 'DigitRecognitionApp' object has no attribute 'draw'\n",
      "Exception in Tkinter callback\n",
      "Traceback (most recent call last):\n",
      "  File \"C:\\ProgramData\\Anaconda3\\lib\\tkinter\\__init__.py\", line 1892, in __call__\n",
      "    return self.func(*args)\n",
      "  File \"C:\\Users\\sanjay\\AppData\\Local\\Temp\\ipykernel_9524\\1006265385.py\", line 35, in paint\n",
      "    self.draw.line([x1, y1, x2, y2], fill=\"black\", width=5)\n",
      "AttributeError: 'DigitRecognitionApp' object has no attribute 'draw'\n",
      "Exception in Tkinter callback\n",
      "Traceback (most recent call last):\n",
      "  File \"C:\\ProgramData\\Anaconda3\\lib\\tkinter\\__init__.py\", line 1892, in __call__\n",
      "    return self.func(*args)\n",
      "  File \"C:\\Users\\sanjay\\AppData\\Local\\Temp\\ipykernel_9524\\1006265385.py\", line 35, in paint\n",
      "    self.draw.line([x1, y1, x2, y2], fill=\"black\", width=5)\n",
      "AttributeError: 'DigitRecognitionApp' object has no attribute 'draw'\n",
      "Exception in Tkinter callback\n",
      "Traceback (most recent call last):\n",
      "  File \"C:\\ProgramData\\Anaconda3\\lib\\tkinter\\__init__.py\", line 1892, in __call__\n",
      "    return self.func(*args)\n",
      "  File \"C:\\Users\\sanjay\\AppData\\Local\\Temp\\ipykernel_9524\\1006265385.py\", line 35, in paint\n",
      "    self.draw.line([x1, y1, x2, y2], fill=\"black\", width=5)\n",
      "AttributeError: 'DigitRecognitionApp' object has no attribute 'draw'\n",
      "Exception in Tkinter callback\n",
      "Traceback (most recent call last):\n",
      "  File \"C:\\ProgramData\\Anaconda3\\lib\\tkinter\\__init__.py\", line 1892, in __call__\n",
      "    return self.func(*args)\n",
      "  File \"C:\\Users\\sanjay\\AppData\\Local\\Temp\\ipykernel_9524\\1006265385.py\", line 35, in paint\n",
      "    self.draw.line([x1, y1, x2, y2], fill=\"black\", width=5)\n",
      "AttributeError: 'DigitRecognitionApp' object has no attribute 'draw'\n",
      "Exception in Tkinter callback\n",
      "Traceback (most recent call last):\n",
      "  File \"C:\\ProgramData\\Anaconda3\\lib\\tkinter\\__init__.py\", line 1892, in __call__\n",
      "    return self.func(*args)\n",
      "  File \"C:\\Users\\sanjay\\AppData\\Local\\Temp\\ipykernel_9524\\1006265385.py\", line 35, in paint\n",
      "    self.draw.line([x1, y1, x2, y2], fill=\"black\", width=5)\n",
      "AttributeError: 'DigitRecognitionApp' object has no attribute 'draw'\n",
      "Exception in Tkinter callback\n",
      "Traceback (most recent call last):\n",
      "  File \"C:\\ProgramData\\Anaconda3\\lib\\tkinter\\__init__.py\", line 1892, in __call__\n",
      "    return self.func(*args)\n",
      "  File \"C:\\Users\\sanjay\\AppData\\Local\\Temp\\ipykernel_9524\\1006265385.py\", line 35, in paint\n",
      "    self.draw.line([x1, y1, x2, y2], fill=\"black\", width=5)\n",
      "AttributeError: 'DigitRecognitionApp' object has no attribute 'draw'\n",
      "Exception in Tkinter callback\n",
      "Traceback (most recent call last):\n",
      "  File \"C:\\ProgramData\\Anaconda3\\lib\\tkinter\\__init__.py\", line 1892, in __call__\n",
      "    return self.func(*args)\n",
      "  File \"C:\\Users\\sanjay\\AppData\\Local\\Temp\\ipykernel_9524\\1006265385.py\", line 35, in paint\n",
      "    self.draw.line([x1, y1, x2, y2], fill=\"black\", width=5)\n",
      "AttributeError: 'DigitRecognitionApp' object has no attribute 'draw'\n",
      "Exception in Tkinter callback\n",
      "Traceback (most recent call last):\n",
      "  File \"C:\\ProgramData\\Anaconda3\\lib\\tkinter\\__init__.py\", line 1892, in __call__\n",
      "    return self.func(*args)\n",
      "  File \"C:\\Users\\sanjay\\AppData\\Local\\Temp\\ipykernel_9524\\1006265385.py\", line 35, in paint\n",
      "    self.draw.line([x1, y1, x2, y2], fill=\"black\", width=5)\n",
      "AttributeError: 'DigitRecognitionApp' object has no attribute 'draw'\n",
      "Exception in Tkinter callback\n",
      "Traceback (most recent call last):\n",
      "  File \"C:\\ProgramData\\Anaconda3\\lib\\tkinter\\__init__.py\", line 1892, in __call__\n",
      "    return self.func(*args)\n",
      "  File \"C:\\Users\\sanjay\\AppData\\Local\\Temp\\ipykernel_9524\\1006265385.py\", line 35, in paint\n",
      "    self.draw.line([x1, y1, x2, y2], fill=\"black\", width=5)\n",
      "AttributeError: 'DigitRecognitionApp' object has no attribute 'draw'\n",
      "Exception in Tkinter callback\n",
      "Traceback (most recent call last):\n",
      "  File \"C:\\ProgramData\\Anaconda3\\lib\\tkinter\\__init__.py\", line 1892, in __call__\n",
      "    return self.func(*args)\n",
      "  File \"C:\\Users\\sanjay\\AppData\\Local\\Temp\\ipykernel_9524\\1006265385.py\", line 35, in paint\n",
      "    self.draw.line([x1, y1, x2, y2], fill=\"black\", width=5)\n",
      "AttributeError: 'DigitRecognitionApp' object has no attribute 'draw'\n",
      "Exception in Tkinter callback\n",
      "Traceback (most recent call last):\n",
      "  File \"C:\\ProgramData\\Anaconda3\\lib\\tkinter\\__init__.py\", line 1892, in __call__\n",
      "    return self.func(*args)\n",
      "  File \"C:\\Users\\sanjay\\AppData\\Local\\Temp\\ipykernel_9524\\1006265385.py\", line 35, in paint\n",
      "    self.draw.line([x1, y1, x2, y2], fill=\"black\", width=5)\n",
      "AttributeError: 'DigitRecognitionApp' object has no attribute 'draw'\n",
      "Exception in Tkinter callback\n",
      "Traceback (most recent call last):\n",
      "  File \"C:\\ProgramData\\Anaconda3\\lib\\tkinter\\__init__.py\", line 1892, in __call__\n",
      "    return self.func(*args)\n",
      "  File \"C:\\Users\\sanjay\\AppData\\Local\\Temp\\ipykernel_9524\\1006265385.py\", line 35, in paint\n",
      "    self.draw.line([x1, y1, x2, y2], fill=\"black\", width=5)\n",
      "AttributeError: 'DigitRecognitionApp' object has no attribute 'draw'\n",
      "Exception in Tkinter callback\n",
      "Traceback (most recent call last):\n",
      "  File \"C:\\ProgramData\\Anaconda3\\lib\\tkinter\\__init__.py\", line 1892, in __call__\n",
      "    return self.func(*args)\n",
      "  File \"C:\\Users\\sanjay\\AppData\\Local\\Temp\\ipykernel_9524\\1006265385.py\", line 35, in paint\n",
      "    self.draw.line([x1, y1, x2, y2], fill=\"black\", width=5)\n",
      "AttributeError: 'DigitRecognitionApp' object has no attribute 'draw'\n",
      "Exception in Tkinter callback\n",
      "Traceback (most recent call last):\n",
      "  File \"C:\\ProgramData\\Anaconda3\\lib\\tkinter\\__init__.py\", line 1892, in __call__\n",
      "    return self.func(*args)\n",
      "  File \"C:\\Users\\sanjay\\AppData\\Local\\Temp\\ipykernel_9524\\1006265385.py\", line 35, in paint\n",
      "    self.draw.line([x1, y1, x2, y2], fill=\"black\", width=5)\n",
      "AttributeError: 'DigitRecognitionApp' object has no attribute 'draw'\n",
      "Exception in Tkinter callback\n",
      "Traceback (most recent call last):\n",
      "  File \"C:\\ProgramData\\Anaconda3\\lib\\tkinter\\__init__.py\", line 1892, in __call__\n",
      "    return self.func(*args)\n",
      "  File \"C:\\Users\\sanjay\\AppData\\Local\\Temp\\ipykernel_9524\\1006265385.py\", line 35, in paint\n",
      "    self.draw.line([x1, y1, x2, y2], fill=\"black\", width=5)\n",
      "AttributeError: 'DigitRecognitionApp' object has no attribute 'draw'\n",
      "Exception in Tkinter callback\n",
      "Traceback (most recent call last):\n",
      "  File \"C:\\ProgramData\\Anaconda3\\lib\\tkinter\\__init__.py\", line 1892, in __call__\n",
      "    return self.func(*args)\n",
      "  File \"C:\\Users\\sanjay\\AppData\\Local\\Temp\\ipykernel_9524\\1006265385.py\", line 35, in paint\n",
      "    self.draw.line([x1, y1, x2, y2], fill=\"black\", width=5)\n",
      "AttributeError: 'DigitRecognitionApp' object has no attribute 'draw'\n",
      "Exception in Tkinter callback\n",
      "Traceback (most recent call last):\n",
      "  File \"C:\\ProgramData\\Anaconda3\\lib\\tkinter\\__init__.py\", line 1892, in __call__\n",
      "    return self.func(*args)\n",
      "  File \"C:\\Users\\sanjay\\AppData\\Local\\Temp\\ipykernel_9524\\1006265385.py\", line 35, in paint\n",
      "    self.draw.line([x1, y1, x2, y2], fill=\"black\", width=5)\n",
      "AttributeError: 'DigitRecognitionApp' object has no attribute 'draw'\n",
      "Exception in Tkinter callback\n",
      "Traceback (most recent call last):\n",
      "  File \"C:\\ProgramData\\Anaconda3\\lib\\tkinter\\__init__.py\", line 1892, in __call__\n",
      "    return self.func(*args)\n",
      "  File \"C:\\Users\\sanjay\\AppData\\Local\\Temp\\ipykernel_9524\\1006265385.py\", line 35, in paint\n",
      "    self.draw.line([x1, y1, x2, y2], fill=\"black\", width=5)\n",
      "AttributeError: 'DigitRecognitionApp' object has no attribute 'draw'\n",
      "Exception in Tkinter callback\n",
      "Traceback (most recent call last):\n",
      "  File \"C:\\ProgramData\\Anaconda3\\lib\\tkinter\\__init__.py\", line 1892, in __call__\n",
      "    return self.func(*args)\n",
      "  File \"C:\\Users\\sanjay\\AppData\\Local\\Temp\\ipykernel_9524\\1006265385.py\", line 35, in paint\n",
      "    self.draw.line([x1, y1, x2, y2], fill=\"black\", width=5)\n",
      "AttributeError: 'DigitRecognitionApp' object has no attribute 'draw'\n",
      "Exception in Tkinter callback\n",
      "Traceback (most recent call last):\n",
      "  File \"C:\\ProgramData\\Anaconda3\\lib\\tkinter\\__init__.py\", line 1892, in __call__\n",
      "    return self.func(*args)\n",
      "  File \"C:\\Users\\sanjay\\AppData\\Local\\Temp\\ipykernel_9524\\1006265385.py\", line 35, in paint\n",
      "    self.draw.line([x1, y1, x2, y2], fill=\"black\", width=5)\n",
      "AttributeError: 'DigitRecognitionApp' object has no attribute 'draw'\n",
      "Exception in Tkinter callback\n",
      "Traceback (most recent call last):\n",
      "  File \"C:\\ProgramData\\Anaconda3\\lib\\tkinter\\__init__.py\", line 1892, in __call__\n",
      "    return self.func(*args)\n",
      "  File \"C:\\Users\\sanjay\\AppData\\Local\\Temp\\ipykernel_9524\\1006265385.py\", line 35, in paint\n",
      "    self.draw.line([x1, y1, x2, y2], fill=\"black\", width=5)\n",
      "AttributeError: 'DigitRecognitionApp' object has no attribute 'draw'\n",
      "Exception in Tkinter callback\n",
      "Traceback (most recent call last):\n",
      "  File \"C:\\ProgramData\\Anaconda3\\lib\\tkinter\\__init__.py\", line 1892, in __call__\n",
      "    return self.func(*args)\n",
      "  File \"C:\\Users\\sanjay\\AppData\\Local\\Temp\\ipykernel_9524\\1006265385.py\", line 35, in paint\n",
      "    self.draw.line([x1, y1, x2, y2], fill=\"black\", width=5)\n",
      "AttributeError: 'DigitRecognitionApp' object has no attribute 'draw'\n",
      "Exception in Tkinter callback\n",
      "Traceback (most recent call last):\n",
      "  File \"C:\\ProgramData\\Anaconda3\\lib\\tkinter\\__init__.py\", line 1892, in __call__\n",
      "    return self.func(*args)\n",
      "  File \"C:\\Users\\sanjay\\AppData\\Local\\Temp\\ipykernel_9524\\1006265385.py\", line 35, in paint\n",
      "    self.draw.line([x1, y1, x2, y2], fill=\"black\", width=5)\n",
      "AttributeError: 'DigitRecognitionApp' object has no attribute 'draw'\n",
      "Exception in Tkinter callback\n",
      "Traceback (most recent call last):\n",
      "  File \"C:\\ProgramData\\Anaconda3\\lib\\tkinter\\__init__.py\", line 1892, in __call__\n",
      "    return self.func(*args)\n",
      "  File \"C:\\Users\\sanjay\\AppData\\Local\\Temp\\ipykernel_9524\\1006265385.py\", line 35, in paint\n",
      "    self.draw.line([x1, y1, x2, y2], fill=\"black\", width=5)\n",
      "AttributeError: 'DigitRecognitionApp' object has no attribute 'draw'\n",
      "Exception in Tkinter callback\n",
      "Traceback (most recent call last):\n",
      "  File \"C:\\ProgramData\\Anaconda3\\lib\\tkinter\\__init__.py\", line 1892, in __call__\n",
      "    return self.func(*args)\n",
      "  File \"C:\\Users\\sanjay\\AppData\\Local\\Temp\\ipykernel_9524\\1006265385.py\", line 35, in paint\n",
      "    self.draw.line([x1, y1, x2, y2], fill=\"black\", width=5)\n",
      "AttributeError: 'DigitRecognitionApp' object has no attribute 'draw'\n",
      "Exception in Tkinter callback\n",
      "Traceback (most recent call last):\n",
      "  File \"C:\\ProgramData\\Anaconda3\\lib\\tkinter\\__init__.py\", line 1892, in __call__\n",
      "    return self.func(*args)\n",
      "  File \"C:\\Users\\sanjay\\AppData\\Local\\Temp\\ipykernel_9524\\1006265385.py\", line 35, in paint\n",
      "    self.draw.line([x1, y1, x2, y2], fill=\"black\", width=5)\n",
      "AttributeError: 'DigitRecognitionApp' object has no attribute 'draw'\n",
      "Exception in Tkinter callback\n",
      "Traceback (most recent call last):\n",
      "  File \"C:\\ProgramData\\Anaconda3\\lib\\tkinter\\__init__.py\", line 1892, in __call__\n",
      "    return self.func(*args)\n",
      "  File \"C:\\Users\\sanjay\\AppData\\Local\\Temp\\ipykernel_9524\\1006265385.py\", line 35, in paint\n",
      "    self.draw.line([x1, y1, x2, y2], fill=\"black\", width=5)\n",
      "AttributeError: 'DigitRecognitionApp' object has no attribute 'draw'\n",
      "Exception in Tkinter callback\n",
      "Traceback (most recent call last):\n",
      "  File \"C:\\ProgramData\\Anaconda3\\lib\\tkinter\\__init__.py\", line 1892, in __call__\n",
      "    return self.func(*args)\n",
      "  File \"C:\\Users\\sanjay\\AppData\\Local\\Temp\\ipykernel_9524\\1006265385.py\", line 35, in paint\n",
      "    self.draw.line([x1, y1, x2, y2], fill=\"black\", width=5)\n",
      "AttributeError: 'DigitRecognitionApp' object has no attribute 'draw'\n",
      "Exception in Tkinter callback\n",
      "Traceback (most recent call last):\n",
      "  File \"C:\\ProgramData\\Anaconda3\\lib\\tkinter\\__init__.py\", line 1892, in __call__\n",
      "    return self.func(*args)\n",
      "  File \"C:\\Users\\sanjay\\AppData\\Local\\Temp\\ipykernel_9524\\1006265385.py\", line 35, in paint\n",
      "    self.draw.line([x1, y1, x2, y2], fill=\"black\", width=5)\n",
      "AttributeError: 'DigitRecognitionApp' object has no attribute 'draw'\n",
      "Exception in Tkinter callback\n",
      "Traceback (most recent call last):\n",
      "  File \"C:\\ProgramData\\Anaconda3\\lib\\tkinter\\__init__.py\", line 1892, in __call__\n",
      "    return self.func(*args)\n",
      "  File \"C:\\Users\\sanjay\\AppData\\Local\\Temp\\ipykernel_9524\\1006265385.py\", line 35, in paint\n",
      "    self.draw.line([x1, y1, x2, y2], fill=\"black\", width=5)\n",
      "AttributeError: 'DigitRecognitionApp' object has no attribute 'draw'\n",
      "Exception in Tkinter callback\n",
      "Traceback (most recent call last):\n",
      "  File \"C:\\ProgramData\\Anaconda3\\lib\\tkinter\\__init__.py\", line 1892, in __call__\n",
      "    return self.func(*args)\n",
      "  File \"C:\\Users\\sanjay\\AppData\\Local\\Temp\\ipykernel_9524\\1006265385.py\", line 35, in paint\n",
      "    self.draw.line([x1, y1, x2, y2], fill=\"black\", width=5)\n",
      "AttributeError: 'DigitRecognitionApp' object has no attribute 'draw'\n",
      "Exception in Tkinter callback\n",
      "Traceback (most recent call last):\n",
      "  File \"C:\\ProgramData\\Anaconda3\\lib\\tkinter\\__init__.py\", line 1892, in __call__\n",
      "    return self.func(*args)\n",
      "  File \"C:\\Users\\sanjay\\AppData\\Local\\Temp\\ipykernel_9524\\1006265385.py\", line 35, in paint\n",
      "    self.draw.line([x1, y1, x2, y2], fill=\"black\", width=5)\n",
      "AttributeError: 'DigitRecognitionApp' object has no attribute 'draw'\n",
      "Exception in Tkinter callback\n",
      "Traceback (most recent call last):\n",
      "  File \"C:\\ProgramData\\Anaconda3\\lib\\tkinter\\__init__.py\", line 1892, in __call__\n",
      "    return self.func(*args)\n",
      "  File \"C:\\Users\\sanjay\\AppData\\Local\\Temp\\ipykernel_9524\\1006265385.py\", line 35, in paint\n",
      "    self.draw.line([x1, y1, x2, y2], fill=\"black\", width=5)\n",
      "AttributeError: 'DigitRecognitionApp' object has no attribute 'draw'\n",
      "Exception in Tkinter callback\n",
      "Traceback (most recent call last):\n",
      "  File \"C:\\ProgramData\\Anaconda3\\lib\\tkinter\\__init__.py\", line 1892, in __call__\n",
      "    return self.func(*args)\n",
      "  File \"C:\\Users\\sanjay\\AppData\\Local\\Temp\\ipykernel_9524\\1006265385.py\", line 35, in paint\n",
      "    self.draw.line([x1, y1, x2, y2], fill=\"black\", width=5)\n",
      "AttributeError: 'DigitRecognitionApp' object has no attribute 'draw'\n",
      "Exception in Tkinter callback\n",
      "Traceback (most recent call last):\n",
      "  File \"C:\\ProgramData\\Anaconda3\\lib\\tkinter\\__init__.py\", line 1892, in __call__\n",
      "    return self.func(*args)\n",
      "  File \"C:\\Users\\sanjay\\AppData\\Local\\Temp\\ipykernel_9524\\1006265385.py\", line 35, in paint\n",
      "    self.draw.line([x1, y1, x2, y2], fill=\"black\", width=5)\n",
      "AttributeError: 'DigitRecognitionApp' object has no attribute 'draw'\n",
      "Exception in Tkinter callback\n",
      "Traceback (most recent call last):\n",
      "  File \"C:\\ProgramData\\Anaconda3\\lib\\tkinter\\__init__.py\", line 1892, in __call__\n",
      "    return self.func(*args)\n",
      "  File \"C:\\Users\\sanjay\\AppData\\Local\\Temp\\ipykernel_9524\\1006265385.py\", line 35, in paint\n",
      "    self.draw.line([x1, y1, x2, y2], fill=\"black\", width=5)\n",
      "AttributeError: 'DigitRecognitionApp' object has no attribute 'draw'\n",
      "Exception in Tkinter callback\n",
      "Traceback (most recent call last):\n",
      "  File \"C:\\ProgramData\\Anaconda3\\lib\\tkinter\\__init__.py\", line 1892, in __call__\n",
      "    return self.func(*args)\n",
      "  File \"C:\\Users\\sanjay\\AppData\\Local\\Temp\\ipykernel_9524\\1006265385.py\", line 35, in paint\n",
      "    self.draw.line([x1, y1, x2, y2], fill=\"black\", width=5)\n",
      "AttributeError: 'DigitRecognitionApp' object has no attribute 'draw'\n",
      "Exception in Tkinter callback\n",
      "Traceback (most recent call last):\n",
      "  File \"C:\\ProgramData\\Anaconda3\\lib\\tkinter\\__init__.py\", line 1892, in __call__\n",
      "    return self.func(*args)\n",
      "  File \"C:\\Users\\sanjay\\AppData\\Local\\Temp\\ipykernel_9524\\1006265385.py\", line 35, in paint\n",
      "    self.draw.line([x1, y1, x2, y2], fill=\"black\", width=5)\n",
      "AttributeError: 'DigitRecognitionApp' object has no attribute 'draw'\n",
      "Exception in Tkinter callback\n",
      "Traceback (most recent call last):\n",
      "  File \"C:\\ProgramData\\Anaconda3\\lib\\tkinter\\__init__.py\", line 1892, in __call__\n",
      "    return self.func(*args)\n",
      "  File \"C:\\Users\\sanjay\\AppData\\Local\\Temp\\ipykernel_9524\\1006265385.py\", line 35, in paint\n",
      "    self.draw.line([x1, y1, x2, y2], fill=\"black\", width=5)\n",
      "AttributeError: 'DigitRecognitionApp' object has no attribute 'draw'\n",
      "Exception in Tkinter callback\n",
      "Traceback (most recent call last):\n",
      "  File \"C:\\ProgramData\\Anaconda3\\lib\\tkinter\\__init__.py\", line 1892, in __call__\n",
      "    return self.func(*args)\n",
      "  File \"C:\\Users\\sanjay\\AppData\\Local\\Temp\\ipykernel_9524\\1006265385.py\", line 35, in paint\n",
      "    self.draw.line([x1, y1, x2, y2], fill=\"black\", width=5)\n",
      "AttributeError: 'DigitRecognitionApp' object has no attribute 'draw'\n",
      "Exception in Tkinter callback\n",
      "Traceback (most recent call last):\n",
      "  File \"C:\\ProgramData\\Anaconda3\\lib\\tkinter\\__init__.py\", line 1892, in __call__\n",
      "    return self.func(*args)\n",
      "  File \"C:\\Users\\sanjay\\AppData\\Local\\Temp\\ipykernel_9524\\1006265385.py\", line 35, in paint\n",
      "    self.draw.line([x1, y1, x2, y2], fill=\"black\", width=5)\n",
      "AttributeError: 'DigitRecognitionApp' object has no attribute 'draw'\n",
      "Exception in Tkinter callback\n",
      "Traceback (most recent call last):\n",
      "  File \"C:\\ProgramData\\Anaconda3\\lib\\tkinter\\__init__.py\", line 1892, in __call__\n",
      "    return self.func(*args)\n",
      "  File \"C:\\Users\\sanjay\\AppData\\Local\\Temp\\ipykernel_9524\\1006265385.py\", line 35, in paint\n",
      "    self.draw.line([x1, y1, x2, y2], fill=\"black\", width=5)\n",
      "AttributeError: 'DigitRecognitionApp' object has no attribute 'draw'\n",
      "Exception in Tkinter callback\n",
      "Traceback (most recent call last):\n",
      "  File \"C:\\ProgramData\\Anaconda3\\lib\\tkinter\\__init__.py\", line 1892, in __call__\n",
      "    return self.func(*args)\n",
      "  File \"C:\\Users\\sanjay\\AppData\\Local\\Temp\\ipykernel_9524\\1006265385.py\", line 35, in paint\n",
      "    self.draw.line([x1, y1, x2, y2], fill=\"black\", width=5)\n",
      "AttributeError: 'DigitRecognitionApp' object has no attribute 'draw'\n",
      "Exception in Tkinter callback\n",
      "Traceback (most recent call last):\n",
      "  File \"C:\\ProgramData\\Anaconda3\\lib\\tkinter\\__init__.py\", line 1892, in __call__\n",
      "    return self.func(*args)\n",
      "  File \"C:\\Users\\sanjay\\AppData\\Local\\Temp\\ipykernel_9524\\1006265385.py\", line 35, in paint\n",
      "    self.draw.line([x1, y1, x2, y2], fill=\"black\", width=5)\n",
      "AttributeError: 'DigitRecognitionApp' object has no attribute 'draw'\n",
      "Exception in Tkinter callback\n",
      "Traceback (most recent call last):\n",
      "  File \"C:\\ProgramData\\Anaconda3\\lib\\tkinter\\__init__.py\", line 1892, in __call__\n",
      "    return self.func(*args)\n",
      "  File \"C:\\Users\\sanjay\\AppData\\Local\\Temp\\ipykernel_9524\\1006265385.py\", line 35, in paint\n",
      "    self.draw.line([x1, y1, x2, y2], fill=\"black\", width=5)\n",
      "AttributeError: 'DigitRecognitionApp' object has no attribute 'draw'\n",
      "Exception in Tkinter callback\n",
      "Traceback (most recent call last):\n",
      "  File \"C:\\ProgramData\\Anaconda3\\lib\\tkinter\\__init__.py\", line 1892, in __call__\n",
      "    return self.func(*args)\n",
      "  File \"C:\\Users\\sanjay\\AppData\\Local\\Temp\\ipykernel_9524\\1006265385.py\", line 35, in paint\n",
      "    self.draw.line([x1, y1, x2, y2], fill=\"black\", width=5)\n",
      "AttributeError: 'DigitRecognitionApp' object has no attribute 'draw'\n",
      "Exception in Tkinter callback\n",
      "Traceback (most recent call last):\n",
      "  File \"C:\\ProgramData\\Anaconda3\\lib\\tkinter\\__init__.py\", line 1892, in __call__\n",
      "    return self.func(*args)\n",
      "  File \"C:\\Users\\sanjay\\AppData\\Local\\Temp\\ipykernel_9524\\1006265385.py\", line 35, in paint\n",
      "    self.draw.line([x1, y1, x2, y2], fill=\"black\", width=5)\n",
      "AttributeError: 'DigitRecognitionApp' object has no attribute 'draw'\n",
      "Exception in Tkinter callback\n",
      "Traceback (most recent call last):\n",
      "  File \"C:\\ProgramData\\Anaconda3\\lib\\tkinter\\__init__.py\", line 1892, in __call__\n",
      "    return self.func(*args)\n",
      "  File \"C:\\Users\\sanjay\\AppData\\Local\\Temp\\ipykernel_9524\\1006265385.py\", line 35, in paint\n",
      "    self.draw.line([x1, y1, x2, y2], fill=\"black\", width=5)\n",
      "AttributeError: 'DigitRecognitionApp' object has no attribute 'draw'\n",
      "Exception in Tkinter callback\n",
      "Traceback (most recent call last):\n",
      "  File \"C:\\ProgramData\\Anaconda3\\lib\\tkinter\\__init__.py\", line 1892, in __call__\n",
      "    return self.func(*args)\n",
      "  File \"C:\\Users\\sanjay\\AppData\\Local\\Temp\\ipykernel_9524\\1006265385.py\", line 35, in paint\n",
      "    self.draw.line([x1, y1, x2, y2], fill=\"black\", width=5)\n",
      "AttributeError: 'DigitRecognitionApp' object has no attribute 'draw'\n",
      "Exception in Tkinter callback\n",
      "Traceback (most recent call last):\n",
      "  File \"C:\\ProgramData\\Anaconda3\\lib\\tkinter\\__init__.py\", line 1892, in __call__\n",
      "    return self.func(*args)\n",
      "  File \"C:\\Users\\sanjay\\AppData\\Local\\Temp\\ipykernel_9524\\1006265385.py\", line 35, in paint\n",
      "    self.draw.line([x1, y1, x2, y2], fill=\"black\", width=5)\n",
      "AttributeError: 'DigitRecognitionApp' object has no attribute 'draw'\n",
      "Exception in Tkinter callback\n",
      "Traceback (most recent call last):\n",
      "  File \"C:\\ProgramData\\Anaconda3\\lib\\tkinter\\__init__.py\", line 1892, in __call__\n",
      "    return self.func(*args)\n",
      "  File \"C:\\Users\\sanjay\\AppData\\Local\\Temp\\ipykernel_9524\\1006265385.py\", line 35, in paint\n",
      "    self.draw.line([x1, y1, x2, y2], fill=\"black\", width=5)\n",
      "AttributeError: 'DigitRecognitionApp' object has no attribute 'draw'\n",
      "Exception in Tkinter callback\n",
      "Traceback (most recent call last):\n",
      "  File \"C:\\ProgramData\\Anaconda3\\lib\\tkinter\\__init__.py\", line 1892, in __call__\n",
      "    return self.func(*args)\n",
      "  File \"C:\\Users\\sanjay\\AppData\\Local\\Temp\\ipykernel_9524\\1006265385.py\", line 35, in paint\n",
      "    self.draw.line([x1, y1, x2, y2], fill=\"black\", width=5)\n",
      "AttributeError: 'DigitRecognitionApp' object has no attribute 'draw'\n",
      "Exception in Tkinter callback\n",
      "Traceback (most recent call last):\n",
      "  File \"C:\\ProgramData\\Anaconda3\\lib\\tkinter\\__init__.py\", line 1892, in __call__\n",
      "    return self.func(*args)\n",
      "  File \"C:\\Users\\sanjay\\AppData\\Local\\Temp\\ipykernel_9524\\1006265385.py\", line 35, in paint\n",
      "    self.draw.line([x1, y1, x2, y2], fill=\"black\", width=5)\n",
      "AttributeError: 'DigitRecognitionApp' object has no attribute 'draw'\n",
      "Exception in Tkinter callback\n",
      "Traceback (most recent call last):\n",
      "  File \"C:\\ProgramData\\Anaconda3\\lib\\tkinter\\__init__.py\", line 1892, in __call__\n",
      "    return self.func(*args)\n",
      "  File \"C:\\Users\\sanjay\\AppData\\Local\\Temp\\ipykernel_9524\\1006265385.py\", line 35, in paint\n",
      "    self.draw.line([x1, y1, x2, y2], fill=\"black\", width=5)\n",
      "AttributeError: 'DigitRecognitionApp' object has no attribute 'draw'\n",
      "Exception in Tkinter callback\n",
      "Traceback (most recent call last):\n",
      "  File \"C:\\ProgramData\\Anaconda3\\lib\\tkinter\\__init__.py\", line 1892, in __call__\n",
      "    return self.func(*args)\n",
      "  File \"C:\\Users\\sanjay\\AppData\\Local\\Temp\\ipykernel_9524\\1006265385.py\", line 35, in paint\n",
      "    self.draw.line([x1, y1, x2, y2], fill=\"black\", width=5)\n",
      "AttributeError: 'DigitRecognitionApp' object has no attribute 'draw'\n",
      "Exception in Tkinter callback\n",
      "Traceback (most recent call last):\n",
      "  File \"C:\\ProgramData\\Anaconda3\\lib\\tkinter\\__init__.py\", line 1892, in __call__\n",
      "    return self.func(*args)\n",
      "  File \"C:\\Users\\sanjay\\AppData\\Local\\Temp\\ipykernel_9524\\1006265385.py\", line 35, in paint\n",
      "    self.draw.line([x1, y1, x2, y2], fill=\"black\", width=5)\n",
      "AttributeError: 'DigitRecognitionApp' object has no attribute 'draw'\n",
      "Exception in Tkinter callback\n",
      "Traceback (most recent call last):\n",
      "  File \"C:\\ProgramData\\Anaconda3\\lib\\tkinter\\__init__.py\", line 1892, in __call__\n",
      "    return self.func(*args)\n",
      "  File \"C:\\Users\\sanjay\\AppData\\Local\\Temp\\ipykernel_9524\\1006265385.py\", line 35, in paint\n",
      "    self.draw.line([x1, y1, x2, y2], fill=\"black\", width=5)\n",
      "AttributeError: 'DigitRecognitionApp' object has no attribute 'draw'\n",
      "Exception in Tkinter callback\n",
      "Traceback (most recent call last):\n",
      "  File \"C:\\ProgramData\\Anaconda3\\lib\\tkinter\\__init__.py\", line 1892, in __call__\n",
      "    return self.func(*args)\n",
      "  File \"C:\\Users\\sanjay\\AppData\\Local\\Temp\\ipykernel_9524\\1006265385.py\", line 35, in paint\n",
      "    self.draw.line([x1, y1, x2, y2], fill=\"black\", width=5)\n",
      "AttributeError: 'DigitRecognitionApp' object has no attribute 'draw'\n",
      "Exception in Tkinter callback\n",
      "Traceback (most recent call last):\n",
      "  File \"C:\\ProgramData\\Anaconda3\\lib\\tkinter\\__init__.py\", line 1892, in __call__\n",
      "    return self.func(*args)\n",
      "  File \"C:\\Users\\sanjay\\AppData\\Local\\Temp\\ipykernel_9524\\1006265385.py\", line 35, in paint\n",
      "    self.draw.line([x1, y1, x2, y2], fill=\"black\", width=5)\n",
      "AttributeError: 'DigitRecognitionApp' object has no attribute 'draw'\n",
      "Exception in Tkinter callback\n",
      "Traceback (most recent call last):\n",
      "  File \"C:\\ProgramData\\Anaconda3\\lib\\tkinter\\__init__.py\", line 1892, in __call__\n",
      "    return self.func(*args)\n",
      "  File \"C:\\Users\\sanjay\\AppData\\Local\\Temp\\ipykernel_9524\\1006265385.py\", line 35, in paint\n",
      "    self.draw.line([x1, y1, x2, y2], fill=\"black\", width=5)\n",
      "AttributeError: 'DigitRecognitionApp' object has no attribute 'draw'\n",
      "Exception in Tkinter callback\n",
      "Traceback (most recent call last):\n",
      "  File \"C:\\ProgramData\\Anaconda3\\lib\\tkinter\\__init__.py\", line 1892, in __call__\n",
      "    return self.func(*args)\n",
      "  File \"C:\\Users\\sanjay\\AppData\\Local\\Temp\\ipykernel_9524\\1006265385.py\", line 35, in paint\n",
      "    self.draw.line([x1, y1, x2, y2], fill=\"black\", width=5)\n",
      "AttributeError: 'DigitRecognitionApp' object has no attribute 'draw'\n",
      "Exception in Tkinter callback\n",
      "Traceback (most recent call last):\n",
      "  File \"C:\\ProgramData\\Anaconda3\\lib\\tkinter\\__init__.py\", line 1892, in __call__\n",
      "    return self.func(*args)\n",
      "  File \"C:\\Users\\sanjay\\AppData\\Local\\Temp\\ipykernel_9524\\1006265385.py\", line 35, in paint\n",
      "    self.draw.line([x1, y1, x2, y2], fill=\"black\", width=5)\n",
      "AttributeError: 'DigitRecognitionApp' object has no attribute 'draw'\n",
      "Exception in Tkinter callback\n",
      "Traceback (most recent call last):\n",
      "  File \"C:\\ProgramData\\Anaconda3\\lib\\tkinter\\__init__.py\", line 1892, in __call__\n",
      "    return self.func(*args)\n",
      "  File \"C:\\Users\\sanjay\\AppData\\Local\\Temp\\ipykernel_9524\\1006265385.py\", line 35, in paint\n",
      "    self.draw.line([x1, y1, x2, y2], fill=\"black\", width=5)\n",
      "AttributeError: 'DigitRecognitionApp' object has no attribute 'draw'\n",
      "Exception in Tkinter callback\n",
      "Traceback (most recent call last):\n",
      "  File \"C:\\ProgramData\\Anaconda3\\lib\\tkinter\\__init__.py\", line 1892, in __call__\n",
      "    return self.func(*args)\n",
      "  File \"C:\\Users\\sanjay\\AppData\\Local\\Temp\\ipykernel_9524\\1006265385.py\", line 35, in paint\n",
      "    self.draw.line([x1, y1, x2, y2], fill=\"black\", width=5)\n",
      "AttributeError: 'DigitRecognitionApp' object has no attribute 'draw'\n",
      "Exception in Tkinter callback\n",
      "Traceback (most recent call last):\n",
      "  File \"C:\\ProgramData\\Anaconda3\\lib\\tkinter\\__init__.py\", line 1892, in __call__\n",
      "    return self.func(*args)\n",
      "  File \"C:\\Users\\sanjay\\AppData\\Local\\Temp\\ipykernel_9524\\1006265385.py\", line 35, in paint\n",
      "    self.draw.line([x1, y1, x2, y2], fill=\"black\", width=5)\n",
      "AttributeError: 'DigitRecognitionApp' object has no attribute 'draw'\n",
      "Exception in Tkinter callback\n",
      "Traceback (most recent call last):\n",
      "  File \"C:\\ProgramData\\Anaconda3\\lib\\tkinter\\__init__.py\", line 1892, in __call__\n",
      "    return self.func(*args)\n",
      "  File \"C:\\Users\\sanjay\\AppData\\Local\\Temp\\ipykernel_9524\\1006265385.py\", line 35, in paint\n",
      "    self.draw.line([x1, y1, x2, y2], fill=\"black\", width=5)\n",
      "AttributeError: 'DigitRecognitionApp' object has no attribute 'draw'\n",
      "Exception in Tkinter callback\n",
      "Traceback (most recent call last):\n",
      "  File \"C:\\ProgramData\\Anaconda3\\lib\\tkinter\\__init__.py\", line 1892, in __call__\n",
      "    return self.func(*args)\n",
      "  File \"C:\\Users\\sanjay\\AppData\\Local\\Temp\\ipykernel_9524\\1006265385.py\", line 35, in paint\n",
      "    self.draw.line([x1, y1, x2, y2], fill=\"black\", width=5)\n",
      "AttributeError: 'DigitRecognitionApp' object has no attribute 'draw'\n",
      "Exception in Tkinter callback\n",
      "Traceback (most recent call last):\n",
      "  File \"C:\\ProgramData\\Anaconda3\\lib\\tkinter\\__init__.py\", line 1892, in __call__\n",
      "    return self.func(*args)\n",
      "  File \"C:\\Users\\sanjay\\AppData\\Local\\Temp\\ipykernel_9524\\1006265385.py\", line 35, in paint\n",
      "    self.draw.line([x1, y1, x2, y2], fill=\"black\", width=5)\n",
      "AttributeError: 'DigitRecognitionApp' object has no attribute 'draw'\n",
      "Exception in Tkinter callback\n",
      "Traceback (most recent call last):\n",
      "  File \"C:\\ProgramData\\Anaconda3\\lib\\tkinter\\__init__.py\", line 1892, in __call__\n",
      "    return self.func(*args)\n",
      "  File \"C:\\Users\\sanjay\\AppData\\Local\\Temp\\ipykernel_9524\\1006265385.py\", line 35, in paint\n",
      "    self.draw.line([x1, y1, x2, y2], fill=\"black\", width=5)\n",
      "AttributeError: 'DigitRecognitionApp' object has no attribute 'draw'\n",
      "Exception in Tkinter callback\n",
      "Traceback (most recent call last):\n",
      "  File \"C:\\ProgramData\\Anaconda3\\lib\\tkinter\\__init__.py\", line 1892, in __call__\n",
      "    return self.func(*args)\n",
      "  File \"C:\\Users\\sanjay\\AppData\\Local\\Temp\\ipykernel_9524\\1006265385.py\", line 35, in paint\n",
      "    self.draw.line([x1, y1, x2, y2], fill=\"black\", width=5)\n",
      "AttributeError: 'DigitRecognitionApp' object has no attribute 'draw'\n",
      "Exception in Tkinter callback\n",
      "Traceback (most recent call last):\n",
      "  File \"C:\\ProgramData\\Anaconda3\\lib\\tkinter\\__init__.py\", line 1892, in __call__\n",
      "    return self.func(*args)\n",
      "  File \"C:\\Users\\sanjay\\AppData\\Local\\Temp\\ipykernel_9524\\1006265385.py\", line 35, in paint\n",
      "    self.draw.line([x1, y1, x2, y2], fill=\"black\", width=5)\n",
      "AttributeError: 'DigitRecognitionApp' object has no attribute 'draw'\n"
     ]
    },
    {
     "name": "stdout",
     "output_type": "stream",
     "text": [
      "1/1 [==============================] - 0s 141ms/step\n",
      "1/1 [==============================] - 0s 42ms/step\n",
      "1/1 [==============================] - 0s 38ms/step\n",
      "1/1 [==============================] - 0s 38ms/step\n",
      "1/1 [==============================] - 0s 26ms/step\n",
      "1/1 [==============================] - 0s 37ms/step\n",
      "1/1 [==============================] - 0s 26ms/step\n",
      "1/1 [==============================] - 0s 41ms/step\n",
      "1/1 [==============================] - 0s 37ms/step\n"
     ]
    }
   ],
   "source": [
    "import tkinter as tk\n",
    "from tkinter import filedialog\n",
    "from PIL import Image, ImageTk, ImageDraw\n",
    "import numpy as np\n",
    "import tensorflow as tf\n",
    "\n",
    "# Load the trained model\n",
    "model = tf.keras.models.load_model(\"model_Gau.h5\")\n",
    "\n",
    "class DigitRecognitionApp:\n",
    "    def __init__(self, root):\n",
    "        self.root = root\n",
    "        self.root.title(\"Handwritten Digit Recognition\")\n",
    "\n",
    "        self.canvas = tk.Canvas(self.root, width=280, height=280, bg=\"white\")\n",
    "        self.canvas.pack()\n",
    "        self.canvas.bind(\"<B1-Motion>\", self.paint)\n",
    "\n",
    "        self.clear_button = tk.Button(self.root, text=\"Clear\", command=self.clear_canvas)\n",
    "        self.clear_button.pack()\n",
    "\n",
    "        self.predict_button = tk.Button(self.root, text=\"Predict\", command=self.predict_digit)\n",
    "        self.predict_button.pack()\n",
    "\n",
    "        self.result_label = tk.Label(self.root, text=\"\")\n",
    "        self.result_label.pack()\n",
    "\n",
    "        self.image = Image.new(\"L\", (280, 280), \"white\")\n",
    "        self.draw = ImageDraw.Draw(self.image)\n",
    "\n",
    "    def paint(self, event):\n",
    "        x1, y1 = (event.x - 10), (event.y - 10)\n",
    "        x2, y2 = (event.x + 10), (event.y + 10)\n",
    "        self.canvas.create_oval(x1, y1, x2, y2, fill=\"black\", width=5)\n",
    "        self.draw.line([x1, y1, x2, y2], fill=\"black\", width=5)\n",
    "\n",
    "    def clear_canvas(self):\n",
    "        self.canvas.delete(\"all\")\n",
    "        self.image = Image.new(\"L\", (280, 280), \"white\")\n",
    "        self.draw = ImageDraw.Draw(self.image)\n",
    "\n",
    "    def predict_digit(self):\n",
    "        img = self.image.resize((28, 28))\n",
    "        img_array = np.array(img)\n",
    "        img_array = img_array.reshape(1, 28, 28, 1) / 255.0\n",
    "        prediction = model.predict(img_array)\n",
    "        predicted_number = np.argmax(prediction)\n",
    "        self.result_label.config(text=f\"Predicted Number: {predicted_number}\")\n",
    "\n",
    "if __name__ == \"__main__\":\n",
    "    root = tk.Tk()\n",
    "    app = DigitRecognitionApp(root)\n",
    "    root.mainloop()\n"
   ]
  },
  {
   "cell_type": "code",
   "execution_count": null,
   "id": "381f8c5f",
   "metadata": {},
   "outputs": [],
   "source": []
  }
 ],
 "metadata": {
  "kernelspec": {
   "display_name": "Python 3 (ipykernel)",
   "language": "python",
   "name": "python3"
  },
  "language_info": {
   "codemirror_mode": {
    "name": "ipython",
    "version": 3
   },
   "file_extension": ".py",
   "mimetype": "text/x-python",
   "name": "python",
   "nbconvert_exporter": "python",
   "pygments_lexer": "ipython3",
   "version": "3.9.12"
  }
 },
 "nbformat": 4,
 "nbformat_minor": 5
}
